Workbook
Name _____________________AMZ2: #REF!
Name _____________________AMZ2: #REF!
Name ____________________AMZ2: #REF!
Name ____________________AMZ2: #REF!
Name ___________________AMZ2: #REF!
Name ___________________AMZ2: #REF!
Name __________________AMZ2: #REF!
Name __________________AMZ2: #REF!
Name _________________AMZ2: #REF!
Name _________________AMZ2: #REF!
Name ________________AMZ2: #REF!
Name ________________AMZ2: #REF!
Name _______________AMZ2: #REF!
Name _______________AMZ2: #REF!
Name _______________AMZ2: #REF!
Name ______________AMZ2: #REF!
Name ______________AMZ2: #REF!
Name ______________AMZ2: #REF!
Name _____________AMZ2: #REF!
Name _____________AMZ2: #REF!
Name _____________AMZ2: #REF!
Name ____________AMZ2: #REF!
Name ____________AMZ2: #REF!
Name ____________AMZ2: #REF!
Name ___________AMZ2: #REF!
Name ___________AMZ2: #REF!
Name ___________AMZ2: #REF!
Name __________AMZ2: #REF!
Name __________AMZ2: #REF!
Name __________AMZ2: #REF!
Name _________AMZ2: #REF!
Name _________AMZ2: #REF!
Name _________AMZ2: #REF!
Name ________AMZ2: #REF!
Name ________AMZ2: #REF!
Name _______AMZ2: #REF!
Name _______AMZ2: #REF!
Name ______AMZ2: #REF!
Name ______AMZ2: #REF!
Name _____AMZ2: #REF!
Name _____AMZ2: #REF!
Name ____AMZ2: #REF!
Name ____AMZ2: #REF!
Name ___AMZ2: #REF!
Name ___AMZ2: #REF!
Name __AMZ2: #REF!
Name __AMZ2: #REF!
Name _1._Jessie_Lee_Alviz_Baldez_2._Glysa_Rapado_Robiso_3._Jovelyn_Ybarola_Gallarin_4._Jonalie_Jose_Molaro_5._Evangeline_Jabenyar_Besar_6._Amielyn_Dime_7._Jayson_Luvedesis_Enriquez_8._Judy_Ann_M._Hernandez_9._Liezel_S._Leynes_10._Marlon_D._Mercado_11._Jessima: #REF!
Name _1._Jessie_Lee_Alviz_Baldez_2._Glysa_Rapado_Robiso_3._Jovelyn_Ybarola_Gallarin_4._Jonalie_Jose_Molaro_5._Evangeline_Jabenyar_Besar_6._Amielyn_Dime_7._Jayson_Luvedesis_Enriquez_8._Judy_Ann_M._Hernandez_9._Liezel_S._Leynes_10._Marlon_D._Mercado_11._Jessima: #REF!
Name _1._Jessie_Lee_Alviz_Baldez_2._Glysa_Rapado_Robiso_3._Jovelyn_Ybarola_Gallarin_4._Jonalie_Jose_Molaro_5._Evangeline_Jabenyar_Besar_6._Amielyn_Dime_7._Jayson_Luvedesis_Enriquez_8._Judy_Ann_M._Hernandez_9._Liezel_S._Leynes_10._Marlon_D._Mercado_11._Jessima: #REF!
Name _402_jpyTotal: #REF!
Name _402_jpyTotal: #REF!
Name _402_jpyTotal: #REF!
Name _AMZ2: #REF!
Name _AMZ2: #REF!
Name _AMZ2: #REF!
Name A: #REF!
Name A: #REF!
Name A: #REF!
Name activity: #REF!

Sheet INVOICE
C1: HYS Metal Plastic and Electronics | H1: =TODAY() -> 46234
B2: On file | C2: Blk 6-2 & 6-4 Amplefield SME Park JP Rizal Ave. Bugtong na Pulo,Lipa City Batangas 4225
H3: 009-937-716-000
D5: =B48 -> ONE MILLION TWO HUNDRED FOURTY SEVEN THOUSAND SIX HUNDRED SIXTY TWO PESOS 93/100 ONLY.
E7: PHP | G7: =H48 -> 117449.5
B9: Billing for the services rendered by Workers ( ALL )
B11: ='BILLING COMPUTATION'!C5 -> PAYROLL PERIOD: JULY 11-25, 2026
C13: Head Count | D13: ='BILLING COMPUTATION'!#REF! -> #REF! | E13: MP
C14: Basic Pay | H14: ='BILLING COMPUTATION'!M102 -> 587400 | K14: =H14='BILLING COMPUTATION'!M102 -> TRUE
C15: Reg Ot | H15: ='BILLING COMPUTATION'!S102 -> 65062.5 | K15: =H15='BILLING COMPUTATION'!S102 -> TRUE
C16: Night Differential | H16: ='BILLING COMPUTATION'!V102 -> 15648.75 | K16: =H16='BILLING COMPUTATION'!V102 -> TRUE
C17: Night Diff. Ot | H17: ='BILLING COMPUTATION'!#REF! -> #REF! | K17: =H17='BILLING COMPUTATION'!#REF! -> #REF!
C18: Sunday Duty | H18: ='BILLING COMPUTATION'!AB102 -> 0 | K18: =H18='BILLING COMPUTATION'!AB102 -> TRUE
C19: Sunday Excess | H19: ='BILLING COMPUTATION'!AE102 -> 0 | K19: =H19='BILLING COMPUTATION'!AE102 -> TRUE
C20: Sunday ND | H20: ='BILLING COMPUTATION'!AH102 -> 0 | K20: =H20='BILLING COMPUTATION'!AH102 -> TRUE
C21: Sunday ND OT | H21: ='BILLING COMPUTATION'!#REF! -> #REF! | K21: =H21='BILLING COMPUTATION'!#REF! -> #REF!
C22: Special Holiday | H22: ='BILLING COMPUTATION'!AT102 -> 0 | K22: =H22='BILLING COMPUTATION'!AT102 -> TRUE
C23: Special Holiday OT | H23: ='BILLING COMPUTATION'!AW102 -> 0 | K23: =H23='BILLING COMPUTATION'!AW102 -> TRUE
C24: Special Holiday ND | I24: ='BILLING COMPUTATION'!AZ102 -> 0 | K24: =H24='BILLING COMPUTATION'!AW103 -> TRUE
C25: Legal Holiday | H25: ='BILLING COMPUTATION'!BD102 -> 0 | K25: =H25='BILLING COMPUTATION'!BD102 -> TRUE
C26: Unworked Legal Holiday | H26: ='BILLING COMPUTATION'!BM102 -> 0 | K26: =H26='BILLING COMPUTATION'!BM102 -> TRUE
C27: Basic Pay (adjustment) | H27: ='BILLING COMPUTATION'!BO102 -> 0 | K27: =H27='BILLING COMPUTATION'!BO102 -> TRUE
C28: Regular OT (adjustment) | H28: ='BILLING COMPUTATION'!BQ102 -> 0 | K28: =H28='BILLING COMPUTATION'!BQ102 -> TRUE
C29: Regular ND (adjustment) | H29: ='BILLING COMPUTATION'!BS102 -> 0 | K29: =H29='BILLING COMPUTATION'!BS102 -> TRUE
C30: Regular NDOT (adjustment) | I30: ='BILLING COMPUTATION'!BU102 -> 0
C31: Sunday Duty (adjustment) | H31: ='BILLING COMPUTATION'!BW102 -> 0 | K31: =H31='BILLING COMPUTATION'!BY103 -> TRUE
C32: Sunday OT (adjustment) | I32: ='BILLING COMPUTATION'!BY102 -> 0
C33: Unworked Legal Holiday ( adjustment ) | H33: ='BILLING COMPUTATION'!CC102 -> 0
C34: Late/Undertime | H34: ='BILLING COMPUTATION'!P102 -> -152.5 | K34: =H34='BILLING COMPUTATION'!P102 -> TRUE
C35: SIL | H35: ='BILLING COMPUTATION'!CF102 -> 0
C36: SSS | H36: ='BILLING COMPUTATION'!CI102 -> 78300 | K36: =H36='BILLING COMPUTATION'!CI102 -> TRUE
C37: EC | H37: ='BILLING COMPUTATION'!CK102 -> 34821.25 | K37: =H37='BILLING COMPUTATION'!CK102 -> TRUE
C38: Philhealth | H38: ='BILLING COMPUTATION'!CM102 -> 17800 | K38: =H38='BILLING COMPUTATION'!CM102 -> TRUE
C39: Pag-Ibig | H39: ='BILLING COMPUTATION'!CO102 -> 881668.12 | K39: =H39='BILLING COMPUTATION'!CO102 -> TRUE
C40: Total Billing Before Admin | H40: ='BILLING COMPUTATION'!CP102 -> 58724.75 | K40: ='BILLING COMPUTATION'!CP102 -> 58724.75
C41: Admin Fee | H41: =SUM(H14,H27,H34)*10% -> 58724.75 | K41: ='BILLING COMPUTATION'!CQ102 -> 940392.88
C43: Total Amount Billing : | H43: =H40+H41 -> 117449.5 | K43: =H43='BILLING COMPUTATION'!CT102 -> FALSE
C44: (See Attachment for Detailed Summary)
B48: ONE MILLION TWO HUNDRED FOURTY SEVEN THOUSAND SIX HUNDRED SIXTY TWO PESOS 93/100 ONLY. | G48: PHP | H48: =H43 -> 117449.5 | K48: =H48='BILLING COMPUTATION'!CT102 -> FALSE
A55: GRACE C. MALBATAAN | E55: CHRISTOPHER D. LAMARCA
...

Sheet Sales Invoice
C9: HYS Metal Plastic and Electronics | I9: =TODAY() -> 46234
C10: Blk 6-2 & 6-4 Amplefield SME Park JP Rizal Ave.
C11: Bugtong na Pulo,Lipa City Batangas 4225 | I11: 009-937-716-000
C16: Billing for the services rendered by Workers ( F3 MS)
C17: ='BILLING COMPUTATION'!C5 -> PAYROLL PERIOD: JULY 11-25, 2026
C19: Total Basic Salary | I19: ='BILLING COMPUTATION'!M102 -> 587400
C20: Admin Fee 10% | I20: ='BILLING COMPUTATION'!CP102 -> 58724.75
C21: TOTAL (exluded basic amount) | I21: ='BILLING COMPUTATION'!CG105 -> 669936.88
C22: Total After Admin | I22: =SUM(I19:I21) -> 1316061.6
C23: SSS ER | I23: ='BILLING COMPUTATION'!CH102 -> 156600
C24: SSS EC | I24: ='BILLING COMPUTATION'!CJ102 -> 2510
C25: PHILHEALTH | I25: ='BILLING COMPUTATION'!CK100 -> 34821.25
C26: PAG-IBIG | I26: ='BILLING COMPUTATION'!CM100 -> 17800
C27: Total Government Premium | I27: =SUM(I23:I26) -> 211731.25
C28: TOTAL BILLING AMOUNT | I28: =I22+I27 -> 1527792.9 | J28: =I28-ABS!H46 -> 587400
I33: =E41 -> 1527792.9
I34: =E40 -> 0
I35: =E41-I34 -> 1527792.9
I37: =I35-I36 -> 1527792.9
E38: =I28 -> 1527792.9 | I38: =ROUND(I28*0.02,2) -> 30555.86
I39: =I37-I38 -> 1497237
E40: =E37*0.12 -> 0 | I40: =E40 -> 0
E41: =SUM(E37:E40) -> 1527792.9 | I41: =SUM(I39:I40) -> 1497237

Sheet ABS
A1: GOLDENHAND MANAGEMENT SERVICES, INC.
A2: Unit 1&2 2/F 2560 Marcelita Bldg. Paciano Rizal 4027
A3: City of Calamba Laguna Philippines
A4: VAT Reg. TIN: 008-417-493-00001
A6: AGENCY BILLING SUMMARY
A8: Client Name | B8: HYS Metal Plastic and Electronics | H8: Issue Date | I8: =TODAY() -> 46234
A9: Client Address | B9: Blk 6-2 & 6-4 Amplefield SME Park JP Rizal Ave. Bugtong na Pulo,Lipa City Batangas 4225 | H9: TIN No.: | I9: 009-937-716-000
A11: P A R T I C U L A R S | H11: Amount
A13: Billing for the services rendered by: | D13: Workers ( F3 MS )
A14: ='BILLING COMPUTATION'!C5 -> PAYROLL PERIOD: JULY 11-25, 2026
B16: Head Count | D16: ='BILLING COMPUTATION'!A102 -> GRAND TOTAL | F16: MP=94
B17: Basic Pay | H17: ='BILLING COMPUTATION'!M102 -> 587400
B18: Reg Ot | H18: ='BILLING COMPUTATION'!S102 -> 65062.5
B19: Night Differential | H19: ='BILLING COMPUTATION'!V102 -> 15648.75
B20: Night Differential OT | I20: ='BILLING COMPUTATION'!Y102 -> 1978.125
B21: Sunday Duty | H21: ='BILLING COMPUTATION'!AB102 -> 0
B22: Sunday Excess | H22: ='BILLING COMPUTATION'!AE102 -> 0
B23: Sunday ND | H23: ='BILLING COMPUTATION'!AH102 -> 0
B24: Special Holiday | H24: ='BILLING COMPUTATION'!AT102 -> 0
B25: Special Holiday OT | H25: ='BILLING COMPUTATION'!AW102 -> 0
B26: Special Holiday ND | H26: ='BILLING COMPUTATION'!AZ102 -> 0
B27: Legal Holiday | H27: ='BILLING COMPUTATION'!BC102 -> 0
B28: Unworked Legal Holiday | H28: ='BILLING COMPUTATION'!BL102 -> 0
B29: Basic Pay (adjustment) | H29: ='BILLING COMPUTATION'!BO102 -> 0
B30: Regular OT (adjustment) | H30: ='BILLING COMPUTATION'!BQ102 -> 0
B31: Regular ND (adjustment) | H31: ='BILLING COMPUTATION'!BS102 -> 0
B32: Regular NDOT (adjustment) | H32: ='BILLING COMPUTATION'!BU102 -> 0
B33: Sunday Duty (adjustment) | H33: ='BILLING COMPUTATION'!BW102 -> 0
B34: Sunday OT (adjustment) | I34: ='BILLING COMPUTATION'!BY102 -> 0
B35: Legal Holiday (adjustment) | H35: ='BILLING COMPUTATION'!CE102 -> 0
B36: Unworked Legal Holiday ( adjustment ) | H36: ='BILLING COMPUTATION'!CC102 -> 0
B37: Late/Undertime | H37: ='BILLING COMPUTATION'!P102 -> -152.5
B38: Allowance | I38: 0
B39: SIL | H39: ='BILLING COMPUTATION'!CF102 -> 0
B40: SSS | H40: ='BILLING COMPUTATION'!CH102 -> 156600
B41: EC | H41: ='BILLING COMPUTATION'!CJ102 -> 2510
B42: Philhealth | H42: ='BILLING COMPUTATION'!CL102 -> 34821.25
B43: Pag-Ibig | H43: ='BILLING COMPUTATION'!CN102 -> 17800
B44: Total Billing Before Admin | H44: =SUM(H17:I43) -> 881668.12
B45: Admin Fee | H45: =SUM(H17,H29,H37)*10% -> 58724.75
...

Sheet BILLING COMPUTATION
C5: PAYROLL PERIOD: JULY 11-25, 2026
A6: No. | B6: FACTORY | C6: ID NO. | E6: NAMES OF EMPLOYEE | F6: BU | G6: DEPARTMENT | H6: POSITION | I6: IDL/DL | J6: REGULAR DAYS | N6: DEDUCTION | Q6: REGULAR OT | T6: REGULAR ND | W6: REGULAR ND OT | Z6: SUNDAY DUTY | AC6: SUNDAY OT EXCESS | AF6: SUNDAY ND | AI6: SPECIAL HOLIDAY+RD | AL6: SPECIAL HOLIDAY OT+RD | AO6: SPECIAL HOLIDAY ND+RD | AR6: SPECIAL HOLIDAY | AU6: SPECIAL HOLIDAY OT | AX6: SPECIAL HOLIDAY ND | BA6: LEGAL HOLIDAY | BD6: LEGAL HOLIDAY OT | BG6: LEGAL HOLIDAY ND | BJ6: UNWORKED LEGAL HOLIDAY | BM6: ADJUSTMENT | CE6: 5 Day's Service Incentive Leave | CG6: GROSS AMOUNT | CH6: MANDATORY | CO6: TOTAL BILLING BEFORE ADMIN FEE | CP6: Admin fee 10% | CQ6: BILLING AFTER ADMIN FEE | CR6: VAT 12% | CS6: TOTAL BILLING | CT6: 13 MONTH
D7: YS ID NO. | J7: NET REGULAR HRS | K7: Days | L7: RATE | M7: AMOUNT | N7: LATE/UNDERTIME IN MINUTES | O7: RATE | P7: AMOUNT | Q7: HOURS | R7: RATE | S7: AMOUNT | T7: HOURS | U7: RATE | V7: AMOUNT | W7: HOURS | X7: RATE | Y7: AMOUNT | Z7: HOURS | AA7: RATE | AB7: AMOUNT | AC7: HOURS | AD7: RATE | AE7: AMOUNT | AF7: HOURS | AG7: RATE | AH7: AMOUNT | AI7: HOURS | AJ7: RATE | AK7: AMOUNT | AL7: HOURS | AM7: RATE | AN7: AMOUNT | AO7: HOURS | AP7: RATE | AQ7: AMOUNT | AR7: HOURS | AS7: RATE | AT7: AMOUNT | AU7: HOURS | AV7: RATE | AW7: AMOUNT | AX7: HOURS | AY7: RATE | AZ7: AMOUNT | BA7: HOURS | BB7: RATE | BC7: AMOUNT | BD7: HOURS | BE7: RATE | BF7: AMOUNT | BG7: HOURS | BH7: RATE | BI7: AMOUNT | BJ7: HOURS | BK7: RATE | BL7: AMOUNT | BM7: REGULAR HOURS | BN7: AMOUNT | BO7: REGULAR OT HOURS | BP7: AMOUNT | BQ7: REGULAR ND HOURS | BR7: AMOUNT | BS7: REGULAR ND OT HOURS | BT7: AMOUNT | BU7: RD REG. HOURS | BV7: AMOUNT | BW7: RD OT HOURS | BX7: AMOUNT | BY7: RD ND HOURS | BZ7: AMOUNT | CA7: ULH | CB7: AMOUNT | CC7: LH | CD7: AMOUNT | CF7: Allowance | CH7: SSS ER | CI7: SSS EE | CJ7: EC | CK7: PHILHEALTH ER | CL7: PHILHEALTH EE | CM7: PAG-IBIG ER | CN7: PAG-IBIG EE | CU7: SIL | CV7: 1st Gross 600 | CW7: 2nd Gross | CX7: TOTAL
A8: 1 | C8: 30332 | D8: =VLOOKUP(E8,'F3 MS (2)'!E:F,2,0) -> GD250532 | E8: Acayin, Jerrick Butial | F8: =VLOOKUP(C8,'[1]ACTIVE GH'!$C:$I,7,0) -> METAL STAMPING | G8: =VLOOKUP(C8,'[1]ACTIVE GH'!$C:$J,8,0) -> PRODUCTION | H8: =VLOOKUP(C8,'[1]ACTIVE GH'!$C:$N,12,0) -> Operator 1 | I8: DL | J8: =IFERROR(VLOOKUP(C8,PIVOT!A:B,2,0),0) -> 56 | K8: =J8/8 -> 7 | L8: 600 | M8: =K8*L8 -> 4200 | N8: =IFERROR(VLOOKUP(C8,PIVOT!A:F,6,0),0) -> 0 | O8: =L8/8/60 -> 1.25 | P8: =-N8*O8 -> 0 | Q8: =IFERROR(VLOOKUP(C8,PIVOT!A:C,3,0),0) -> 2 | R8: =L8/8*1.25 -> 93.75 | S8: =Q8*R8 -> 187.5 | T8: =IFERROR(VLOOKUP(C8,PIVOT!A:D,4,0),0) -> 0 | U8: =L8/8*0.1 -> 7.5 | V8: =T8*U8 -> 0 | W8: =IFERROR(VLOOKUP(C8,PIVOT!A:E,5,0),0) -> 0 | X8: =L8/8*1.25*0.1 -> 9.375 | Y8: =X8*W8 -> 0 | Z8: =IFERROR(VLOOKUP(C8,#REF!,6,0),0) -> 0 | AA8: =L8/8*1.3 -> 97.5 | AB8: =Z8*AA8 -> 0 | AD8: =L8/8*1.69 -> 126.75 | AE8: =AD8*AC8 -> 0 | AF8: =IFERROR(VLOOKUP(C8,#REF!,8,0),0) -> 0 | AG8: =L8/8*1.3*0.1 -> 9.75 | AH8: =AF8*AG8 -> 0 | AJ8: =L8/8*1.5 -> 112.5 | AK8: =AI8*AJ8 -> 0 | AM8: =L8/8*1.5*1.3 -> 146.25 | AN8: 0 | AP8: =L8/8*1.5*0.1 -> 11.25 | AQ8: =AO8*AP8 -> 0 | AR8: =IFERROR(VLOOKUP(C8,#REF!,7,0),0) -> 0 | AS8: =L8/8*1.3 -> 97.5 | AT8: =AR8*AS8 -> 0 | AX8: =IFERROR(VLOOKUP(C8,#REF!,8,0),0) -> 0 | AY8: =L8/8*1.3*0.1 -> 9.75 | AZ8: =AX8*AY8 -> 0 | BA8: =IFERROR(VLOOKUP(C8,#REF!,10,0),0) -> 0 | BB8: =600/8*2 -> 150 | BC8: =BA8*BB8 -> 0 | BJ8: =IFERROR(VLOOKUP(C8,#REF!,9,0),0) -> 0 | BK8: =L8/8 -> 75 | BL8: =BJ8*BK8 -> 0 | CG8: =SUM(Y8,V8,S8,P8,M8) -> 4387.5 | CH8: =VLOOKUP(CX8,SSS_2025!A:N,8) -> 1500 | CI8: =VLOOKUP(CX8,SSS_2025!A:N,13) -> 750 | CJ8: =VLOOKUP(CX8,SSS_2025!A:N,9) -> 30 | CK8: 391.25 | CL8: 391.25 | CM8: 200 | CN8: 200 | CO8: =CG8+CH8+CJ8+CL8+CN8 -> 6508.75 | CP8: =(M8+P8+BN8)*10% -> 420 | CQ8: =CO8+CP8 -> 6928.75 | CS8: =CQ8+CR8 -> 6928.75 | CT8: =SUM(M8+(BC8/2)+BL8+BN8+P8)/12 -> 350 | CV8: =IFERROR(VLOOKUP(C8,'[2]BILLING COMPUTATION'!$C$8:$CI$224,85,0),0) -> 10552.5 | CW8: =CG8 -> 4387.5 | CX8: =CV8+CW8 -> 14940 | CZ8: =IFERROR(VLOOKUP(C8,'[5]BILLING COMPUTATION'!$C$8:$CG$101,83,0),0) -> 5550 | DA8: =CG8 -> 4387.5 | DB8: =SUM(CZ8:DA8) -> 9937.5 | DC8: =DB8-CX8 -> -5002.5
A9: 2 | C9: 12808 | D9: =VLOOKUP(E9,'F3 MS (2)'!E:F,2,0) -> GD250278 | E9: Aclan, Marvin Balmes | F9: =VLOOKUP(C9,'[1]ACTIVE GH'!$C:$I,7,0) -> METAL STAMPING | G9: =VLOOKUP(C9,'[1]ACTIVE GH'!$C:$J,8,0) -> PRODUCTION | H9: =VLOOKUP(C9,'[1]ACTIVE GH'!$C:$N,12,0) -> Operator 1 | I9: DL | J9: =IFERROR(VLOOKUP(C9,PIVOT!A:B,2,0),0) -> 80 | K9: =J9/8 -> 10 | L9: 600 | M9: =K9*L9 -> 6000 | N9: =IFERROR(VLOOKUP(C9,PIVOT!A:F,6,0),0) -> 0 | O9: =L9/8/60 -> 1.25 | P9: =-N9*O9 -> 0 | Q9: =IFERROR(VLOOKUP(C9,PIVOT!A:C,3,0),0) -> 6 | R9: =L9/8*1.25 -> 93.75 | S9: =Q9*R9 -> 562.5 | T9: =IFERROR(VLOOKUP(C9,PIVOT!A:D,4,0),0) -> 60 | U9: =L9/8*0.1 -> 7.5 | V9: =T9*U9 -> 450 | W9: =IFERROR(VLOOKUP(C9,PIVOT!A:E,5,0),0) -> 6 | X9: =L9/8*1.25*0.1 -> 9.375 | Y9: =X9*W9 -> 56.25 | Z9: =IFERROR(VLOOKUP(C9,#REF!,6,0),0) -> 0 | AA9: =L9/8*1.3 -> 97.5 | AB9: =Z9*AA9 -> 0 | AD9: =L9/8*1.69 -> 126.75 | AE9: =AD9*AC9 -> 0 | AF9: =IFERROR(VLOOKUP(C9,#REF!,8,0),0) -> 0 | AG9: =L9/8*1.3*0.1 -> 9.75 | AH9: =AF9*AG9 -> 0 | AJ9: =L9/8*1.5 -> 112.5 | AK9: =AI9*AJ9 -> 0 | AM9: =L9/8*1.5*1.3 -> 146.25 | AN9: 0 | AP9: =L9/8*1.5*0.1 -> 11.25 | AQ9: =AO9*AP9 -> 0 | AR9: =IFERROR(VLOOKUP(C9,#REF!,7,0),0) -> 0 | AS9: =L9/8*1.3 -> 97.5 | AT9: =AR9*AS9 -> 0 | AX9: =IFERROR(VLOOKUP(C9,#REF!,8,0),0) -> 0 | AY9: =L9/8*1.3*0.1 -> 9.75 | AZ9: =AX9*AY9 -> 0 | BA9: =IFERROR(VLOOKUP(C9,#REF!,10,0),0) -> 0 | BB9: =600/8*2 -> 150 | BC9: =BA9*BB9 -> 0 | BJ9: =IFERROR(VLOOKUP(C9,#REF!,9,0),0) -> 0 | BK9: =L9/8 -> 75 | BL9: =BJ9*BK9 -> 0 | CG9: =SUM(Y9,V9,S9,P9,M9) -> 7068.75 | CH9: =VLOOKUP(CX9,SSS_2025!A:N,8) -> 1750 | CI9: =VLOOKUP(CX9,SSS_2025!A:N,13) -> 875 | CJ9: =VLOOKUP(CX9,SSS_2025!A:N,9) -> 30 | CK9: 391.25 | CL9: 391.25 | CM9: 200 | CN9: 200 | CO9: =CG9+CH9+CJ9+CL9+CN9 -> 9440 | CP9: =(M9+P9+BN9)*10% -> 600 | CQ9: =CO9+CP9 -> 10040 | CS9: =CQ9+CR9 -> 10040 | CT9: =SUM(M9+(BC9/2)+BL9+BN9+P9)/12 -> 500 | CV9: =IFERROR(VLOOKUP(C9,'[2]BILLING COMPUTATION'!$C$8:$CI$224,85,0),0) -> 10680 | CW9: =CG9 -> 7068.75 | CX9: =CV9+CW9 -> 17748.75 | CZ9: =IFERROR(VLOOKUP(C9,'[5]BILLING COMPUTATION'!$C$8:$CG$101,83,0),0) -> 7918.125 | DA9: =CG9 -> 7068.75 | DB9: =SUM(CZ9:DA9) -> 14986.875 | DC9: =DB9-CX9 -> -2761.875
A10: 3 | C10: 12810 | D10: =VLOOKUP(E10,'F3 MS (2)'!E:F,2,0) -> GD250280 | E10: Acosta, Alexis Dorongon | F10: =VLOOKUP(C10,'[1]ACTIVE GH'!$C:$I,7,0) -> METAL STAMPING | G10: =VLOOKUP(C10,'[1]ACTIVE GH'!$C:$J,8,0) -> PRODUCTION | H10: =VLOOKUP(C10,'[1]ACTIVE GH'!$C:$N,12,0) -> Operator 1 | I10: DL | J10: =IFERROR(VLOOKUP(C10,PIVOT!A:B,2,0),0) -> 88 | K10: =J10/8 -> 11 | L10: 600 | M10: =K10*L10 -> 6600 | N10: =IFERROR(VLOOKUP(C10,PIVOT!A:F,6,0),0) -> 0 | O10: =L10/8/60 -> 1.25 | P10: =-N10*O10 -> 0 | Q10: =IFERROR(VLOOKUP(C10,PIVOT!A:C,3,0),0) -> 1 | R10: =L10/8*1.25 -> 93.75 | S10: =Q10*R10 -> 93.75 | T10: =IFERROR(VLOOKUP(C10,PIVOT!A:D,4,0),0) -> 6 | U10: =L10/8*0.1 -> 7.5 | V10: =T10*U10 -> 45 | W10: =IFERROR(VLOOKUP(C10,PIVOT!A:E,5,0),0) -> 0 | X10: =L10/8*1.25*0.1 -> 9.375 | Y10: =X10*W10 -> 0 | Z10: =IFERROR(VLOOKUP(C10,#REF!,6,0),0) -> 0 | AA10: =L10/8*1.3 -> 97.5 | AB10: =Z10*AA10 -> 0 | AD10: =L10/8*1.69 -> 126.75 | AE10: =AD10*AC10 -> 0 | AF10: =IFERROR(VLOOKUP(C10,#REF!,8,0),0) -> 0 | AG10: =L10/8*1.3*0.1 -> 9.75 | AH10: =AF10*AG10 -> 0 | AJ10: =L10/8*1.5 -> 112.5 | AK10: =AI10*AJ10 -> 0 | AM10: =L10/8*1.5*1.3 -> 146.25 | AN10: 0 | AP10: =L10/8*1.5*0.1 -> 11.25 | AQ10: =AO10*AP10 -> 0 | AR10: =IFERROR(VLOOKUP(C10,#REF!,7,0),0) -> 0 | AS10: =L10/8*1.3 -> 97.5 | AT10: =AR10*AS10 -> 0 | AX10: =IFERROR(VLOOKUP(C10,#REF!,8,0),0) -> 0 | AY10: =L10/8*1.3*0.1 -> 9.75 | AZ10: =AX10*AY10 -> 0 | BA10: =IFERROR(VLOOKUP(C10,#REF!,10,0),0) -> 0 | BB10: =600/8*2 -> 150 | BC10: =BA10*BB10 -> 0 | BJ10: =IFERROR(VLOOKUP(C10,#REF!,9,0),0) -> 0 | BK10: =L10/8 -> 75 | BL10: =BJ10*BK10 -> 0 | CG10: =SUM(Y10,V10,S10,P10,M10) -> 6738.75 | CH10: =VLOOKUP(CX10,SSS_2025!A:N,8) -> 1750 | CI10: =VLOOKUP(CX10,SSS_2025!A:N,13) -> 875 | CJ10: =VLOOKUP(CX10,SSS_2025!A:N,9) -> 30 | CK10: 391.25 | CL10: 391.25 | CM10: 200 | CN10: 200 | CO10: =CG10+CH10+CJ10+CL10+CN10 -> 9110 | CP10: =(M10+P10+BN10)*10% -> 660 | CQ10: =CO10+CP10 -> 9770 | CS10: =CQ10+CR10 -> 9770 | CT10: =SUM(M10+(BC10/2)+BL10+BN10+P10)/12 -> 550 | CV10: =IFERROR(VLOOKUP(C10,'[2]BILLING COMPUTATION'!$C$8:$CI$224,85,0),0) -> 10511.25 | CW10: =CG10 -> 6738.75 | CX10: =CV10+CW10 -> 17250 | CZ10: =IFERROR(VLOOKUP(C10,'[5]BILLING COMPUTATION'!$C$8:$CG$101,83,0),0) -> 9920 | DA10: =CG10 -> 6738.75 | DB10: =SUM(CZ10:DA10) -> 16658.75 | DC10: =DB10-CX10 -> -591.25
A11: 4 | C11: 4327 | D11: =VLOOKUP(E11,'F3 MS (2)'!E:F,2,0) -> GD250042 | E11: Ada, Joemer Vera | F11: =VLOOKUP(C11,'[1]ACTIVE GH'!$C:$I,7,0) -> METAL STAMPING | G11: =VLOOKUP(C11,'[1]ACTIVE GH'!$C:$J,8,0) -> PRODUCTION | H11: =VLOOKUP(C11,'[1]ACTIVE GH'!$C:$N,12,0) -> Operator 1 | I11: DL | J11: =IFERROR(VLOOKUP(C11,PIVOT!A:B,2,0),0) -> 80 | K11: =J11/8 -> 10 | L11: 600 | M11: =K11*L11 -> 6000 | N11: =IFERROR(VLOOKUP(C11,PIVOT!A:F,6,0),0) -> 0 | O11: =L11/8/60 -> 1.25 | P11: =-N11*O11 -> 0 | Q11: =IFERROR(VLOOKUP(C11,PIVOT!A:C,3,0),0) -> 2 | R11: =L11/8*1.25 -> 93.75 | S11: =Q11*R11 -> 187.5 | T11: =IFERROR(VLOOKUP(C11,PIVOT!A:D,4,0),0) -> 0 | U11: =L11/8*0.1 -> 7.5 | V11: =T11*U11 -> 0 | W11: =IFERROR(VLOOKUP(C11,PIVOT!A:E,5,0),0) -> 0 | X11: =L11/8*1.25*0.1 -> 9.375 | Y11: =X11*W11 -> 0 | Z11: =IFERROR(VLOOKUP(C11,#REF!,6,0),0) -> 0 | AA11: =L11/8*1.3 -> 97.5 | AB11: =Z11*AA11 -> 0 | AD11: =L11/8*1.69 -> 126.75 | AE11: =AD11*AC11 -> 0 | AF11: =IFERROR(VLOOKUP(C11,#REF!,8,0),0) -> 0 | AG11: =L11/8*1.3*0.1 -> 9.75 | AH11: =AF11*AG11 -> 0 | AJ11: =L11/8*1.5 -> 112.5 | AK11: =AI11*AJ11 -> 0 | AM11: =L11/8*1.5*1.3 -> 146.25 | AN11: 0 | AP11: =L11/8*1.5*0.1 -> 11.25 | AQ11: =AO11*AP11 -> 0 | AR11: =IFERROR(VLOOKUP(C11,#REF!,7,0),0) -> 0 | AS11: =L11/8*1.3 -> 97.5 | AT11: =AR11*AS11 -> 0 | AX11: =IFERROR(VLOOKUP(C11,#REF!,8,0),0) -> 0 | AY11: =L11/8*1.3*0.1 -> 9.75 | AZ11: =AX11*AY11 -> 0 | BA11: =IFERROR(VLOOKUP(C11,#REF!,10,0),0) -> 0 | BB11: =600/8*2 -> 150 | BC11: =BA11*BB11 -> 0 | BJ11: =IFERROR(VLOOKUP(C11,#REF!,9,0),0) -> 0 | BK11: =L11/8 -> 75 | BL11: =BJ11*BK11 -> 0 | CG11: =SUM(Y11,V11,S11,P11,M11) -> 6187.5 | CH11: =VLOOKUP(CX11,SSS_2025!A:N,8) -> 1350 | CI11: =VLOOKUP(CX11,SSS_2025!A:N,13) -> 675 | CJ11: =VLOOKUP(CX11,SSS_2025!A:N,9) -> 10 | CK11: 391.25 | CL11: 391.25 | CM11: 200 | CN11: 200 | CO11: =CG11+CH11+CJ11+CL11+CN11 -> 8138.75 | CP11: =(M11+P11+BN11)*10% -> 600 | CQ11: =CO11+CP11 -> 8738.75 | CS11: =CQ11+CR11 -> 8738.75 | CT11: =SUM(M11+(BC11/2)+BL11+BN11+P11)/12 -> 500 | CV11: =IFERROR(VLOOKUP(C11,'[2]BILLING COMPUTATION'!$C$8:$CI$224,85,0),0) -> 7140 | CW11: =CG11 -> 6187.5 | CX11: =CV11+CW11 -> 13327.5 | CZ11: =IFERROR(VLOOKUP(C11,'[5]BILLING COMPUTATION'!$C$8:$CG$101,83,0),0) -> 6330 | DA11: =CG11 -> 6187.5 | DB11: =SUM(CZ11:DA11) -> 12517.5 | DC11: =DB11-CX11 -> -810
A12: 5 | C12: 12816 | D12: =VLOOKUP(E12,'F3 MS (2)'!E:F,2,0) -> GD250285 | E12: Aguilera, Baby Rose Lacbay | F12: =VLOOKUP(C12,'[1]ACTIVE GH'!$C:$I,7,0) -> METAL STAMPING | G12: =VLOOKUP(C12,'[1]ACTIVE GH'!$C:$J,8,0) -> PRODUCTION | H12: =VLOOKUP(C12,'[1]ACTIVE GH'!$C:$N,12,0) -> Operator 1 | I12: DL | J12: =IFERROR(VLOOKUP(C12,PIVOT!A:B,2,0),0) -> 96 | K12: =J12/8 -> 12 | L12: 600 | M12: =K12*L12 -> 7200 | N12: =IFERROR(VLOOKUP(C12,PIVOT!A:F,6,0),0) -> 0 | O12: =L12/8/60 -> 1.25 | P12: =-N12*O12 -> 0 | Q12: =IFERROR(VLOOKUP(C12,PIVOT!A:C,3,0),0) -> 20 | R12: =L12/8*1.25 -> 93.75 | S12: =Q12*R12 -> 1875 | T12: =IFERROR(VLOOKUP(C12,PIVOT!A:D,4,0),0) -> 0 | U12: =L12/8*0.1 -> 7.5 | V12: =T12*U12 -> 0 | W12: =IFERROR(VLOOKUP(C12,PIVOT!A:E,5,0),0) -> 0 | X12: =L12/8*1.25*0.1 -> 9.375 | Y12: =X12*W12 -> 0 | Z12: =IFERROR(VLOOKUP(C12,#REF!,6,0),0) -> 0 | AA12: =L12/8*1.3 -> 97.5 | AB12: =Z12*AA12 -> 0 | AD12: =L12/8*1.69 -> 126.75 | AE12: =AD12*AC12 -> 0 | AF12: =IFERROR(VLOOKUP(C12,#REF!,8,0),0) -> 0 | AG12: =L12/8*1.3*0.1 -> 9.75 | AH12: =AF12*AG12 -> 0 | AJ12: =L12/8*1.5 -> 112.5 | AK12: =AI12*AJ12 -> 0 | AM12: =L12/8*1.5*1.3 -> 146.25 | AN12: 0 | AP12: =L12/8*1.5*0.1 -> 11.25 | AQ12: =AO12*AP12 -> 0 | AR12: =IFERROR(VLOOKUP(C12,#REF!,7,0),0) -> 0 | AS12: =L12/8*1.3 -> 97.5 | AT12: =AR12*AS12 -> 0 | AX12: =IFERROR(VLOOKUP(C12,#REF!,8,0),0) -> 0 | AY12: =L12/8*1.3*0.1 -> 9.75 | AZ12: =AX12*AY12 -> 0 | BA12: =IFERROR(VLOOKUP(C12,#REF!,10,0),0) -> 0 | BB12: =600/8*2 -> 150 | BC12: =BA12*BB12 -> 0 | BJ12: =IFERROR(VLOOKUP(C12,#REF!,9,0),0) -> 0 | BK12: =L12/8 -> 75 | BL12: =BJ12*BK12 -> 0 | CG12: =SUM(Y12,V12,S12,P12,M12) -> 9075 | CH12: =VLOOKUP(CX12,SSS_2025!A:N,8) -> 1950 | CI12: =VLOOKUP(CX12,SSS_2025!A:N,13) -> 975 | CJ12: =VLOOKUP(CX12,SSS_2025!A:N,9) -> 30 | CK12: 391.25 | CL12: 391.25 | CM12: 200 | CN12: 200 | CO12: =CG12+CH12+CJ12+CL12+CN12 -> 11646.25 | CP12: =(M12+P12+BN12)*10% -> 720 | CQ12: =CO12+CP12 -> 12366.25 | CS12: =CQ12+CR12 -> 12366.25 | CT12: =SUM(M12+(BC12/2)+BL12+BN12+P12)/12 -> 600 | CV12: =IFERROR(VLOOKUP(C12,'[2]BILLING COMPUTATION'!$C$8:$CI$224,85,0),0) -> 10671.25 | CW12: =CG12 -> 9075 | CX12: =CV12+CW12 -> 19746.25 | CZ12: =IFERROR(VLOOKUP(C12,'[5]BILLING COMPUTATION'!$C$8:$CG$101,83,0),0) -> 8985 | DA12: =CG12 -> 9075 | DB12: =SUM(CZ12:DA12) -> 18060 | DC12: =DB12-CX12 -> -1686.25
A13: 6 | C13: 14479 | D13: =VLOOKUP(E13,'F3 MS (2)'!E:F,2,0) -> GD250252 | E13: Albaña, Rose Marie Esternon | F13: =VLOOKUP(C13,'[1]ACTIVE GH'!$C:$I,7,0) -> METAL STAMPING | G13: =VLOOKUP(C13,'[1]ACTIVE GH'!$C:$J,8,0) -> PRODUCTION | H13: =VLOOKUP(C13,'[1]ACTIVE GH'!$C:$N,12,0) -> Operator 1 | I13: DL | J13: =IFERROR(VLOOKUP(C13,PIVOT!A:B,2,0),0) -> 96 | K13: =J13/8 -> 12 | L13: 600 | M13: =K13*L13 -> 7200 | N13: =IFERROR(VLOOKUP(C13,PIVOT!A:F,6,0),0) -> 0 | O13: =L13/8/60 -> 1.25 | P13: =-N13*O13 -> 0 | Q13: =IFERROR(VLOOKUP(C13,PIVOT!A:C,3,0),0) -> 10 | R13: =L13/8*1.25 -> 93.75 | S13: =Q13*R13 -> 937.5 | T13: =IFERROR(VLOOKUP(C13,PIVOT!A:D,4,0),0) -> 6 | U13: =L13/8*0.1 -> 7.5 | V13: =T13*U13 -> 45 | W13: =IFERROR(VLOOKUP(C13,PIVOT!A:E,5,0),0) -> 0 | X13: =L13/8*1.25*0.1 -> 9.375 | Y13: =X13*W13 -> 0 | Z13: =IFERROR(VLOOKUP(C13,#REF!,6,0),0) -> 0 | AA13: =L13/8*1.3 -> 97.5 | AB13: =Z13*AA13 -> 0 | AD13: =L13/8*1.69 -> 126.75 | AE13: =AD13*AC13 -> 0 | AF13: =IFERROR(VLOOKUP(C13,#REF!,8,0),0) -> 0 | AG13: =L13/8*1.3*0.1 -> 9.75 | AH13: =AF13*AG13 -> 0 | AJ13: =L13/8*1.5 -> 112.5 | AK13: =AI13*AJ13 -> 0 | AM13: =L13/8*1.5*1.3 -> 146.25 | AN13: 0 | AP13: =L13/8*1.5*0.1 -> 11.25 | AQ13: =AO13*AP13 -> 0 | AR13: =IFERROR(VLOOKUP(C13,#REF!,7,0),0) -> 0 | AS13: =L13/8*1.3 -> 97.5 | AT13: =AR13*AS13 -> 0 | AX13: =IFERROR(VLOOKUP(C13,#REF!,8,0),0) -> 0 | AY13: =L13/8*1.3*0.1 -> 9.75 | AZ13: =AX13*AY13 -> 0 | BA13: =IFERROR(VLOOKUP(C13,#REF!,10,0),0) -> 0 | BB13: =600/8*2 -> 150 | BC13: =BA13*BB13 -> 0 | BJ13: =IFERROR(VLOOKUP(C13,#REF!,9,0),0) -> 0 | BK13: =L13/8 -> 75 | BL13: =BJ13*BK13 -> 0 | CG13: =SUM(Y13,V13,S13,P13,M13) -> 8182.5 | CH13: =VLOOKUP(CX13,SSS_2025!A:N,8) -> 1950 | CI13: =VLOOKUP(CX13,SSS_2025!A:N,13) -> 975 | CJ13: =VLOOKUP(CX13,SSS_2025!A:N,9) -> 30 | CK13: 391.25 | CL13: 391.25 | CM13: 200 | CN13: 200 | CO13: =CG13+CH13+CJ13+CL13+CN13 -> 10753.75 | CP13: =(M13+P13+BN13)*10% -> 720 | CQ13: =CO13+CP13 -> 11473.75 | CS13: =CQ13+CR13 -> 11473.75 | CT13: =SUM(M13+(BC13/2)+BL13+BN13+P13)/12 -> 600 | CV13: =IFERROR(VLOOKUP(C13,'[2]BILLING COMPUTATION'!$C$8:$CI$224,85,0),0) -> 11403.75 | CW13: =CG13 -> 8182.5 | CX13: =CV13+CW13 -> 19586.25 | CZ13: =IFERROR(VLOOKUP(C13,'[5]BILLING COMPUTATION'!$C$8:$CG$101,83,0),0) -> 9075 | DA13: =CG13 -> 8182.5 | DB13: =SUM(CZ13:DA13) -> 17257.5 | DC13: =DB13-CX13 -> -2328.75
A14: 7 | C14: 12830 | D14: =VLOOKUP(E14,'F3 MS (2)'!E:F,2,0) -> GD250292 | E14: Ampon, Jerrold Mark Anday | F14: =VLOOKUP(C14,'[1]ACTIVE GH'!$C:$I,7,0) -> METAL STAMPING | G14: =VLOOKUP(C14,'[1]ACTIVE GH'!$C:$J,8,0) -> PRODUCTION | H14: =VLOOKUP(C14,'[1]ACTIVE GH'!$C:$N,12,0) -> Operator 1 | I14: DL | J14: =IFERROR(VLOOKUP(C14,PIVOT!A:B,2,0),0) -> 92 | K14: =J14/8 -> 11.5 | L14: 600 | M14: =K14*L14 -> 6900 | N14: =IFERROR(VLOOKUP(C14,PIVOT!A:F,6,0),0) -> 0 | O14: =L14/8/60 -> 1.25 | P14: =-N14*O14 -> 0 | Q14: =IFERROR(VLOOKUP(C14,PIVOT!A:C,3,0),0) -> 16 | R14: =L14/8*1.25 -> 93.75 | S14: =Q14*R14 -> 1500 | T14: =IFERROR(VLOOKUP(C14,PIVOT!A:D,4,0),0) -> 66 | U14: =L14/8*0.1 -> 7.5 | V14: =T14*U14 -> 495 | W14: =IFERROR(VLOOKUP(C14,PIVOT!A:E,5,0),0) -> 16 | X14: =L14/8*1.25*0.1 -> 9.375 | Y14: =X14*W14 -> 150 | Z14: =IFERROR(VLOOKUP(C14,#REF!,6,0),0) -> 0 | AA14: =L14/8*1.3 -> 97.5 | AB14: =Z14*AA14 -> 0 | AD14: =L14/8*1.69 -> 126.75 | AE14: =AD14*AC14 -> 0 | AF14: =IFERROR(VLOOKUP(C14,#REF!,8,0),0) -> 0 | AG14: =L14/8*1.3*0.1 -> 9.75 | AH14: =AF14*AG14 -> 0 | AJ14: =L14/8*1.5 -> 112.5 | AK14: =AI14*AJ14 -> 0 | AM14: =L14/8*1.5*1.3 -> 146.25 | AN14: 0 | AP14: =L14/8*1.5*0.1 -> 11.25 | AQ14: =AO14*AP14 -> 0 | AR14: =IFERROR(VLOOKUP(C14,#REF!,7,0),0) -> 0 | AS14: =L14/8*1.3 -> 97.5 | AT14: =AR14*AS14 -> 0 | AX14: =IFERROR(VLOOKUP(C14,#REF!,8,0),0) -> 0 | AY14: =L14/8*1.3*0.1 -> 9.75 | AZ14: =AX14*AY14 -> 0 | BA14: =IFERROR(VLOOKUP(C14,#REF!,10,0),0) -> 0 | BB14: =600/8*2 -> 150 | BC14: =BA14*BB14 -> 0 | BJ14: =IFERROR(VLOOKUP(C14,#REF!,9,0),0) -> 0 | BK14: =L14/8 -> 75 | BL14: =BJ14*BK14 -> 0 | CG14: =SUM(Y14,V14,S14,P14,M14) -> 9045 | CH14: =VLOOKUP(CX14,SSS_2025!A:N,8) -> 1950 | CI14: =VLOOKUP(CX14,SSS_2025!A:N,13) -> 975 | CJ14: =VLOOKUP(CX14,SSS_2025!A:N,9) -> 30 | CK14: 391.25 | CL14: 391.25 | CM14: 200 | CN14: 200 | CO14: =CG14+CH14+CJ14+CL14+CN14 -> 11616.25 | CP14: =(M14+P14+BN14)*10% -> 690 | CQ14: =CO14+CP14 -> 12306.25 | CS14: =CQ14+CR14 -> 12306.25 | CT14: =SUM(M14+(BC14/2)+BL14+BN14+P14)/12 -> 575 | CV14: =IFERROR(VLOOKUP(C14,'[2]BILLING COMPUTATION'!$C$8:$CI$224,85,0),0) -> 10492.5 | CW14: =CG14 -> 9045 | CX14: =CV14+CW14 -> 19537.5 | CZ14: =IFERROR(VLOOKUP(C14,'[5]BILLING COMPUTATION'!$C$8:$CG$101,83,0),0) -> 10001.25 | DA14: =CG14 -> 9045 | DB14: =SUM(CZ14:DA14) -> 19046.25 | DC14: =DB14-CX14 -> -491.25
A15: 8 | C15: 5076 | D15: =VLOOKUP(E15,'F3 MS (2)'!E:F,2,0) -> GD250017 | E15: Aragdon, Edmun Aguilar | F15: =VLOOKUP(C15,'[1]ACTIVE GH'!$C:$I,7,0) -> METAL STAMPING | G15: =VLOOKUP(C15,'[1]ACTIVE GH'!$C:$J,8,0) -> PRODUCTION | H15: =VLOOKUP(C15,'[1]ACTIVE GH'!$C:$N,12,0) -> Operator 1 | I15: DL | J15: =IFERROR(VLOOKUP(C15,PIVOT!A:B,2,0),0) -> 88 | K15: =J15/8 -> 11 | L15: 600 | M15: =K15*L15 -> 6600 | N15: =IFERROR(VLOOKUP(C15,PIVOT!A:F,6,0),0) -> 0 | O15: =L15/8/60 -> 1.25 | P15: =-N15*O15 -> 0 | Q15: =IFERROR(VLOOKUP(C15,PIVOT!A:C,3,0),0) -> 0 | R15: =L15/8*1.25 -> 93.75 | S15: =Q15*R15 -> 0 | T15: =IFERROR(VLOOKUP(C15,PIVOT!A:D,4,0),0) -> 0 | U15: =L15/8*0.1 -> 7.5 | V15: =T15*U15 -> 0 | W15: =IFERROR(VLOOKUP(C15,PIVOT!A:E,5,0),0) -> 0 | X15: =L15/8*1.25*0.1 -> 9.375 | Y15: =X15*W15 -> 0 | Z15: =IFERROR(VLOOKUP(C15,#REF!,6,0),0) -> 0 | AA15: =L15/8*1.3 -> 97.5 | AB15: =Z15*AA15 -> 0 | AD15: =L15/8*1.69 -> 126.75 | AE15: =AD15*AC15 -> 0 | AF15: =IFERROR(VLOOKUP(C15,#REF!,8,0),0) -> 0 | AG15: =L15/8*1.3*0.1 -> 9.75 | AH15: =AF15*AG15 -> 0 | AJ15: =L15/8*1.5 -> 112.5 | AK15: =AI15*AJ15 -> 0 | AM15: =L15/8*1.5*1.3 -> 146.25 | AN15: 0 | AP15: =L15/8*1.5*0.1 -> 11.25 | AQ15: =AO15*AP15 -> 0 | AR15: =IFERROR(VLOOKUP(C15,#REF!,7,0),0) -> 0 | AS15: =L15/8*1.3 -> 97.5 | AT15: =AR15*AS15 -> 0 | AX15: =IFERROR(VLOOKUP(C15,#REF!,8,0),0) -> 0 | AY15: =L15/8*1.3*0.1 -> 9.75 | AZ15: =AX15*AY15 -> 0 | BA15: =IFERROR(VLOOKUP(C15,#REF!,10,0),0) -> 0 | BB15: =600/8*2 -> 150 | BC15: =BA15*BB15 -> 0 | BJ15: =IFERROR(VLOOKUP(C15,#REF!,9,0),0) -> 0 | BK15: =L15/8 -> 75 | BL15: =BJ15*BK15 -> 0 | CG15: =SUM(Y15,V15,S15,P15,M15) -> 6600 | CH15: =VLOOKUP(CX15,SSS_2025!A:N,8) -> 1450 | CI15: =VLOOKUP(CX15,SSS_2025!A:N,13) -> 725 | CJ15: =VLOOKUP(CX15,SSS_2025!A:N,9) -> 10 | CK15: 391.25 | CL15: 391.25 | CM15: 200 | CN15: 200 | CO15: =CG15+CH15+CJ15+CL15+CN15 -> 8651.25 | CP15: =(M15+P15+BN15)*10% -> 660 | CQ15: =CO15+CP15 -> 9311.25 | CS15: =CQ15+CR15 -> 9311.25 | CT15: =SUM(M15+(BC15/2)+BL15+BN15+P15)/12 -> 550 | CV15: =IFERROR(VLOOKUP(C15,'[2]BILLING COMPUTATION'!$C$8:$CI$224,85,0),0) -> 8126.25 | CW15: =CG15 -> 6600 | CX15: =CV15+CW15 -> 14726.25 | CZ15: =IFERROR(VLOOKUP(C15,'[5]BILLING COMPUTATION'!$C$8:$CG$101,83,0),0) -> 8520 | DA15: =CG15 -> 6600 | DB15: =SUM(CZ15:DA15) -> 15120 | DC15: =DB15-CX15 -> 393.75
A16: 10 | C16: 32436 | D16: =VLOOKUP(E16,'F3 MS (2)'!E:F,2,0) -> GD260698 | E16: Bajamonde, Marlon San Andres | F16: =VLOOKUP(C16,'[1]ACTIVE GH'!$C:$I,7,0) -> METAL STAMPING | G16: =VLOOKUP(C16,'[1]ACTIVE GH'!$C:$J,8,0) -> PRODUCTION | H16: =VLOOKUP(C16,'[1]ACTIVE GH'!$C:$N,12,0) -> Operator 1 | I16: DL | J16: =IFERROR(VLOOKUP(C16,PIVOT!A:B,2,0),0) -> 80 | K16: =J16/8 -> 10 | L16: 600 | M16: =K16*L16 -> 6000 | N16: =IFERROR(VLOOKUP(C16,PIVOT!A:F,6,0),0) -> 0 | O16: =L16/8/60 -> 1.25 | P16: =-N16*O16 -> 0 | Q16: =IFERROR(VLOOKUP(C16,PIVOT!A:C,3,0),0) -> 8 | R16: =L16/8*1.25 -> 93.75 | S16: =Q16*R16 -> 750 | T16: =IFERROR(VLOOKUP(C16,PIVOT!A:D,4,0),0) -> 60 | U16: =L16/8*0.1 -> 7.5 | V16: =T16*U16 -> 450 | W16: =IFERROR(VLOOKUP(C16,PIVOT!A:E,5,0),0) -> 8 | X16: =L16/8*1.25*0.1 -> 9.375 | Y16: =X16*W16 -> 75 | Z16: =IFERROR(VLOOKUP(C16,#REF!,6,0),0) -> 0 | AA16: =L16/8*1.3 -> 97.5 | AB16: =Z16*AA16 -> 0 | AD16: =L16/8*1.69 -> 126.75 | AE16: =AD16*AC16 -> 0 | AF16: =IFERROR(VLOOKUP(C16,#REF!,8,0),0) -> 0 | AG16: =L16/8*1.3*0.1 -> 9.75 | AH16: =AF16*AG16 -> 0 | AJ16: =L16/8*1.5 -> 112.5 | AK16: =AI16*AJ16 -> 0 | AM16: =L16/8*1.5*1.3 -> 146.25 | AN16: 0 | AP16: =L16/8*1.5*0.1 -> 11.25 | AQ16: =AO16*AP16 -> 0 | AR16: =IFERROR(VLOOKUP(C16,#REF!,7,0),0) -> 0 | AS16: =L16/8*1.3 -> 97.5 | AT16: =AR16*AS16 -> 0 | AX16: =IFERROR(VLOOKUP(C16,#REF!,8,0),0) -> 0 | AY16: =L16/8*1.3*0.1 -> 9.75 | AZ16: =AX16*AY16 -> 0 | BA16: =IFERROR(VLOOKUP(C16,#REF!,10,0),0) -> 0 | BB16: =600/8*2 -> 150 | BC16: =BA16*BB16 -> 0 | BJ16: =IFERROR(VLOOKUP(C16,#REF!,9,0),0) -> 0 | BK16: =L16/8 -> 75 | BL16: =BJ16*BK16 -> 0 | CG16: =SUM(Y16,V16,S16,P16,M16) -> 7275 | CH16: =VLOOKUP(CX16,SSS_2025!A:N,8) -> 1800 | CI16: =VLOOKUP(CX16,SSS_2025!A:N,13) -> 900 | CJ16: =VLOOKUP(CX16,SSS_2025!A:N,9) -> 30 | CK16: 391.25 | CL16: 391.25 | CM16: 200 | CN16: 200 | CO16: =CG16+CH16+CJ16+CL16+CN16 -> 9696.25 | CP16: =(M16+P16+BN16)*10% -> 600 | CQ16: =CO16+CP16 -> 10296.25 | CS16: =CQ16+CR16 -> 10296.25 | CT16: =SUM(M16+(BC16/2)+BL16+BN16+P16)/12 -> 500 | CV16: =IFERROR(VLOOKUP(C16,'[2]BILLING COMPUTATION'!$C$8:$CI$224,85,0),0) -> 10492.5 | CW16: =CG16 -> 7275 | CX16: =CV16+CW16 -> 17767.5 | CZ16: =IFERROR(VLOOKUP(C16,'[5]BILLING COMPUTATION'!$C$8:$CG$101,83,0),0) -> 7871.25 | DA16: =CG16 -> 7275 | DB16: =SUM(CZ16:DA16) -> 15146.25 | DC16: =DB16-CX16 -> -2621.25
A17: 11 | C17: 14760 | D17: =VLOOKUP(E17,'F3 MS (2)'!E:F,2,0) -> GD250201 | E17: Balba, Christopher Laloma | F17: =VLOOKUP(C17,'[1]ACTIVE GH'!$C:$I,7,0) -> METAL STAMPING | G17: =VLOOKUP(C17,'[1]ACTIVE GH'!$C:$J,8,0) -> PRODUCTION | H17: =VLOOKUP(C17,'[1]ACTIVE GH'!$C:$N,12,0) -> Operator 1 | I17: DL | J17: =IFERROR(VLOOKUP(C17,PIVOT!A:B,2,0),0) -> 88 | K17: =J17/8 -> 11 | L17: 600 | M17: =K17*L17 -> 6600 | N17: =IFERROR(VLOOKUP(C17,PIVOT!A:F,6,0),0) -> 0 | O17: =L17/8/60 -> 1.25 | P17: =-N17*O17 -> 0 | Q17: =IFERROR(VLOOKUP(C17,PIVOT!A:C,3,0),0) -> 14 | R17: =L17/8*1.25 -> 93.75 | S17: =Q17*R17 -> 1312.5 | T17: =IFERROR(VLOOKUP(C17,PIVOT!A:D,4,0),0) -> 66 | U17: =L17/8*0.1 -> 7.5 | V17: =T17*U17 -> 495 | W17: =IFERROR(VLOOKUP(C17,PIVOT!A:E,5,0),0) -> 14 | X17: =L17/8*1.25*0.1 -> 9.375 | Y17: =X17*W17 -> 131.25 | Z17: =IFERROR(VLOOKUP(C17,#REF!,6,0),0) -> 0 | AA17: =L17/8*1.3 -> 97.5 | AB17: =Z17*AA17 -> 0 | AD17: =L17/8*1.69 -> 126.75 | AE17: =AD17*AC17 -> 0 | AF17: =IFERROR(VLOOKUP(C17,#REF!,8,0),0) -> 0 | AG17: =L17/8*1.3*0.1 -> 9.75 | AH17: =AF17*AG17 -> 0 | AJ17: =L17/8*1.5 -> 112.5 | AK17: =AI17*AJ17 -> 0 | AM17: =L17/8*1.5*1.3 -> 146.25 | AN17: 0 | AP17: =L17/8*1.5*0.1 -> 11.25 | AQ17: =AO17*AP17 -> 0 | AR17: =IFERROR(VLOOKUP(C17,#REF!,7,0),0) -> 0 | AS17: =L17/8*1.3 -> 97.5 | AT17: =AR17*AS17 -> 0 | AX17: =IFERROR(VLOOKUP(C17,#REF!,8,0),0) -> 0 | AY17: =L17/8*1.3*0.1 -> 9.75 | AZ17: =AX17*AY17 -> 0 | BA17: =IFERROR(VLOOKUP(C17,#REF!,10,0),0) -> 0 | BB17: =600/8*2 -> 150 | BC17: =BA17*BB17 -> 0 | BJ17: =IFERROR(VLOOKUP(C17,#REF!,9,0),0) -> 0 | BK17: =L17/8 -> 75 | BL17: =BJ17*BK17 -> 0 | CG17: =SUM(Y17,V17,S17,P17,M17) -> 8538.75 | CH17: =VLOOKUP(CX17,SSS_2025!A:N,8) -> 1900 | CI17: =VLOOKUP(CX17,SSS_2025!A:N,13) -> 950 | CJ17: =VLOOKUP(CX17,SSS_2025!A:N,9) -> 30 | CK17: 391.25 | CL17: 391.25 | CM17: 200 | CN17: 200 | CO17: =CG17+CH17+CJ17+CL17+CN17 -> 11060 | CP17: =(M17+P17+BN17)*10% -> 660 | CQ17: =CO17+CP17 -> 11720 | CS17: =CQ17+CR17 -> 11720 | CT17: =SUM(M17+(BC17/2)+BL17+BN17+P17)/12 -> 550 | CV17: =IFERROR(VLOOKUP(C17,'[2]BILLING COMPUTATION'!$C$8:$CI$224,85,0),0) -> 10698.75 | CW17: =CG17 -> 8538.75 | CX17: =CV17+CW17 -> 19237.5 | CZ17: =IFERROR(VLOOKUP(C17,'[5]BILLING COMPUTATION'!$C$8:$CG$101,83,0),0) -> 10141.875 | DA17: =CG17 -> 8538.75 | DB17: =SUM(CZ17:DA17) -> 18680.625 | DC17: =DB17-CX17 -> -556.875
A18: 12 | C18: 30679 | D18: =VLOOKUP(E18,'F3 MS (2)'!E:F,2,0) -> GD250548 | E18: Bardon, Norly Villacruel | F18: =VLOOKUP(C18,'[1]ACTIVE GH'!$C:$I,7,0) -> METAL STAMPING | G18: =VLOOKUP(C18,'[1]ACTIVE GH'!$C:$J,8,0) -> PRODUCTION | H18: =VLOOKUP(C18,'[1]ACTIVE GH'!$C:$N,12,0) -> Operator 1 | I18: DL | J18: =IFERROR(VLOOKUP(C18,PIVOT!A:B,2,0),0) -> 88 | K18: =J18/8 -> 11 | L18: 600 | M18: =K18*L18 -> 6600 | N18: =IFERROR(VLOOKUP(C18,PIVOT!A:F,6,0),0) -> 0 | O18: =L18/8/60 -> 1.25 | P18: =-N18*O18 -> 0 | Q18: =IFERROR(VLOOKUP(C18,PIVOT!A:C,3,0),0) -> 6 | R18: =L18/8*1.25 -> 93.75 | S18: =Q18*R18 -> 562.5 | T18: =IFERROR(VLOOKUP(C18,PIVOT!A:D,4,0),0) -> 60 | U18: =L18/8*0.1 -> 7.5 | V18: =T18*U18 -> 450 | W18: =IFERROR(VLOOKUP(C18,PIVOT!A:E,5,0),0) -> 6 | X18: =L18/8*1.25*0.1 -> 9.375 | Y18: =X18*W18 -> 56.25 | Z18: =IFERROR(VLOOKUP(C18,#REF!,6,0),0) -> 0 | AA18: =L18/8*1.3 -> 97.5 | AB18: =Z18*AA18 -> 0 | AD18: =L18/8*1.69 -> 126.75 | AE18: =AD18*AC18 -> 0 | AF18: =IFERROR(VLOOKUP(C18,#REF!,8,0),0) -> 0 | AG18: =L18/8*1.3*0.1 -> 9.75 | AH18: =AF18*AG18 -> 0 | AJ18: =L18/8*1.5 -> 112.5 | AK18: =AI18*AJ18 -> 0 | AM18: =L18/8*1.5*1.3 -> 146.25 | AN18: 0 | AP18: =L18/8*1.5*0.1 -> 11.25 | AQ18: =AO18*AP18 -> 0 | AR18: =IFERROR(VLOOKUP(C18,#REF!,7,0),0) -> 0 | AS18: =L18/8*1.3 -> 97.5 | AT18: =AR18*AS18 -> 0 | AX18: =IFERROR(VLOOKUP(C18,#REF!,8,0),0) -> 0 | AY18: =L18/8*1.3*0.1 -> 9.75 | AZ18: =AX18*AY18 -> 0 | BA18: =IFERROR(VLOOKUP(C18,#REF!,10,0),0) -> 0 | BB18: =600/8*2 -> 150 | BC18: =BA18*BB18 -> 0 | BJ18: =IFERROR(VLOOKUP(C18,#REF!,9,0),0) -> 0 | BK18: =L18/8 -> 75 | BL18: =BJ18*BK18 -> 0 | CG18: =SUM(Y18,V18,S18,P18,M18) -> 7668.75 | CH18: =VLOOKUP(CX18,SSS_2025!A:N,8) -> 1850 | CI18: =VLOOKUP(CX18,SSS_2025!A:N,13) -> 925 | CJ18: =VLOOKUP(CX18,SSS_2025!A:N,9) -> 30 | CK18: 391.25 | CL18: 391.25 | CM18: 200 | CN18: 200 | CO18: =CG18+CH18+CJ18+CL18+CN18 -> 10140 | CP18: =(M18+P18+BN18)*10% -> 660 | CQ18: =CO18+CP18 -> 10800 | CS18: =CQ18+CR18 -> 10800 | CT18: =SUM(M18+(BC18/2)+BL18+BN18+P18)/12 -> 550 | CV18: =IFERROR(VLOOKUP(C18,'[2]BILLING COMPUTATION'!$C$8:$CI$224,85,0),0) -> 10698.75 | CW18: =CG18 -> 7668.75 | CX18: =CV18+CW18 -> 18367.5 | CZ18: =IFERROR(VLOOKUP(C18,'[5]BILLING COMPUTATION'!$C$8:$CG$101,83,0),0) -> 4852.5 | DA18: =CG18 -> 7668.75 | DB18: =SUM(CZ18:DA18) -> 12521.25 | DC18: =DB18-CX18 -> -5846.25
A19: 13 | C19: 7708 | D19: =VLOOKUP(E19,'F3 MS (2)'!E:F,2,0) -> GD250089 | E19: Belarmino, Jade Espenida | F19: =VLOOKUP(C19,'[1]ACTIVE GH'!$C:$I,7,0) -> METAL STAMPING | G19: =VLOOKUP(C19,'[1]ACTIVE GH'!$C:$J,8,0) -> PRODUCTION | H19: =VLOOKUP(C19,'[1]ACTIVE GH'!$C:$N,12,0) -> Operator 1 | I19: DL | J19: =IFERROR(VLOOKUP(C19,PIVOT!A:B,2,0),0) -> 96 | K19: =J19/8 -> 12 | L19: 600 | M19: =K19*L19 -> 7200 | N19: =IFERROR(VLOOKUP(C19,PIVOT!A:F,6,0),0) -> 0 | O19: =L19/8/60 -> 1.25 | P19: =-N19*O19 -> 0 | Q19: =IFERROR(VLOOKUP(C19,PIVOT!A:C,3,0),0) -> 0 | R19: =L19/8*1.25 -> 93.75 | S19: =Q19*R19 -> 0 | T19: =IFERROR(VLOOKUP(C19,PIVOT!A:D,4,0),0) -> 6 | U19: =L19/8*0.1 -> 7.5 | V19: =T19*U19 -> 45 | W19: =IFERROR(VLOOKUP(C19,PIVOT!A:E,5,0),0) -> 0 | X19: =L19/8*1.25*0.1 -> 9.375 | Y19: =X19*W19 -> 0 | Z19: =IFERROR(VLOOKUP(C19,#REF!,6,0),0) -> 0 | AA19: =L19/8*1.3 -> 97.5 | AB19: =Z19*AA19 -> 0 | AD19: =L19/8*1.69 -> 126.75 | AE19: =AD19*AC19 -> 0 | AF19: =IFERROR(VLOOKUP(C19,#REF!,8,0),0) -> 0 | AG19: =L19/8*1.3*0.1 -> 9.75 | AH19: =AF19*AG19 -> 0 | AJ19: =L19/8*1.5 -> 112.5 | AK19: =AI19*AJ19 -> 0 | AM19: =L19/8*1.5*1.3 -> 146.25 | AN19: 0 | AP19: =L19/8*1.5*0.1 -> 11.25 | AQ19: =AO19*AP19 -> 0 | AR19: =IFERROR(VLOOKUP(C19,#REF!,7,0),0) -> 0 | AS19: =L19/8*1.3 -> 97.5 | AT19: =AR19*AS19 -> 0 | AX19: =IFERROR(VLOOKUP(C19,#REF!,8,0),0) -> 0 | AY19: =L19/8*1.3*0.1 -> 9.75 | AZ19: =AX19*AY19 -> 0 | BA19: =IFERROR(VLOOKUP(C19,#REF!,10,0),0) -> 0 | BB19: =600/8*2 -> 150 | BC19: =BA19*BB19 -> 0 | BJ19: =IFERROR(VLOOKUP(C19,#REF!,9,0),0) -> 0 | BK19: =L19/8 -> 75 | BL19: =BJ19*BK19 -> 0 | CG19: =SUM(Y19,V19,S19,P19,M19) -> 7245 | CH19: =VLOOKUP(CX19,SSS_2025!A:N,8) -> 1750 | CI19: =VLOOKUP(CX19,SSS_2025!A:N,13) -> 875 | CJ19: =VLOOKUP(CX19,SSS_2025!A:N,9) -> 30 | CK19: 391.25 | CL19: 391.25 | CM19: 200 | CN19: 200 | CO19: =CG19+CH19+CJ19+CL19+CN19 -> 9616.25 | CP19: =(M19+P19+BN19)*10% -> 720 | CQ19: =CO19+CP19 -> 10336.25 | CS19: =CQ19+CR19 -> 10336.25 | CT19: =SUM(M19+(BC19/2)+BL19+BN19+P19)/12 -> 600 | CV19: =IFERROR(VLOOKUP(C19,'[2]BILLING COMPUTATION'!$C$8:$CI$224,85,0),0) -> 10192.5 | CW19: =CG19 -> 7245 | CX19: =CV19+CW19 -> 17437.5 | CZ19: =IFERROR(VLOOKUP(C19,'[5]BILLING COMPUTATION'!$C$8:$CG$101,83,0),0) -> 8430 | DA19: =CG19 -> 7245 | DB19: =SUM(CZ19:DA19) -> 15675 | DC19: =DB19-CX19 -> -1762.5
... A21: 15 | C21: 12397 | D21: =VLOOKUP(E21,'F3 MS (2)'!E:F,2,0) -> GD250185 | E21: Capuno, Janarah Nicole Ical | F21: =VLOOKUP(C21,'[1]ACTIVE GH'!$C:$I,7,0) -> METAL STAMPING | G21: =VLOOKUP(C21,'[1]ACTIVE GH'!$C:$J,8,0) -> PRODUCTION | H21: =VLOOKUP(C21,'[1]ACTIVE GH'!$C:$N,12,0) -> Operator 1 | I21: DL | J21: =IFERROR(VLOOKUP(C21,PIVOT!A:B,2,0),0) -> 96 | K21: =J21/8 -> 12 | L21: 600 | M21: =K21*L21 -> 7200 | N21: =IFERROR(VLOOKUP(C21,PIVOT!A:F,6,0),0) -> 0 | O21: =L21/8/60 -> 1.25 | P21: =-N21*O21 -> 0 | Q21: =IFERROR(VLOOKUP(C21,PIVOT!A:C,3,0),0) -> 12 | R21: =L21/8*1.25 -> 93.75 | S21: =Q21*R21 -> 1125 | T21: =IFERROR(VLOOKUP(C21,PIVOT!A:D,4,0),0) -> 0 | U21: =L21/8*0.1 -> 7.5 | V21: =T21*U21 -> 0 | W21: =IFERROR(VLOOKUP(C21,PIVOT!A:E,5,0),0) -> 0 | X21: =L21/8*1.25*0.1 -> 9.375 | Y21: =X21*W21 -> 0 | Z21: =IFERROR(VLOOKUP(C21,#REF!,6,0),0) -> 0 | AA21: =L21/8*1.3 -> 97.5 | AB21: =Z21*AA21 -> 0 | AD21: =L21/8*1.69 -> 126.75 | AE21: =AD21*AC21 -> 0 | AF21: =IFERROR(VLOOKUP(C21,#REF!,8,0),0) -> 0 | AG21: =L21/8*1.3*0.1 -> 9.75 | AH21: =AF21*AG21 -> 0 | AJ21: =L21/8*1.5 -> 112.5 | AK21: =AI21*AJ21 -> 0 | AM21: =L21/8*1.5*1.3 -> 146.25 | AN21: 0 | AP21: =L21/8*1.5*0.1 -> 11.25 | AQ21: =AO21*AP21 -> 0 | AR21: =IFERROR(VLOOKUP(C21,#REF!,7,0),0) -> 0 | AS21: =L21/8*1.3 -> 97.5 | AT21: =AR21*AS21 -> 0 | AX21: =IFERROR(VLOOKUP(C21,#REF!,8,0),0) -> 0 | AY21: =L21/8*1.3*0.1 -> 9.75 | AZ21: =AX21*AY21 -> 0 | BA21: =IFERROR(VLOOKUP(C21,#REF!,10,0),0) -> 0 | BB21: =600/8*2 -> 150 | BC21: =BA21*BB21 -> 0 | BJ21: =IFERROR(VLOOKUP(C21,#REF!,9,0),0) -> 0 | BK21: =L21/8 -> 75 | BL21: =BJ21*BK21 -> 0 | CG21: =SUM(Y21,V21,S21,P21,M21) -> 8325 | CH21: =VLOOKUP(CX21,SSS_2025!A:N,8) -> 1700 | CI21: =VLOOKUP(CX21,SSS_2025!A:N,13) -> 850 | CJ21: =VLOOKUP(CX21,SSS_2025!A:N,9) -> 30 | CK21: 391.25 | CL21: 391.25 | CM21: 200 | CN21: 200 | CO21: =CG21+CH21+CJ21+CL21+CN21 -> 10646.25 | CP21: =(M21+P21+BN21)*10% -> 720 | CQ21: =CO21+CP21 -> 11366.25 | CS21: =CQ21+CR21 -> 11366.25 | CT21: =SUM(M21+(BC21/2)+BL21+BN21+P21)/12 -> 600 | CV21: =IFERROR(VLOOKUP(C21,'[2]BILLING COMPUTATION'!$C$8:$CI$224,85,0),0) -> 8916.25 | CW21: =CG21 -> 8325 | CX21: =CV21+CW21 -> 17241.25 | CZ21: =IFERROR(VLOOKUP(C21,'[5]BILLING COMPUTATION'!$C$8:$CG$101,83,0),0) -> 9480 | DA21: =CG21 -> 8325 | DB21: =SUM(CZ21:DA21) -> 17805 | DC21: =DB21-CX21 -> 563.75
A22: 16 | C22: 32518 | D22: GD260754 | E22: Caringal, Jennylyn | F22: =VLOOKUP(D22,'[1]ACTIVE GH'!$D:$I,6,0) -> METAL STAMPING | G22: PRODUCTION | H22: Operator 1 | I22: DL | J22: =IFERROR(VLOOKUP(C22,PIVOT!A:B,2,0),0) -> 72 | K22: =J22/8 -> 9 | L22: 600 | M22: =K22*L22 -> 5400 | N22: =IFERROR(VLOOKUP(C22,PIVOT!A:F,6,0),0) -> 0 | O22: =L22/8/60 -> 1.25 | P22: =-N22*O22 -> 0 | Q22: =IFERROR(VLOOKUP(C22,PIVOT!A:C,3,0),0) -> 14 | R22: =L22/8*1.25 -> 93.75 | S22: =Q22*R22 -> 1312.5 | T22: =IFERROR(VLOOKUP(C22,PIVOT!A:D,4,0),0) -> 0 | U22: =L22/8*0.1 -> 7.5 | V22: =T22*U22 -> 0 | W22: =IFERROR(VLOOKUP(C22,PIVOT!A:E,5,0),0) -> 0 | X22: =L22/8*1.25*0.1 -> 9.375 | Y22: =X22*W22 -> 0 | Z22: =IFERROR(VLOOKUP(C22,#REF!,6,0),0) -> 0 | AA22: =L22/8*1.3 -> 97.5 | AB22: =Z22*AA22 -> 0 | AD22: =L22/8*1.69 -> 126.75 | AE22: =AD22*AC22 -> 0 | AF22: =IFERROR(VLOOKUP(C22,#REF!,8,0),0) -> 0 | AG22: =L22/8*1.3*0.1 -> 9.75 | AH22: =AF22*AG22 -> 0 | AJ22: =L22/8*1.5 -> 112.5 | AK22: =AI22*AJ22 -> 0 | AM22: =L22/8*1.5*1.3 -> 146.25 | AN22: 0 | AP22: =L22/8*1.5*0.1 -> 11.25 | AQ22: =AO22*AP22 -> 0 | AR22: =IFERROR(VLOOKUP(C22,#REF!,7,0),0) -> 0 | AS22: =L22/8*1.3 -> 97.5 | AT22: =AR22*AS22 -> 0 | AX22: =IFERROR(VLOOKUP(C22,#REF!,8,0),0) -> 0 | AY22: =L22/8*1.3*0.1 -> 9.75 | AZ22: =AX22*AY22 -> 0 | BA22: =IFERROR(VLOOKUP(C22,#REF!,10,0),0) -> 0 | BB22: =600/8*2 -> 150 | BC22: =BA22*BB22 -> 0 | BJ22: =IFERROR(VLOOKUP(C22,#REF!,9,0),0) -> 0 | BK22: =L22/8 -> 75 | BL22: =BJ22*BK22 -> 0 | CG22: =SUM(Y22,V22,S22,P22,M22) -> 6712.5 | CH22: =VLOOKUP(CX22,SSS_2025!A:N,8) -> 1750 | CI22: =VLOOKUP(CX22,SSS_2025!A:N,13) -> 875 | CJ22: =VLOOKUP(CX22,SSS_2025!A:N,9) -> 30 | CK22: 391.25 | CL22: 391.25 | CM22: 200 | CN22: 200 | CO22: =CG22+CH22+CJ22+CL22+CN22 -> 9083.75 | CP22: =(M22+P22+BN22)*10% -> 540 | CQ22: =CO22+CP22 -> 9623.75 | CS22: =CQ22+CR22 -> 9623.75 | CT22: =SUM(M22+(BC22/2)+BL22+BN22+P22)/12 -> 450 | CV22: =IFERROR(VLOOKUP(C22,'[2]BILLING COMPUTATION'!$C$8:$CI$224,85,0),0) -> 10621.25 | CW22: =CG22 -> 6712.5 | CX22: =CV22+CW22 -> 17333.75 | CZ22: =IFERROR(VLOOKUP(C22,'[5]BILLING COMPUTATION'!$C$8:$CG$101,83,0),0) -> 9067.5 | DA22: =CG22 -> 6712.5 | DB22: =SUM(CZ22:DA22) -> 15780 | DC22: =DB22-CX22 -> -1553.75
A23: 17 | C23: 8064 | D23: =VLOOKUP(E23,'F3 MS (2)'!E:F,2,0) -> GD250048 | E23: Caudilla, Arlene | F23: =VLOOKUP(C23,'[1]ACTIVE GH'!$C:$I,7,0) -> METAL STAMPING | G23: =VLOOKUP(C23,'[1]ACTIVE GH'!$C:$J,8,0) -> PRODUCTION | H23: =VLOOKUP(C23,'[1]ACTIVE GH'!$C:$N,12,0) -> Operator 1 | I23: DL | J23: =IFERROR(VLOOKUP(C23,PIVOT!A:B,2,0),0) -> 96 | K23: =J23/8 -> 12 | L23: 600 | M23: =K23*L23 -> 7200 | N23: =IFERROR(VLOOKUP(C23,PIVOT!A:F,6,0),0) -> 6 | O23: =L23/8/60 -> 1.25 | P23: =-N23*O23 -> -7.5 | Q23: =IFERROR(VLOOKUP(C23,PIVOT!A:C,3,0),0) -> 0 | R23: =L23/8*1.25 -> 93.75 | S23: =Q23*R23 -> 0 | T23: =IFERROR(VLOOKUP(C23,PIVOT!A:D,4,0),0) -> 66 | U23: =L23/8*0.1 -> 7.5 | V23: =T23*U23 -> 495 | W23: =IFERROR(VLOOKUP(C23,PIVOT!A:E,5,0),0) -> 0 | X23: =L23/8*1.25*0.1 -> 9.375 | Y23: =X23*W23 -> 0 | Z23: =IFERROR(VLOOKUP(C23,#REF!,6,0),0) -> 0 | AA23: =L23/8*1.3 -> 97.5 | AB23: =Z23*AA23 -> 0 | AD23: =L23/8*1.69 -> 126.75 | AE23: =AD23*AC23 -> 0 | AF23: =IFERROR(VLOOKUP(C23,#REF!,8,0),0) -> 0 | AG23: =L23/8*1.3*0.1 -> 9.75 | AH23: =AF23*AG23 -> 0 | AJ23: =L23/8*1.5 -> 112.5 | AK23: =AI23*AJ23 -> 0 | AM23: =L23/8*1.5*1.3 -> 146.25 | AN23: 0 | AP23: =L23/8*1.5*0.1 -> 11.25 | AQ23: =AO23*AP23 -> 0 | AR23: =IFERROR(VLOOKUP(C23,#REF!,7,0),0) -> 0 | AS23: =L23/8*1.3 -> 97.5 | AT23: =AR23*AS23 -> 0 | AX23: =IFERROR(VLOOKUP(C23,#REF!,8,0),0) -> 0 | AY23: =L23/8*1.3*0.1 -> 9.75 | AZ23: =AX23*AY23 -> 0 | BA23: =IFERROR(VLOOKUP(C23,#REF!,10,0),0) -> 0 | BB23: =600/8*2 -> 150 | BC23: =BA23*BB23 -> 0 | BJ23: =IFERROR(VLOOKUP(C23,#REF!,9,0),0) -> 0 | BK23: =L23/8 -> 75 | BL23: =BJ23*BK23 -> 0 | CG23: =SUM(Y23,V23,S23,P23,M23) -> 7687.5 | CH23: =VLOOKUP(CX23,SSS_2025!A:N,8) -> 1750 | CI23: =VLOOKUP(CX23,SSS_2025!A:N,13) -> 875 | CJ23: =VLOOKUP(CX23,SSS_2025!A:N,9) -> 30 | CK23: 391.25 | CL23: 391.25 | CM23: 200 | CN23: 200 | CO23: =CG23+CH23+CJ23+CL23+CN23 -> 10058.75 | CP23: =(M23+P23+BN23)*10% -> 719.25 | CQ23: =CO23+CP23 -> 10778 | CS23: =CQ23+CR23 -> 10778 | CT23: =SUM(M23+(BC23/2)+BL23+BN23+P23)/12 -> 599.375 | CV23: =IFERROR(VLOOKUP(C23,'[2]BILLING COMPUTATION'!$C$8:$CI$224,85,0),0) -> 9977.5 | CW23: =CG23 -> 7687.5 | CX23: =CV23+CW23 -> 17665 | CZ23: =IFERROR(VLOOKUP(C23,'[5]BILLING COMPUTATION'!$C$8:$CG$101,83,0),0) -> 9398.75 | DA23: =CG23 -> 7687.5 | DB23: =SUM(CZ23:DA23) -> 17086.25 | DC23: =DB23-CX23 -> -578.75
A24: 18 | C24: 12909 | D24: =VLOOKUP(E24,'F3 MS (2)'!E:F,2,0) -> GD250332 | E24: Cerda, Josephine Tirados | F24: =VLOOKUP(C24,'[1]ACTIVE GH'!$C:$I,7,0) -> METAL STAMPING | G24: =VLOOKUP(C24,'[1]ACTIVE GH'!$C:$J,8,0) -> PRODUCTION | H24: =VLOOKUP(C24,'[1]ACTIVE GH'!$C:$N,12,0) -> Operator 1 | I24: DL | J24: =IFERROR(VLOOKUP(C24,PIVOT!A:B,2,0),0) -> 80 | K24: =J24/8 -> 10 | L24: 600 | M24: =K24*L24 -> 6000 | N24: =IFERROR(VLOOKUP(C24,PIVOT!A:F,6,0),0) -> 0 | O24: =L24/8/60 -> 1.25 | P24: =-N24*O24 -> 0 | Q24: =IFERROR(VLOOKUP(C24,PIVOT!A:C,3,0),0) -> 0 | R24: =L24/8*1.25 -> 93.75 | S24: =Q24*R24 -> 0 | T24: =IFERROR(VLOOKUP(C24,PIVOT!A:D,4,0),0) -> 0 | U24: =L24/8*0.1 -> 7.5 | V24: =T24*U24 -> 0 | W24: =IFERROR(VLOOKUP(C24,PIVOT!A:E,5,0),0) -> 0 | X24: =L24/8*1.25*0.1 -> 9.375 | Y24: =X24*W24 -> 0 | Z24: =IFERROR(VLOOKUP(C24,#REF!,6,0),0) -> 0 | AA24: =L24/8*1.3 -> 97.5 | AB24: =Z24*AA24 -> 0 | AD24: =L24/8*1.69 -> 126.75 | AE24: =AD24*AC24 -> 0 | AF24: =IFERROR(VLOOKUP(C24,#REF!,8,0),0) -> 0 | AG24: =L24/8*1.3*0.1 -> 9.75 | AH24: =AF24*AG24 -> 0 | AJ24: =L24/8*1.5 -> 112.5 | AK24: =AI24*AJ24 -> 0 | AM24: =L24/8*1.5*1.3 -> 146.25 | AN24: 0 | AP24: =L24/8*1.5*0.1 -> 11.25 | AQ24: =AO24*AP24 -> 0 | AR24: =IFERROR(VLOOKUP(C24,#REF!,7,0),0) -> 0 | AS24: =L24/8*1.3 -> 97.5 | AT24: =AR24*AS24 -> 0 | AX24: =IFERROR(VLOOKUP(C24,#REF!,8,0),0) -> 0 | AY24: =L24/8*1.3*0.1 -> 9.75 | AZ24: =AX24*AY24 -> 0 | BA24: =IFERROR(VLOOKUP(C24,#REF!,10,0),0) -> 0 | BB24: =600/8*2 -> 150 | BC24: =BA24*BB24 -> 0 | BJ24: =IFERROR(VLOOKUP(C24,#REF!,9,0),0) -> 0 | BK24: =L24/8 -> 75 | BL24: =BJ24*BK24 -> 0 | CG24: =SUM(Y24,V24,S24,P24,M24) -> 6000 | CH24: =VLOOKUP(CX24,SSS_2025!A:N,8) -> 1400 | CI24: =VLOOKUP(CX24,SSS_2025!A:N,13) -> 700 | CJ24: =VLOOKUP(CX24,SSS_2025!A:N,9) -> 10 | CK24: 391.25 | CL24: 391.25 | CM24: 200 | CN24: 200 | CO24: =CG24+CH24+CJ24+CL24+CN24 -> 8001.25 | CP24: =(M24+P24+BN24)*10% -> 600 | CQ24: =CO24+CP24 -> 8601.25 | CS24: =CQ24+CR24 -> 8601.25 | CT24: =SUM(M24+(BC24/2)+BL24+BN24+P24)/12 -> 500 | CV24: =IFERROR(VLOOKUP(C24,'[3]BILLING COMPUTATION'!$C$34:$CF$34,82,0),0) -> 7800 | CW24: =CG24 -> 6000 | CX24: =CV24+CW24 -> 13800 | CZ24: =IFERROR(VLOOKUP(C24,'[5]BILLING COMPUTATION'!$C$8:$CG$101,83,0),0) -> 6600 | DA24: =CG24 -> 6000 | DB24: =SUM(CZ24:DA24) -> 12600 | DC24: =DB24-CX24 -> -1200
A25: 19 | C25: 30293 | D25: =VLOOKUP(E25,'F3 MS (2)'!E:F,2,0) -> GD250531 | E25: Conzaga, Anna Fe Acopio | F25: =VLOOKUP(C25,'[1]ACTIVE GH'!$C:$I,7,0) -> METAL STAMPING | G25: =VLOOKUP(C25,'[1]ACTIVE GH'!$C:$J,8,0) -> PRODUCTION | H25: =VLOOKUP(C25,'[1]ACTIVE GH'!$C:$N,12,0) -> Operator 1 | I25: DL | J25: =IFERROR(VLOOKUP(C25,PIVOT!A:B,2,0),0) -> 96 | K25: =J25/8 -> 12 | L25: 600 | M25: =K25*L25 -> 7200 | N25: =IFERROR(VLOOKUP(C25,PIVOT!A:F,6,0),0) -> 0 | O25: =L25/8/60 -> 1.25 | P25: =-N25*O25 -> 0 | Q25: =IFERROR(VLOOKUP(C25,PIVOT!A:C,3,0),0) -> 20 | R25: =L25/8*1.25 -> 93.75 | S25: =Q25*R25 -> 1875 | T25: =IFERROR(VLOOKUP(C25,PIVOT!A:D,4,0),0) -> 0 | U25: =L25/8*0.1 -> 7.5 | V25: =T25*U25 -> 0 | W25: =IFERROR(VLOOKUP(C25,PIVOT!A:E,5,0),0) -> 0 | X25: =L25/8*1.25*0.1 -> 9.375 | Y25: =X25*W25 -> 0 | Z25: =IFERROR(VLOOKUP(C25,#REF!,6,0),0) -> 0 | AA25: =L25/8*1.3 -> 97.5 | AB25: =Z25*AA25 -> 0 | AD25: =L25/8*1.69 -> 126.75 | AE25: =AD25*AC25 -> 0 | AF25: =IFERROR(VLOOKUP(C25,#REF!,8,0),0) -> 0 | AG25: =L25/8*1.3*0.1 -> 9.75 | AH25: =AF25*AG25 -> 0 | AJ25: =L25/8*1.5 -> 112.5 | AK25: =AI25*AJ25 -> 0 | AM25: =L25/8*1.5*1.3 -> 146.25 | AN25: 0 | AP25: =L25/8*1.5*0.1 -> 11.25 | AQ25: =AO25*AP25 -> 0 | AR25: =IFERROR(VLOOKUP(C25,#REF!,7,0),0) -> 0 | AS25: =L25/8*1.3 -> 97.5 | AT25: =AR25*AS25 -> 0 | AX25: =IFERROR(VLOOKUP(C25,#REF!,8,0),0) -> 0 | AY25: =L25/8*1.3*0.1 -> 9.75 | AZ25: =AX25*AY25 -> 0 | BA25: =IFERROR(VLOOKUP(C25,#REF!,10,0),0) -> 0 | BB25: =600/8*2 -> 150 | BC25: =BA25*BB25 -> 0 | BJ25: =IFERROR(VLOOKUP(C25,#REF!,9,0),0) -> 0 | BK25: =L25/8 -> 75 | BL25: =BJ25*BK25 -> 0 | CG25: =SUM(Y25,V25,S25,P25,M25) -> 9075 | CH25: =VLOOKUP(CX25,SSS_2025!A:N,8) -> 1950 | CI25: =VLOOKUP(CX25,SSS_2025!A:N,13) -> 975 | CJ25: =VLOOKUP(CX25,SSS_2025!A:N,9) -> 30 | CK25: 391.25 | CL25: 391.25 | CM25: 200 | CN25: 200 | CO25: =CG25+CH25+CJ25+CL25+CN25 -> 11646.25 | CP25: =(M25+P25+BN25)*10% -> 720 | CQ25: =CO25+CP25 -> 12366.25 | CS25: =CQ25+CR25 -> 12366.25 | CT25: =SUM(M25+(BC25/2)+BL25+BN25+P25)/12 -> 600 | CV25: =IFERROR(VLOOKUP(C25,'[2]BILLING COMPUTATION'!$C$8:$CI$224,85,0),0) -> 10305 | CW25: =CG25 -> 9075 | CX25: =CV25+CW25 -> 19380 | CZ25: =IFERROR(VLOOKUP(C25,'[5]BILLING COMPUTATION'!$C$8:$CG$101,83,0),0) -> 10747.5 | DA25: =CG25 -> 9075 | DB25: =SUM(CZ25:DA25) -> 19822.5 | DC25: =DB25-CX25 -> 442.5
A26: 20 | C26: 11863 | D26: =VLOOKUP(E26,'F3 MS (2)'!E:F,2,0) -> GD250159 | E26: Cortez, Armin Padis | F26: =VLOOKUP(C26,'[1]ACTIVE GH'!$C:$I,7,0) -> METAL STAMPING | G26: =VLOOKUP(C26,'[1]ACTIVE GH'!$C:$J,8,0) -> PRODUCTION | H26: =VLOOKUP(C26,'[1]ACTIVE GH'!$C:$N,12,0) -> Operator 1 | I26: DL | J26: =IFERROR(VLOOKUP(C26,PIVOT!A:B,2,0),0) -> 96 | K26: =J26/8 -> 12 | L26: 600 | M26: =K26*L26 -> 7200 | N26: =IFERROR(VLOOKUP(C26,PIVOT!A:F,6,0),0) -> 0 | O26: =L26/8/60 -> 1.25 | P26: =-N26*O26 -> 0 | Q26: =IFERROR(VLOOKUP(C26,PIVOT!A:C,3,0),0) -> 0 | R26: =L26/8*1.25 -> 93.75 | S26: =Q26*R26 -> 0 | T26: =IFERROR(VLOOKUP(C26,PIVOT!A:D,4,0),0) -> 6 | U26: =L26/8*0.1 -> 7.5 | V26: =T26*U26 -> 45 | W26: =IFERROR(VLOOKUP(C26,PIVOT!A:E,5,0),0) -> 0 | X26: =L26/8*1.25*0.1 -> 9.375 | Y26: =X26*W26 -> 0 | Z26: =IFERROR(VLOOKUP(C26,#REF!,6,0),0) -> 0 | AA26: =L26/8*1.3 -> 97.5 | AB26: =Z26*AA26 -> 0 | AD26: =L26/8*1.69 -> 126.75 | AE26: =AD26*AC26 -> 0 | AF26: =IFERROR(VLOOKUP(C26,#REF!,8,0),0) -> 0 | AG26: =L26/8*1.3*0.1 -> 9.75 | AH26: =AF26*AG26 -> 0 | AJ26: =L26/8*1.5 -> 112.5 | AK26: =AI26*AJ26 -> 0 | AM26: =L26/8*1.5*1.3 -> 146.25 | AN26: 0 | AP26: =L26/8*1.5*0.1 -> 11.25 | AQ26: =AO26*AP26 -> 0 | AR26: =IFERROR(VLOOKUP(C26,#REF!,7,0),0) -> 0 | AS26: =L26/8*1.3 -> 97.5 | AT26: =AR26*AS26 -> 0 | AX26: =IFERROR(VLOOKUP(C26,#REF!,8,0),0) -> 0 | AY26: =L26/8*1.3*0.1 -> 9.75 | AZ26: =AX26*AY26 -> 0 | BA26: =IFERROR(VLOOKUP(C26,#REF!,10,0),0) -> 0 | BB26: =600/8*2 -> 150 | BC26: =BA26*BB26 -> 0 | BJ26: =IFERROR(VLOOKUP(C26,#REF!,9,0),0) -> 0 | BK26: =L26/8 -> 75 | BL26: =BJ26*BK26 -> 0 | CG26: =SUM(Y26,V26,S26,P26,M26) -> 7245 | CH26: =VLOOKUP(CX26,SSS_2025!A:N,8) -> 1900 | CI26: =VLOOKUP(CX26,SSS_2025!A:N,13) -> 950 | CJ26: =VLOOKUP(CX26,SSS_2025!A:N,9) -> 30 | CK26: 391.25 | CL26: 391.25 | CM26: 200 | CN26: 200 | CO26: =CG26+CH26+CJ26+CL26+CN26 -> 9766.25 | CP26: =(M26+P26+BN26)*10% -> 720 | CQ26: =CO26+CP26 -> 10486.25 | CS26: =CQ26+CR26 -> 10486.25 | CT26: =SUM(M26+(BC26/2)+BL26+BN26+P26)/12 -> 600 | CV26: =IFERROR(VLOOKUP(C26,'[2]BILLING COMPUTATION'!$C$8:$CI$224,85,0),0) -> 11610 | CW26: =CG26 -> 7245 | CX26: =CV26+CW26 -> 18855 | CZ26: =IFERROR(VLOOKUP(C26,'[5]BILLING COMPUTATION'!$C$8:$CG$101,83,0),0) -> 8585 | DA26: =CG26 -> 7245 | DB26: =SUM(CZ26:DA26) -> 15830 | DC26: =DB26-CX26 -> -3025
A27: 21 | C27: 30261 | D27: =VLOOKUP(E27,'F3 MS (2)'!E:F,2,0) -> GD250522 | E27: Dado, Jerome Romero | F27: =VLOOKUP(C27,'[1]ACTIVE GH'!$C:$I,7,0) -> METAL STAMPING | G27: =VLOOKUP(C27,'[1]ACTIVE GH'!$C:$J,8,0) -> PRODUCTION | H27: =VLOOKUP(C27,'[1]ACTIVE GH'!$C:$N,12,0) -> Operator 1 | I27: DL | J27: =IFERROR(VLOOKUP(C27,PIVOT!A:B,2,0),0) -> 80 | K27: =J27/8 -> 10 | L27: 600 | M27: =K27*L27 -> 6000 | N27: =IFERROR(VLOOKUP(C27,PIVOT!A:F,6,0),0) -> 0 | O27: =L27/8/60 -> 1.25 | P27: =-N27*O27 -> 0 | Q27: =IFERROR(VLOOKUP(C27,PIVOT!A:C,3,0),0) -> 6 | R27: =L27/8*1.25 -> 93.75 | S27: =Q27*R27 -> 562.5 | T27: =IFERROR(VLOOKUP(C27,PIVOT!A:D,4,0),0) -> 0 | U27: =L27/8*0.1 -> 7.5 | V27: =T27*U27 -> 0 | W27: =IFERROR(VLOOKUP(C27,PIVOT!A:E,5,0),0) -> 0 | X27: =L27/8*1.25*0.1 -> 9.375 | Y27: =X27*W27 -> 0 | Z27: =IFERROR(VLOOKUP(C27,#REF!,6,0),0) -> 0 | AA27: =L27/8*1.3 -> 97.5 | AB27: =Z27*AA27 -> 0 | AD27: =L27/8*1.69 -> 126.75 | AE27: =AD27*AC27 -> 0 | AF27: =IFERROR(VLOOKUP(C27,#REF!,8,0),0) -> 0 | AG27: =L27/8*1.3*0.1 -> 9.75 | AH27: =AF27*AG27 -> 0 | AJ27: =L27/8*1.5 -> 112.5 | AK27: =AI27*AJ27 -> 0 | AM27: =L27/8*1.5*1.3 -> 146.25 | AN27: 0 | AP27: =L27/8*1.5*0.1 -> 11.25 | AQ27: =AO27*AP27 -> 0 | AR27: =IFERROR(VLOOKUP(C27,#REF!,7,0),0) -> 0 | AS27: =L27/8*1.3 -> 97.5 | AT27: =AR27*AS27 -> 0 | AX27: =IFERROR(VLOOKUP(C27,#REF!,8,0),0) -> 0 | AY27: =L27/8*1.3*0.1 -> 9.75 | AZ27: =AX27*AY27 -> 0 | BA27: =IFERROR(VLOOKUP(C27,#REF!,10,0),0) -> 0 | BB27: =600/8*2 -> 150 | BC27: =BA27*BB27 -> 0 | BJ27: =IFERROR(VLOOKUP(C27,#REF!,9,0),0) -> 0 | BK27: =L27/8 -> 75 | BL27: =BJ27*BK27 -> 0 | CG27: =SUM(Y27,V27,S27,P27,M27) -> 6562.5 | CH27: =VLOOKUP(CX27,SSS_2025!A:N,8) -> 1700 | CI27: =VLOOKUP(CX27,SSS_2025!A:N,13) -> 850 | CJ27: =VLOOKUP(CX27,SSS_2025!A:N,9) -> 30 | CK27: 391.25 | CL27: 391.25 | CM27: 200 | CN27: 200 | CO27: =CG27+CH27+CJ27+CL27+CN27 -> 8883.75 | CP27: =(M27+P27+BN27)*10% -> 600 | CQ27: =CO27+CP27 -> 9483.75 | CS27: =CQ27+CR27 -> 9483.75 | CT27: =SUM(M27+(BC27/2)+BL27+BN27+P27)/12 -> 500 | CV27: =IFERROR(VLOOKUP(C27,'[2]BILLING COMPUTATION'!$C$8:$CI$224,85,0),0) -> 10346.25 | CW27: =CG27 -> 6562.5 | CX27: =CV27+CW27 -> 16908.75 | CZ27: =IFERROR(VLOOKUP(C27,'[5]BILLING COMPUTATION'!$C$8:$CG$101,83,0),0) -> 7388.75 | DA27: =CG27 -> 6562.5 | DB27: =SUM(CZ27:DA27) -> 13951.25 | DC27: =DB27-CX27 -> -2957.5
A28: 22 | C28: 12927 | D28: =VLOOKUP(E28,'F3 MS (2)'!E:F,2,0) -> GD250343 | E28: Dagli, Renz Jemrick Zara | F28: =VLOOKUP(C28,'[1]ACTIVE GH'!$C:$I,7,0) -> METAL STAMPING | G28: =VLOOKUP(C28,'[1]ACTIVE GH'!$C:$J,8,0) -> PRODUCTION | H28: =VLOOKUP(C28,'[1]ACTIVE GH'!$C:$N,12,0) -> Operator 1 | I28: DL | J28: =IFERROR(VLOOKUP(C28,PIVOT!A:B,2,0),0) -> 88 | K28: =J28/8 -> 11 | L28: 600 | M28: =K28*L28 -> 6600 | N28: =IFERROR(VLOOKUP(C28,PIVOT!A:F,6,0),0) -> 0 | O28: =L28/8/60 -> 1.25 | P28: =-N28*O28 -> 0 | Q28: =IFERROR(VLOOKUP(C28,PIVOT!A:C,3,0),0) -> 0 | R28: =L28/8*1.25 -> 93.75 | S28: =Q28*R28 -> 0 | T28: =IFERROR(VLOOKUP(C28,PIVOT!A:D,4,0),0) -> 6 | U28: =L28/8*0.1 -> 7.5 | V28: =T28*U28 -> 45 | W28: =IFERROR(VLOOKUP(C28,PIVOT!A:E,5,0),0) -> 0 | X28: =L28/8*1.25*0.1 -> 9.375 | Y28: =X28*W28 -> 0 | Z28: =IFERROR(VLOOKUP(C28,#REF!,6,0),0) -> 0 | AA28: =L28/8*1.3 -> 97.5 | AB28: =Z28*AA28 -> 0 | AD28: =L28/8*1.69 -> 126.75 | AE28: =AD28*AC28 -> 0 | AF28: =IFERROR(VLOOKUP(C28,#REF!,8,0),0) -> 0 | AG28: =L28/8*1.3*0.1 -> 9.75 | AH28: =AF28*AG28 -> 0 | AJ28: =L28/8*1.5 -> 112.5 | AK28: =AI28*AJ28 -> 0 | AM28: =L28/8*1.5*1.3 -> 146.25 | AN28: 0 | AP28: =L28/8*1.5*0.1 -> 11.25 | AQ28: =AO28*AP28 -> 0 | AR28: =IFERROR(VLOOKUP(C28,#REF!,7,0),0) -> 0 | AS28: =L28/8*1.3 -> 97.5 | AT28: =AR28*AS28 -> 0 | AX28: =IFERROR(VLOOKUP(C28,#REF!,8,0),0) -> 0 | AY28: =L28/8*1.3*0.1 -> 9.75 | AZ28: =AX28*AY28 -> 0 | BA28: =IFERROR(VLOOKUP(C28,#REF!,10,0),0) -> 0 | BB28: =600/8*2 -> 150 | BC28: =BA28*BB28 -> 0 | BJ28: =IFERROR(VLOOKUP(C28,#REF!,9,0),0) -> 0 | BK28: =L28/8 -> 75 | BL28: =BJ28*BK28 -> 0 | CG28: =SUM(Y28,V28,S28,P28,M28) -> 6645 | CH28: =VLOOKUP(CX28,SSS_2025!A:N,8) -> 1800 | CI28: =VLOOKUP(CX28,SSS_2025!A:N,13) -> 900 | CJ28: =VLOOKUP(CX28,SSS_2025!A:N,9) -> 30 | CK28: 391.25 | CL28: 391.25 | CM28: 200 | CN28: 200 | CO28: =CG28+CH28+CJ28+CL28+CN28 -> 9066.25 | CP28: =(M28+P28+BN28)*10% -> 660 | CQ28: =CO28+CP28 -> 9726.25 | CS28: =CQ28+CR28 -> 9726.25 | CT28: =SUM(M28+(BC28/2)+BL28+BN28+P28)/12 -> 550 | CV28: =IFERROR(VLOOKUP(C28,'[2]BILLING COMPUTATION'!$C$8:$CI$224,85,0),0) -> 11422.5 | CW28: =CG28 -> 6645 | CX28: =CV28+CW28 -> 18067.5 | CZ28: =IFERROR(VLOOKUP(C28,'[5]BILLING COMPUTATION'!$C$8:$CG$101,83,0),0) -> 8448.75 | DA28: =CG28 -> 6645 | DB28: =SUM(CZ28:DA28) -> 15093.75 | DC28: =DB28-CX28 -> -2973.75
