Workbook
Name _____________________AMZ2: [1]LIST!$C$2:$C$112
Name ____________________AMZ2: [2]LIST!$C$2:$C$112
Name ___________________AMZ2: [2]LIST!$C$2:$C$112
Name __________________AMZ2: [2]LIST!$C$2:$C$112
Name _________________AMZ2: [2]LIST!$C$2:$C$112
Name ________________AMZ2: [2]LIST!$C$2:$C$112
Name _______________AMZ2: [3]LIST!$C$2:$C$112
Name ______________AMZ2: [3]LIST!$C$2:$C$112
Name _____________AMZ2: [3]LIST!$C$2:$C$112
Name ____________AMZ2: [3]LIST!$C$2:$C$112
Name ___________AMZ2: [3]LIST!$C$2:$C$112
Name __________AMZ2: [3]LIST!$C$2:$C$112
Name _________AMZ2: [3]LIST!$C$2:$C$112
Name ________AMZ2: [2]LIST!$C$2:$C$112
Name _______AMZ2: [2]LIST!$C$2:$C$112
Name ______AMZ2: [4]LIST!$C$2:$C$112
Name _____AMZ2: [2]LIST!$C$2:$C$112
Name ____AMZ2: [2]LIST!$C$2:$C$112
Name ___AMZ2: [1]LIST!$C$2:$C$112
Name __AMZ2: [4]LIST!$C$2:$C$112
Name _a1: #REF!
Name _a1: #REF!
Name _AMZ2: [5]LIST!$C$2:$C$112
Name _AMZ2: [1]LIST!$C$2:$C$112
Name A: #REF!
Name A: #REF!
Name A: #REF!
Name activity: [6]LIST!$C$2:$C$112
Name activity: [3]LIST!$C$2:$C$112
Name adaskdm: [1]LIST!$C$2:$C$112
Name AJ: #REF!
Name AJ: #REF!
Name AJ: #REF!
Name AM: #REF!
Name AM: #REF!
Name AM: #REF!
Name AMABELLEAUGUSTO: #REF!
Name AMABELLEAUGUSTO: #REF!
Name AMABELLEAUGUSTO: #REF!
Name AMZ: [5]LIST!$C$2:$C$112
Name AMZ: [4]LIST!$C$2:$C$112
Name ANDBOR: '[4]TIMEKEEP DMSF'!#REF!
Name ANDBOR: '[4]TIMEKEEP DMSF'!#REF!
Name ANDBOR: '[4]TIMEKEEP DMSF'!#REF!
Name as: [7]Departments!$A$2:$A$65536
Name asa: [7]Departments!$A$2:$A$65536
Name asd: [7]Departments!$A$2:$A$65536
Name assfdgfgjhgkujhk: #REF!
Name assfdgfgjhgkujhk: #REF!
Name assfdgfgjhgkujhk: #REF!
Name B: #REF!
Name B: #REF!
Name B: #REF!
Name bhgfcjhl: #REF!
Name bhgfcjhl: #REF!
Name bhgfcjhl: #REF!
Name BILL: #REF!
Name BILL: #REF!
Name BILL: #REF!
Name BILLDRAFT: #REF!

Sheet INVOICE
B2: On file | C2: CHIYODA PHILIPPINES MFG. CORP. | H2: =TODAY() -> 46207
C3: B20 L20 LIMA TECH. CENTRAL SPECIAL ECONOMIC , LIPA CITY , BATANGAS
C8: TWO MILLION THREE HUNDRED EIGHTY-THREE THOUSAND TWO HUNDRED FIFTY-THREE PESOS AND 50/100 ONLY
G10: PHP | H10: =H22 -> 2111789.2
B14: Billing for the services rendered by Workers
B15: ='BILLING COMPUTATION '!A2 -> PAYROLL BILLING PERIOD: JUNE 1-15, 2026
C18: TOTAL BILLING BEFORE ADMIN | H18: ='BILLING COMPUTATION '!CQ192 -> 1869643.8 | K18: =H18='[43]BILLING COMPUTATION'!CZ229 -> FALSE
C19: ADMIN FEE (10%) | H19: ='BILLING COMPUTATION '!CR192 -> 186964.38 | K19: =H19='[43]BILLING COMPUTATION'!DA229 -> FALSE
C20: TOTAL BILLING AFTER ADMIN | H20: =SUM(H18:H19) -> 2056608.2 | K20: =H20='[43]BILLING COMPUTATION'!DB229 -> FALSE
C21: MEAL ALLOWANCE | H21: ='BILLING COMPUTATION '!CU192 -> 55180.969 | K21: =H21='[43]BILLING COMPUTATION'!DD229 -> FALSE
C22: Total Amount Billing : | H22: =SUM(H20:H21) -> 2111789.2 | K22: =H22='[43]BILLING COMPUTATION'!DE229 -> FALSE
C23: (See Attachment for Detailed Summary)
B27: =C8 -> TWO MILLION THREE HUNDRED EIGHTY-THREE THOUSAND TWO HUNDRED FIFTY-THREE PESOS AND 50/100 ONLY | G27: PHP | H27: =H22 -> 2111789.2 | K27: =H27='[43]BILLING COMPUTATION'!DE229 -> FALSE
E31: ='BILLING COMPUTATION '!A192 -> 186
A35: HANNAH LEAH Q. REANZARES | E35: REYMARK L. HADIA
A36: BILLING OFFICER | E36: BRANCH HEAD

Sheet SALES INVOICE
C6: CHIYODA PHILIPPINES MANUFACTURING CORPORATION | I6: =TODAY() -> 46207
C8: Lot 2 Block 20 Lima Technology Center SEZ, Lipa City Batangas, 4217, Phils.
I9: 006-361-397-000
C14: Billing for the services rendered by Workers
C15: ='BILLING COMPUTATION '!A2 -> PAYROLL BILLING PERIOD: JUNE 1-15, 2026
C18: Total Billing Operation | I18: ='BILLING COMPUTATION '!CQ192 -> 1869643.8
C19: Admin Fee | I19: ='BILLING COMPUTATION '!CR192 -> 186964.38
C20: TOTAL | I20: =I18+I19 -> 2056608.2
C21: Meal Allowance | I21: ='BILLING COMPUTATION '!CU192 -> 55180.969
C22: GROSS AMOUNT | I22: =SUM(I20:I21) -> 2111789.2
I32: =E40 -> 2111789.2
I33: =E39 -> 0
I34: =E40-I33 -> 2111789.2
I36: =I34-I35 -> 2111789.2
E37: =I22 -> 2111789.2 | I37: =ROUND(I36*0.02,2) -> 42235.78
I38: =I36-I37 -> 2069553.4
E39: =E36*0.12 -> 0 | I39: =E39 -> 0
E40: =SUM(E36:E39) -> 2111789.2 | I40: =SUM(I38:I39) -> 2069553.4

Sheet BILLING COMPUTATION 
A2: PAYROLL BILLING PERIOD: JUNE 1-15, 2026
A3: NO. | B3: ID No. | C3: DATE HIRED | D3: BATCH NO. | E3: NAMES OF EMPLOYEE | G3: LOCATION | H3: DEPARTMENT | I3: BASIC | M3: REGULAR OT | P3: NIGHT DIFF | S3: NIGHT DIFF OT | V3: COMPANY HOLIDAY | Y3: RD REGULAR | AB3: RD OT | AE3: RD ND | AH3: RD OTND | AK3: SPECIAL HOLIDAY HRS | AN3: SPECIAL HOLIDAY OT | AQ3: SPECIAL HOLIDAY ND | AT3: SPECIAL HOLIDAY NDOT | AW3: UNWORKED LEGAL HOLIDAY | AZ3: LEGAL HOLIDAY | BC3: LEGAL HOLIDAY ND | BF3: LATE/ UNDERTIME | BH3: ADJUSTMENT | BZ3: JUNE 6 PAY (SEPARATED EMPLOYEES) | CD3: SAT WORK | CH3: SAT WORK ND | CK3: TOTAL AMOUNT | CM3: MANDATORY CONTIBUTIONS | CP3: 13th MONTH | CQ3: TOTAL BILLING BEFORE ADMIN FEE | CR3: ADMIN FEE 10% | CS3: TOTAL WITH ADMIN FEE | CT3: Deduction to Meal Allowance | CU3: MEAL ALLOWANCE (31 PER DAY) | CV3: TOTAL
I4: HRS | J4: DAYS | K4: RATE | L4: AMOUNT | M4: HRS | N4: RATE | O4: AMOUNT | P4: HRS | Q4: RATE | R4: AMOUNT | S4: HRS | T4: RATE | U4: AMOUNT | V4: HRS | W4: RATE | X4: AMOUNT | Y4: HRS | Z4: RATE | AA4: AMOUNT | AB4: HRS | AC4: RATE | AD4: AMOUNT | AE4: DAYS | AF4: RATE | AG4: AMOUNT | AH4: DAYS | AI4: RATE | AJ4: AMOUNT | AK4: DAYS | AL4: RATE | AM4: AMOUNT | AN4: DAYS | AO4: RATE | AP4: AMOUNT | AQ4: DAYS | AR4: RATE | AS4: AMOUNT | AT4: DAYS | AU4: RATE | AV4: AMOUNT | AW4: HRS | AX4: RATE | AY4: AMOUNT | AZ4: DAYS | BA4: RATE | BB4: AMOUNT | BC4: DAYS | BD4: RATE | BE4: AMOUNT | BF4: MINS | BG4: AMOUNT | BH4: REG HRS | BI4: RATE | BJ4: AMOUNT | BK4: OT | BL4: RATE | BM4: AMOUNT | BN4: ND | BO4: RATE | BP4: AMOUNT | BQ4: NDOT | BR4: RATE | BS4: AMOUNT | BT4: SUN HRS | BU4: RATE | BV4: AMOUNT | BW4: MEAL ALLOWANCE | BX4: RATE | BY4: AMOUNT | BZ4: HRS | CA4: DAYS | CB4: RATE | CC4: AMOUNT | CD4: HRS | CE4: DAYS | CF4: RATE | CG4: AMOUNT | CH4: HRS | CI4: RATE | CJ4: AMOUNT | CL4: HMO | CM4: SSS TOTAL | CN4: Philhealth ER | CO4: Pag-ibig
A5: 1 | B5: 5683 | C5: 45244 | D5: B3 | E5: Abcede, Jomar Pavino | G5: Factory 2 | H5: QC Inspection | I5: 88 | J5: 11 | K5: 600 | L5: 6600 | M5: 27 | N5: 93.75 | O5: 2531.25 | P5: 30 | Q5: 7.5 | R5: 225 | S5: 10 | T5: 9.375 | U5: 93.75 | W5: 93.75 | X5: 0 | Z5: 97.5 | AA5: 0 | AC5: 126.75 | AD5: 0 | AF5: 9.75 | AG5: 0 | AI5: 12.6675 | AJ5: 0 | AL5: 97.5 | AM5: 0 | AO5: 126.75 | AP5: 0 | AR5: 9.75 | AS5: 0 | AU5: 12.675 | AV5: 0 | AW5: 8 | AX5: 600 | AY5: 600 | BA5: 540 | BB5: 0 | BF5: 0 | BG5: 0 | BH5: 0 | BI5: 600 | BJ5: 0 | BL5: 93.75 | BM5: 0 | BO5: 7.5 | BP5: 0 | BR5: 9.375 | BS5: 0 | BU5: 97.5 | BV5: 0 | BW5: 0 | BX5: 31 | BY5: 0 | BZ5: 0 | CA5: 0 | CB5: 67.5 | CC5: 0 | CD5: 0 | CE5: 0 | CF5: 93.75 | CG5: 0 | CI5: 9.375 | CJ5: 0 | CK5: 10050 | CM5: 2130 | CN5: 391.25 | CO5: 200 | CP5: 550 | CQ5: 13321.25 | CR5: 1332.125 | CS5: 14653.375 | CT5: 0 | CU5: 341 | CV5: 14994.375
A6: 2 | B6: 31024 | C6: 45951 | D6: B50 | E6: Abrio, Althea Mae Divila | G6: Factory 1 | H6: Subaru Engine | I6: 80 | J6: 10 | K6: 600 | L6: 6000 | M6: 27 | N6: 93.75 | O6: 2531.25 | P6: 25 | Q6: 7.5 | R6: 187.5 | S6: 10 | T6: 9.375 | U6: 93.75 | W6: 93.75 | X6: 0 | Z6: 97.5 | AA6: 0 | AC6: 126.75 | AD6: 0 | AF6: 9.75 | AG6: 0 | AI6: 12.6675 | AJ6: 0 | AL6: 97.5 | AM6: 0 | AO6: 126.75 | AP6: 0 | AR6: 9.75 | AS6: 0 | AU6: 12.675 | AV6: 0 | AW6: 0 | AX6: 600 | AY6: 0 | BA6: 541 | BB6: 0 | BF6: 0 | BG6: 0 | BH6: 0 | BI6: 600 | BJ6: 0 | BL6: 93.75 | BM6: 0 | BO6: 7.5 | BP6: 0 | BR6: 9.375 | BS6: 0 | BU6: 97.5 | BV6: 0 | BW6: 0 | BX6: 31 | BY6: 0 | BZ6: 0 | CA6: 0 | CB6: 67.5 | CC6: 0 | CD6: 0 | CE6: 0 | CF6: 93.75 | CG6: 0 | CI6: 9.375 | CJ6: 0 | CK6: 8812.5 | CM6: 2030 | CN6: 391.25 | CO6: 200 | CP6: 500 | CQ6: 11933.75 | CR6: 1193.375 | CS6: 13127.125 | CT6: 0 | CU6: 310 | CV6: 13437.125
A7: 3 | B7: 13373 | C7: 45811 | D7: B47 | E7: Acasamoso, Jerico Ladia | G7: Factory 3 | H7: QC Inspection | I7: 80 | J7: 10 | K7: 600 | L7: 6000 | M7: 19.67 | N7: 93.75 | O7: 1844.0625 | P7: 20 | Q7: 7.5 | R7: 150 | S7: 2 | T7: 9.375 | U7: 18.75 | W7: 93.75 | X7: 0 | Z7: 97.5 | AA7: 0 | AC7: 126.75 | AD7: 0 | AF7: 9.75 | AG7: 0 | AI7: 12.6675 | AJ7: 0 | AL7: 97.5 | AM7: 0 | AO7: 126.75 | AP7: 0 | AR7: 9.75 | AS7: 0 | AU7: 12.675 | AV7: 0 | AW7: 8 | AX7: 600 | AY7: 600 | BA7: 542 | BB7: 0 | BF7: 0 | BG7: 0 | BH7: 0 | BI7: 600 | BJ7: 0 | BL7: 93.75 | BM7: 0 | BO7: 7.5 | BP7: 0 | BR7: 9.375 | BS7: 0 | BU7: 97.5 | BV7: 0 | BW7: 0 | BX7: 31 | BY7: 0 | BZ7: 0 | CA7: 0 | CB7: 67.5 | CC7: 0 | CD7: 0 | CE7: 0 | CF7: 93.75 | CG7: 0 | CI7: 9.375 | CJ7: 0 | CK7: 8612.8125 | CM7: 1980 | CN7: 391.25 | CO7: 200 | CP7: 500 | CQ7: 11684.062 | CR7: 1168.4062 | CS7: 12852.469 | CT7: 0 | CU7: 310 | CV7: 13162.469
A8: 4 | B8: 7167 | C8: 45524 | D8: B23 | E8: Aguirre, Christopher Isla | G8: Factory 1 | H8: Subaru Engine | I8: 56 | J8: 7 | K8: 600 | L8: 4200 | M8: 15 | N8: 93.75 | O8: 1406.25 | P8: 20 | Q8: 7.5 | R8: 150 | S8: 6 | T8: 9.375 | U8: 56.25 | W8: 93.75 | X8: 0 | Z8: 97.5 | AA8: 0 | AC8: 126.75 | AD8: 0 | AF8: 9.75 | AG8: 0 | AI8: 12.6675 | AJ8: 0 | AL8: 97.5 | AM8: 0 | AO8: 126.75 | AP8: 0 | AR8: 9.75 | AS8: 0 | AU8: 12.675 | AV8: 0 | AW8: 0 | AX8: 600 | AY8: 0 | BA8: 543 | BB8: 0 | BF8: 0 | BG8: 0 | BH8: 0 | BI8: 600 | BJ8: 0 | BL8: 93.75 | BM8: 0 | BO8: 7.5 | BP8: 0 | BR8: 9.375 | BS8: 0 | BU8: 97.5 | BV8: 0 | BW8: 0 | BX8: 31 | BY8: 0 | BZ8: 0 | CA8: 0 | CB8: 67.5 | CC8: 0 | CD8: 0 | CE8: 0 | CF8: 93.75 | CG8: 0 | CI8: 9.375 | CJ8: 0 | CK8: 5812.5 | CM8: 0 | CN8: 0 | CO8: 0 | CP8: 350 | CQ8: 6162.5 | CR8: 616.25 | CS8: 6778.75 | CT8: 0 | CU8: 217 | CV8: 6995.75
A9: 5 | B9: 32300 | C9: 46175 | D9: B59 | E9: Albello, Joyce Anne Palma | G9: Factory 2 | H9: Trainee | I9: 80 | J9: 10 | K9: 600 | L9: 6000 | M9: 0 | N9: 93.75 | O9: 0 | P9: 0 | Q9: 7.5 | R9: 0 | S9: 0 | T9: 9.375 | U9: 0 | W9: 93.75 | X9: 0 | Z9: 97.5 | AA9: 0 | AC9: 126.75 | AD9: 0 | AF9: 9.75 | AG9: 0 | AI9: 12.6675 | AJ9: 0 | AL9: 97.5 | AM9: 0 | AO9: 126.75 | AP9: 0 | AR9: 9.75 | AS9: 0 | AU9: 12.675 | AV9: 0 | AW9: 8 | AX9: 600 | AY9: 600 | BA9: 544 | BB9: 0 | BF9: 0 | BG9: 0 | BH9: 0 | BI9: 600 | BJ9: 0 | BL9: 93.75 | BM9: 0 | BO9: 7.5 | BP9: 0 | BR9: 9.375 | BS9: 0 | BU9: 97.5 | BV9: 0 | BW9: 0 | BX9: 31 | BY9: 0 | BZ9: 0 | CA9: 0 | CB9: 67.5 | CC9: 0 | CD9: 0 | CE9: 0 | CF9: 93.75 | CG9: 0 | CI9: 9.375 | CJ9: 0 | CK9: 6600 | CM9: 710 | CN9: 391.25 | CO9: 200 | CP9: 500 | CQ9: 8401.25 | CR9: 840.125 | CS9: 9241.375 | CT9: 0 | CU9: 310 | CV9: 9551.375
A10: 6 | B10: 32202 | C10: 46161 | D10: B58 | E10: Alcantara, Felix Salvador Andoque | G10: Factory 2 | H10: Trainee | I10: 80 | J10: 10 | K10: 600 | L10: 6000 | M10: 0 | N10: 93.75 | O10: 0 | P10: 0 | Q10: 7.5 | R10: 0 | S10: 0 | T10: 9.375 | U10: 0 | W10: 93.75 | X10: 0 | Z10: 97.5 | AA10: 0 | AC10: 126.75 | AD10: 0 | AF10: 9.75 | AG10: 0 | AI10: 12.6675 | AJ10: 0 | AL10: 97.5 | AM10: 0 | AO10: 126.75 | AP10: 0 | AR10: 9.75 | AS10: 0 | AU10: 12.675 | AV10: 0 | AW10: 8 | AX10: 600 | AY10: 600 | BA10: 545 | BB10: 0 | BF10: 0 | BG10: 0 | BH10: 0 | BI10: 600 | BJ10: 0 | BL10: 93.75 | BM10: 0 | BO10: 7.5 | BP10: 0 | BR10: 9.375 | BS10: 0 | BU10: 97.5 | BV10: 0 | BW10: 0 | BX10: 31 | BY10: 0 | BZ10: 0 | CA10: 0 | CB10: 67.5 | CC10: 0 | CD10: 0 | CE10: 0 | CF10: 93.75 | CG10: 0 | CI10: 9.375 | CJ10: 0 | CK10: 6600 | CM10: 1310 | CN10: 391.25 | CO10: 200 | CP10: 500 | CQ10: 9001.25 | CR10: 900.125 | CS10: 9901.375 | CT10: 0 | CU10: 310 | CV10: 10211.375
A11: 7 | B11: 32255 | C11: 46175 | D11: B59 | E11: Alikhan, Mohammad King Verona | G11: Factory 2 | H11: Trainee | I11: 80 | J11: 10 | K11: 600 | L11: 6000 | M11: 6 | N11: 93.75 | O11: 562.5 | P11: 30 | Q11: 7.5 | R11: 225 | S11: 4 | T11: 9.375 | U11: 37.5 | W11: 93.75 | X11: 0 | Z11: 97.5 | AA11: 0 | AC11: 126.75 | AD11: 0 | AF11: 9.75 | AG11: 0 | AI11: 12.6675 | AJ11: 0 | AL11: 97.5 | AM11: 0 | AO11: 126.75 | AP11: 0 | AR11: 9.75 | AS11: 0 | AU11: 12.675 | AV11: 0 | AW11: 8 | AX11: 600 | AY11: 600 | BA11: 546 | BB11: 0 | BF11: 0 | BG11: 0 | BH11: 0 | BI11: 600 | BJ11: 0 | BL11: 93.75 | BM11: 0 | BO11: 7.5 | BP11: 0 | BR11: 9.375 | BS11: 0 | BU11: 97.5 | BV11: 0 | BW11: 0 | BX11: 31 | BY11: 0 | BZ11: 0 | CA11: 0 | CB11: 67.5 | CC11: 0 | CD11: 0 | CE11: 0 | CF11: 93.75 | CG11: 0 | CI11: 9.375 | CJ11: 0 | CK11: 7425 | CM11: 760 | CN11: 391.25 | CO11: 200 | CP11: 500 | CQ11: 9276.25 | CR11: 927.625 | CS11: 10203.875 | CT11: 0 | CU11: 310 | CV11: 10513.875
A12: 8 | B12: 11936 | C12: 45734 | D12: B38 | E12: Alongalay, Ruiz Trillanes | G12: Factory 1 | H12: Parts Preparation | I12: 88 | J12: 11 | K12: 600 | L12: 6600 | M12: 13.92 | N12: 93.75 | O12: 1305 | P12: 30 | Q12: 7.5 | R12: 225 | S12: 2 | T12: 9.375 | U12: 18.75 | W12: 93.75 | X12: 0 | Z12: 97.5 | AA12: 0 | AC12: 126.75 | AD12: 0 | AF12: 9.75 | AG12: 0 | AI12: 12.6675 | AJ12: 0 | AL12: 97.5 | AM12: 0 | AO12: 126.75 | AP12: 0 | AR12: 9.75 | AS12: 0 | AU12: 12.675 | AV12: 0 | AW12: 8 | AX12: 600 | AY12: 600 | BA12: 547 | BB12: 0 | BF12: 0 | BG12: 0 | BH12: 0 | BI12: 600 | BJ12: 0 | BL12: 93.75 | BM12: 0 | BO12: 7.5 | BP12: 0 | BR12: 9.375 | BS12: 0 | BU12: 97.5 | BV12: 0 | BW12: 0 | BX12: 31 | BY12: 0 | BZ12: 0 | CA12: 0 | CB12: 67.5 | CC12: 0 | CD12: 0 | CE12: 0 | CF12: 93.75 | CG12: 0 | CI12: 9.375 | CJ12: 0 | CK12: 8748.75 | CM12: 1980 | CN12: 391.25 | CO12: 200 | CP12: 550 | CQ12: 11870 | CR12: 1187 | CS12: 13057 | CT12: 0 | CU12: 341 | CV12: 13398
A13: 9 | B13: 31006 | C13: 45944 | D13: B49 | E13: An, Rey Alcos | G13: Factory 1 | H13: Material Handler | I13: 88 | J13: 11 | K13: 600 | L13: 6600 | M13: 27 | N13: 93.75 | O13: 2531.25 | P13: 25 | Q13: 7.5 | R13: 187.5 | S13: 10 | T13: 9.375 | U13: 93.75 | W13: 93.75 | X13: 0 | Z13: 97.5 | AA13: 0 | AC13: 126.75 | AD13: 0 | AF13: 9.75 | AG13: 0 | AI13: 12.6675 | AJ13: 0 | AL13: 97.5 | AM13: 0 | AO13: 126.75 | AP13: 0 | AR13: 9.75 | AS13: 0 | AU13: 12.675 | AV13: 0 | AW13: 8 | AX13: 600 | AY13: 600 | BA13: 548 | BB13: 0 | BF13: 0 | BG13: 0 | BH13: 0 | BI13: 600 | BJ13: 0 | BL13: 93.75 | BM13: 0 | BO13: 7.5 | BP13: 0 | BR13: 9.375 | BS13: 0 | BU13: 97.5 | BV13: 0 | BW13: 0 | BX13: 31 | BY13: 0 | BZ13: 0 | CA13: 0 | CB13: 67.5 | CC13: 0 | CD13: 0 | CE13: 0 | CF13: 93.75 | CG13: 0 | CI13: 9.375 | CJ13: 0 | CK13: 10012.5 | CM13: 2030 | CN13: 391.25 | CO13: 200 | CP13: 550 | CQ13: 13183.75 | CR13: 1318.375 | CS13: 14502.125 | CT13: 0 | CU13: 341 | CV13: 14843.125
A14: 10 | B14: 32281 | C14: 46175 | D14: B59 | E14: Andal, Ana Mae De Jesus | G14: Factory 2 | H14: Trainee | I14: 80 | J14: 10 | K14: 600 | L14: 6000 | M14: 0 | N14: 93.75 | O14: 0 | P14: 0 | Q14: 7.5 | R14: 0 | S14: 0 | T14: 9.375 | U14: 0 | W14: 93.75 | X14: 0 | Z14: 97.5 | AA14: 0 | AC14: 126.75 | AD14: 0 | AF14: 9.75 | AG14: 0 | AI14: 12.6675 | AJ14: 0 | AL14: 97.5 | AM14: 0 | AO14: 126.75 | AP14: 0 | AR14: 9.75 | AS14: 0 | AU14: 12.675 | AV14: 0 | AW14: 8 | AX14: 600 | AY14: 600 | BA14: 549 | BB14: 0 | BF14: 0 | BG14: 0 | BH14: 0 | BI14: 600 | BJ14: 0 | BL14: 93.75 | BM14: 0 | BO14: 7.5 | BP14: 0 | BR14: 9.375 | BS14: 0 | BU14: 97.5 | BV14: 0 | BW14: 0 | BX14: 31 | BY14: 0 | BZ14: 0 | CA14: 0 | CB14: 67.5 | CC14: 0 | CD14: 0 | CE14: 0 | CF14: 93.75 | CG14: 0 | CI14: 9.375 | CJ14: 0 | CK14: 6600 | CM14: 710 | CN14: 391.25 | CO14: 200 | CP14: 500 | CQ14: 8401.25 | CR14: 840.125 | CS14: 9241.375 | CT14: 0 | CU14: 310 | CV14: 9551.375
A15: 11 | B15: 7080 | C15: 45531 | D15: B24 | E15: Antaran, Alrey jay Barber | G15: Factory 3 | H15: Warehouse | I15: 80 | J15: 10 | K15: 600 | L15: 6000 | M15: 12 | N15: 93.75 | O15: 1125 | P15: 24.96 | Q15: 7.5 | R15: 187.2 | S15: 6 | T15: 9.375 | U15: 56.25 | W15: 93.75 | X15: 0 | Z15: 97.5 | AA15: 0 | AC15: 126.75 | AD15: 0 | AF15: 9.75 | AG15: 0 | AI15: 12.6675 | AJ15: 0 | AL15: 97.5 | AM15: 0 | AO15: 126.75 | AP15: 0 | AR15: 9.75 | AS15: 0 | AU15: 12.675 | AV15: 0 | AW15: 8 | AX15: 600 | AY15: 600 | BA15: 550 | BB15: 0 | BF15: 3 | BG15: -3.75 | BH15: 0 | BI15: 600 | BJ15: 0 | BL15: 93.75 | BM15: 0 | BO15: 7.5 | BP15: 0 | BR15: 9.375 | BS15: 0 | BU15: 97.5 | BV15: 0 | BW15: 0 | BX15: 31 | BY15: 0 | BZ15: 0 | CA15: 0 | CB15: 67.5 | CC15: 0 | CD15: 0 | CE15: 0 | CF15: 93.75 | CG15: 0 | CI15: 9.375 | CJ15: 0 | CK15: 7964.7 | CM15: 1730 | CN15: 391.25 | CO15: 200 | CP15: 499.6875 | CQ15: 10785.638 | CR15: 1078.5638 | CS15: 11864.201 | CT15: 0 | CU15: 310 | CV15: 12174.201
A16: 12 | B16: 31088 | C16: 45993 | D16: B53 | E16: Armada, Simon Estacio | G16: Factory 1 | H16: QC Inspection | I16: 72 | J16: 9 | K16: 600 | L16: 5400 | M16: 18 | N16: 93.75 | O16: 1687.5 | P16: 25 | Q16: 7.5 | R16: 187.5 | S16: 8 | T16: 9.375 | U16: 75 | W16: 93.75 | X16: 0 | Z16: 97.5 | AA16: 0 | AC16: 126.75 | AD16: 0 | AF16: 9.75 | AG16: 0 | AI16: 12.6675 | AJ16: 0 | AL16: 97.5 | AM16: 0 | AO16: 126.75 | AP16: 0 | AR16: 9.75 | AS16: 0 | AU16: 12.675 | AV16: 0 | AW16: 8 | AX16: 600 | AY16: 600 | BA16: 551 | BB16: 0 | BF16: 0 | BG16: 0 | BH16: 0 | BI16: 600 | BJ16: 0 | BL16: 93.75 | BM16: 0 | BO16: 7.5 | BP16: 0 | BR16: 9.375 | BS16: 0 | BU16: 97.5 | BV16: 0 | BW16: 0 | BX16: 31 | BY16: 0 | BZ16: 0 | CA16: 0 | CB16: 67.5 | CC16: 0 | CD16: 0 | CE16: 0 | CF16: 93.75 | CG16: 0 | CI16: 9.375 | CJ16: 0 | CK16: 7950 | CM16: 1830 | CN16: 391.25 | CO16: 200 | CP16: 450 | CQ16: 10821.25 | CR16: 1082.125 | CS16: 11903.375 | CT16: 0 | CU16: 279 | CV16: 12182.375
... A65: 61 | B65: 12450 | C65: 45670 | D65: B30 | E65: Deuna, Rommel Lumpot | G65: Factory 1 | H65: Wire Preparation | I65: 80 | J65: 10 | K65: 600 | L65: 6000 | M65: 15 | N65: 93.75 | O65: 1406.25 | P65: 25 | Q65: 7.5 | R65: 187.5 | S65: 0 | T65: 9.375 | U65: 0 | W65: 93.75 | X65: 0 | Z65: 97.5 | AA65: 0 | AC65: 126.75 | AD65: 0 | AF65: 9.75 | AG65: 0 | AI65: 12.6675 | AJ65: 0 | AL65: 97.5 | AM65: 0 | AO65: 126.75 | AP65: 0 | AR65: 9.75 | AS65: 0 | AU65: 12.675 | AV65: 0 | AW65: 8 | AX65: 600 | AY65: 600 | BA65: 602 | BB65: 0 | BF65: 0 | BG65: 0 | BH65: 0 | BI65: 600 | BJ65: 0 | BL65: 93.75 | BM65: 0 | BO65: 7.5 | BP65: 0 | BR65: 9.375 | BS65: 0 | BU65: 97.5 | BV65: 0 | BW65: 0 | BX65: 31 | BY65: 0 | BZ65: 0 | CA65: 0 | CB65: 67.5 | CC65: 0 | CD65: 0 | CE65: 0 | CF65: 93.75 | CG65: 0 | CI65: 9.375 | CJ65: 0 | CK65: 8193.75 | CM65: 1880 | CN65: 391.25 | CO65: 200 | CP65: 500 | CQ65: 11165 | CR65: 1116.5 | CS65: 12281.5 | CT65: 0 | CU65: 310 | CV65: 12591.5
A66: 62 | B66: 5846 | C66: 45244 | D66: B2 | E66: Diaz, Junel Mago | G66: Factory 1 | H66: Wire Preparation | I66: 80 | J66: 10 | K66: 600 | L66: 6000 | M66: 24 | N66: 93.75 | O66: 2250 | P66: 25 | Q66: 7.5 | R66: 187.5 | S66: 8 | T66: 9.375 | U66: 75 | W66: 93.75 | X66: 0 | Z66: 97.5 | AA66: 0 | AC66: 126.75 | AD66: 0 | AF66: 9.75 | AG66: 0 | AI66: 12.6675 | AJ66: 0 | AL66: 97.5 | AM66: 0 | AO66: 126.75 | AP66: 0 | AR66: 9.75 | AS66: 0 | AU66: 12.675 | AV66: 0 | AW66: 8 | AX66: 600 | AY66: 600 | BA66: 603 | BB66: 0 | BF66: 0 | BG66: 0 | BH66: 0 | BI66: 600 | BJ66: 0 | BK66: 0 | BL66: 93.75 | BM66: 0 | BO66: 7.5 | BP66: 0 | BR66: 9.375 | BS66: 0 | BU66: 97.5 | BV66: 0 | BW66: 0 | BX66: 31 | BY66: 0 | BZ66: 0 | CA66: 0 | CB66: 67.5 | CC66: 0 | CD66: 0 | CE66: 0 | CF66: 93.75 | CG66: 0 | CI66: 9.375 | CJ66: 0 | CK66: 9112.5 | CM66: 1930 | CN66: 391.25 | CO66: 200 | CP66: 500 | CQ66: 12133.75 | CR66: 1213.375 | CS66: 13347.125 | CT66: 0 | CU66: 310 | CV66: 13657.125
A67: 63 | B67: 14872 | C67: 45818 | D67: B48 | E67: Dorado, Merlan Gatdula | G67: Factory 1 | H67: Wire Preparation | I67: 48 | J67: 6 | K67: 600 | L67: 3600 | M67: 0 | N67: 93.75 | O67: 0 | P67: 10 | Q67: 7.5 | R67: 75 | S67: 0 | T67: 9.375 | U67: 0 | W67: 93.75 | X67: 0 | Z67: 97.5 | AA67: 0 | AC67: 126.75 | AD67: 0 | AF67: 9.75 | AG67: 0 | AI67: 12.6675 | AJ67: 0 | AL67: 97.5 | AM67: 0 | AO67: 126.75 | AP67: 0 | AR67: 9.75 | AS67: 0 | AU67: 12.675 | AV67: 0 | AW67: 0 | AX67: 600 | AY67: 0 | BA67: 604 | BB67: 0 | BF67: 0 | BG67: 0 | BH67: 0 | BI67: 600 | BJ67: 0 | BL67: 93.75 | BM67: 0 | BO67: 7.5 | BP67: 0 | BR67: 9.375 | BS67: 0 | BU67: 97.5 | BV67: 0 | BW67: 0 | BX67: 31 | BY67: 0 | BZ67: 0 | CA67: 0 | CB67: 67.5 | CC67: 0 | CD67: 0 | CE67: 0 | CF67: 93.75 | CG67: 0 | CI67: 9.375 | CJ67: 0 | CK67: 3675 | CM67: 1060 | CN67: 391.25 | CO67: 200 | CP67: 300 | CQ67: 5626.25 | CR67: 562.625 | CS67: 6188.875 | CT67: 0 | CU67: 186 | CV67: 6374.875
A68: 64 | B68: 31012 | C68: 45944 | D68: B49 | E68: Encila, Marilyn Lopez | G68: Factory 1 | H68: Wire Preparation | I68: 88 | J68: 11 | K68: 600 | L68: 6600 | M68: 12 | N68: 93.75 | O68: 1125 | P68: 30 | Q68: 7.5 | R68: 225 | S68: 2 | T68: 9.375 | U68: 18.75 | W68: 93.75 | X68: 0 | Z68: 97.5 | AA68: 0 | AC68: 126.75 | AD68: 0 | AF68: 9.75 | AG68: 0 | AI68: 12.6675 | AJ68: 0 | AL68: 97.5 | AM68: 0 | AO68: 126.75 | AP68: 0 | AR68: 9.75 | AS68: 0 | AU68: 12.675 | AV68: 0 | AW68: 8 | AX68: 600 | AY68: 600 | BA68: 605 | BB68: 0 | BF68: 0 | BG68: 0 | BH68: 0 | BI68: 600 | BJ68: 0 | BL68: 93.75 | BM68: 0 | BO68: 7.5 | BP68: 0 | BR68: 9.375 | BS68: 0 | BU68: 97.5 | BV68: 0 | BW68: 0 | BX68: 31 | BY68: 0 | BZ68: 0 | CA68: 0 | CB68: 67.5 | CC68: 0 | CD68: 0 | CE68: 0 | CF68: 93.75 | CG68: 0 | CI68: 9.375 | CJ68: 0 | CK68: 8568.75 | CM68: 1880 | CN68: 391.25 | CO68: 200 | CP68: 550 | CQ68: 11590 | CR68: 1159 | CS68: 12749 | CT68: 0 | CU68: 341 | CV68: 13090
A69: 65 | B69: 32286 | C69: 46175 | D69: B59 | E69: Endozo, Ejay | G69: Factory 2 | H69: Trainee | I69: 80 | J69: 10 | K69: 600 | L69: 6000 | M69: 0 | N69: 93.75 | O69: 0 | P69: 0 | Q69: 7.5 | R69: 0 | S69: 0 | T69: 9.375 | U69: 0 | W69: 93.75 | X69: 0 | Z69: 97.5 | AA69: 0 | AC69: 126.75 | AD69: 0 | AF69: 9.75 | AG69: 0 | AI69: 12.6675 | AJ69: 0 | AL69: 97.5 | AM69: 0 | AO69: 126.75 | AP69: 0 | AR69: 9.75 | AS69: 0 | AU69: 12.675 | AV69: 0 | AW69: 8 | AX69: 600 | AY69: 600 | BA69: 606 | BB69: 0 | BF69: 240 | BG69: -300 | BH69: 0 | BI69: 600 | BJ69: 0 | BL69: 93.75 | BM69: 0 | BO69: 7.5 | BP69: 0 | BR69: 9.375 | BS69: 0 | BU69: 97.5 | BV69: 0 | BW69: 0 | BX69: 31 | BY69: 0 | BZ69: 0 | CA69: 0 | CB69: 67.5 | CC69: 0 | CD69: 0 | CE69: 0 | CF69: 93.75 | CG69: 0 | CI69: 9.375 | CJ69: 0 | CK69: 6300 | CM69: 660 | CN69: 391.25 | CO69: 200 | CP69: 475 | CQ69: 8026.25 | CR69: 802.625 | CS69: 8828.875 | CT69: 15.5 | CU69: 294.5 | CV69: 9123.375
A70: 66 | B70: 32559 | C70: 46154 | D70: B57 | E70: Enecimo, Rodelyn Macahis | G70: Factory 3 | H70: Wire Preparation | I70: 88 | J70: 11 | K70: 600 | L70: 6600 | M70: 0 | N70: 93.75 | O70: 0 | P70: 30 | Q70: 7.5 | R70: 225 | S70: 0 | T70: 9.375 | U70: 0 | W70: 93.75 | X70: 0 | Z70: 97.5 | AA70: 0 | AC70: 126.75 | AD70: 0 | AF70: 9.75 | AG70: 0 | AI70: 12.6675 | AJ70: 0 | AL70: 97.5 | AM70: 0 | AO70: 126.75 | AP70: 0 | AR70: 9.75 | AS70: 0 | AU70: 12.675 | AV70: 0 | AW70: 8 | AX70: 600 | AY70: 600 | BA70: 607 | BB70: 0 | BF70: 0 | BG70: 0 | BH70: 0 | BI70: 600 | BJ70: 0 | BL70: 93.75 | BM70: 0 | BO70: 7.5 | BP70: 0 | BR70: 9.375 | BS70: 0 | BU70: 97.5 | BV70: 0 | BW70: 0 | BX70: 31 | BY70: 0 | BZ70: 0 | CA70: 0 | CB70: 67.5 | CC70: 0 | CD70: 0 | CE70: 0 | CF70: 93.75 | CG70: 0 | CI70: 9.375 | CJ70: 0 | CK70: 7425 | CM70: 1580 | CN70: 391.25 | CO70: 200 | CP70: 550 | CQ70: 10146.25 | CR70: 1014.625 | CS70: 11160.875 | CT70: 0 | CU70: 341 | CV70: 11501.875
A71: 67 | B71: 32537 | C71: 46154 | D71: B57 | E71: Enriquez, Felicidad Dajon | G71: Factory 1 | H71: Wire Preparation | I71: 88 | J71: 11 | K71: 600 | L71: 6600 | M71: 3 | N71: 93.75 | O71: 281.25 | P71: 25 | Q71: 7.5 | R71: 187.5 | S71: 2 | T71: 9.375 | U71: 18.75 | W71: 93.75 | X71: 0 | Z71: 97.5 | AA71: 0 | AC71: 126.75 | AD71: 0 | AF71: 9.75 | AG71: 0 | AI71: 12.6675 | AJ71: 0 | AL71: 97.5 | AM71: 0 | AO71: 126.75 | AP71: 0 | AR71: 9.75 | AS71: 0 | AU71: 12.675 | AV71: 0 | AW71: 8 | AX71: 600 | AY71: 600 | BA71: 608 | BB71: 0 | BF71: 0 | BG71: 0 | BH71: 0 | BI71: 600 | BJ71: 0 | BL71: 93.75 | BM71: 0 | BO71: 7.5 | BP71: 0 | BR71: 9.375 | BS71: 0 | BU71: 97.5 | BV71: 0 | BW71: 0 | BX71: 31 | BY71: 0 | BZ71: 0 | CA71: 0 | CB71: 67.5 | CC71: 0 | CD71: 0 | CE71: 0 | CF71: 93.75 | CG71: 0 | CI71: 9.375 | CJ71: 0 | CK71: 7687.5 | CM71: 1730 | CN71: 391.25 | CO71: 200 | CP71: 550 | CQ71: 10558.75 | CR71: 1055.875 | CS71: 11614.625 | CT71: 0 | CU71: 341 | CV71: 11955.625
A72: 68 | B72: 13357 | C72: 45811 | D72: B47 | E72: Esplana, Ronald N/A | G72: Factory 3 | H72: Wire Preparation | I72: 88 | J72: 11 | K72: 600 | L72: 6600 | M72: 6 | N72: 93.75 | O72: 562.5 | P72: 30 | Q72: 7.5 | R72: 225 | S72: 2 | T72: 9.375 | U72: 18.75 | W72: 93.75 | X72: 0 | Z72: 97.5 | AA72: 0 | AC72: 126.75 | AD72: 0 | AF72: 9.75 | AG72: 0 | AI72: 12.6675 | AJ72: 0 | AL72: 97.5 | AM72: 0 | AO72: 126.75 | AP72: 0 | AR72: 9.75 | AS72: 0 | AU72: 12.675 | AV72: 0 | AW72: 8 | AX72: 600 | AY72: 600 | BA72: 609 | BB72: 0 | BF72: 0 | BG72: 0 | BH72: 0 | BI72: 600 | BJ72: 0 | BL72: 93.75 | BM72: 0 | BO72: 7.5 | BP72: 0 | BR72: 9.375 | BS72: 0 | BU72: 97.5 | BV72: 0 | BW72: 0 | BX72: 31 | BY72: 0 | BZ72: 0 | CA72: 0 | CB72: 67.5 | CC72: 0 | CD72: 0 | CE72: 0 | CF72: 93.75 | CG72: 0 | CI72: 9.375 | CJ72: 0 | CK72: 8006.25 | CM72: 1680 | CN72: 391.25 | CO72: 200 | CP72: 550 | CQ72: 10827.5 | CR72: 1082.75 | CS72: 11910.25 | CT72: 0 | CU72: 341 | CV72: 12251.25
A73: 69 | B73: 12260 | C73: 45768 | D73: B41 | E73: Estipona, Joel De Mesa | G73: Factory 1 | H73: Subaru Engine | I73: 80 | J73: 10 | K73: 600 | L73: 6000 | M73: 9 | N73: 93.75 | O73: 843.75 | P73: 30 | Q73: 7.5 | R73: 225 | S73: 0 | T73: 9.375 | U73: 0 | W73: 93.75 | X73: 0 | Z73: 97.5 | AA73: 0 | AC73: 126.75 | AD73: 0 | AF73: 9.75 | AG73: 0 | AI73: 12.6675 | AJ73: 0 | AL73: 97.5 | AM73: 0 | AO73: 126.75 | AP73: 0 | AR73: 9.75 | AS73: 0 | AU73: 12.675 | AV73: 0 | AW73: 8 | AX73: 600 | AY73: 600 | BA73: 610 | BB73: 0 | BF73: 0 | BG73: 0 | BH73: 0 | BI73: 600 | BJ73: 0 | BL73: 93.75 | BM73: 0 | BO73: 7.5 | BP73: 0 | BR73: 9.375 | BS73: 0 | BU73: 97.5 | BV73: 0 | BW73: 0 | BX73: 31 | BY73: 0 | BZ73: 0 | CA73: 0 | CB73: 67.5 | CC73: 0 | CD73: 0 | CE73: 0 | CF73: 93.75 | CG73: 0 | CI73: 9.375 | CJ73: 0 | CK73: 7668.75 | CM73: 1830 | CN73: 391.25 | CO73: 200 | CP73: 500 | CQ73: 10590 | CR73: 1059 | CS73: 11649 | CT73: 0 | CU73: 310 | CV73: 11959
A74: 70 | B74: 32570 | C74: 46154 | D74: B57 | E74: Estolano, Jade Marie Flores | G74: Factory 1 | H74: Wire Preparation | I74: 88 | J74: 11 | K74: 600 | L74: 6600 | M74: 0 | N74: 93.75 | O74: 0 | P74: 25 | Q74: 7.5 | R74: 187.5 | S74: 0 | T74: 9.375 | U74: 0 | W74: 93.75 | X74: 0 | Z74: 97.5 | AA74: 0 | AC74: 126.75 | AD74: 0 | AF74: 9.75 | AG74: 0 | AI74: 12.6675 | AJ74: 0 | AL74: 97.5 | AM74: 0 | AO74: 126.75 | AP74: 0 | AR74: 9.75 | AS74: 0 | AU74: 12.675 | AV74: 0 | AW74: 8 | AX74: 600 | AY74: 600 | BA74: 611 | BB74: 0 | BF74: 35 | BG74: -43.75 | BH74: 0 | BI74: 600 | BJ74: 0 | BL74: 93.75 | BM74: 0 | BO74: 7.5 | BP74: 0 | BR74: 9.375 | BS74: 0 | BU74: 97.5 | BV74: 0 | BW74: 0 | BX74: 31 | BY74: 0 | BZ74: 0 | CA74: 0 | CB74: 67.5 | CC74: 0 | CD74: 0 | CE74: 0 | CF74: 93.75 | CG74: 0 | CI74: 9.375 | CJ74: 0 | CK74: 7343.75 | CM74: 1310 | CN74: 391.25 | CO74: 200 | CP74: 546.35417 | CQ74: 9791.3542 | CR74: 979.13542 | CS74: 10770.49 | CT74: 0 | CU74: 341 | CV74: 11111.49
A75: 71 | B75: 6905 | C75: 45497 | D75: B19 | E75: Estrada, Kevin James Hernandez | G75: Factory 1 | H75: Subaru Insertion | I75: 88 | J75: 11 | K75: 600 | L75: 6600 | M75: 21 | N75: 93.75 | O75: 1968.75 | P75: 30 | Q75: 7.5 | R75: 225 | S75: 6 | T75: 9.375 | U75: 56.25 | W75: 93.75 | X75: 0 | Z75: 97.5 | AA75: 0 | AC75: 126.75 | AD75: 0 | AF75: 9.75 | AG75: 0 | AI75: 12.6675 | AJ75: 0 | AL75: 97.5 | AM75: 0 | AO75: 126.75 | AP75: 0 | AR75: 9.75 | AS75: 0 | AU75: 12.675 | AV75: 0 | AW75: 8 | AX75: 600 | AY75: 600 | BA75: 612 | BB75: 0 | BF75: 0 | BG75: 0 | BH75: 0 | BI75: 600 | BJ75: 0 | BL75: 93.75 | BM75: 0 | BO75: 7.5 | BP75: 0 | BR75: 9.375 | BS75: 0 | BU75: 97.5 | BV75: 0 | BW75: 0 | BX75: 31 | BY75: 0 | BZ75: 0 | CA75: 0 | CB75: 67.5 | CC75: 0 | CD75: 0 | CE75: 0 | CF75: 93.75 | CG75: 0 | CI75: 9.375 | CJ75: 0 | CK75: 9450 | CM75: 2080 | CN75: 391.25 | CO75: 200 | CP75: 550 | CQ75: 12671.25 | CR75: 1267.125 | CS75: 13938.375 | CT75: 0 | CU75: 341 | CV75: 14279.375
A76: 72 | B76: 13351 | C76: 45811 | D76: B47 | E76: Faderog, Mark Japhet Francisco | G76: Factory 3 | H76: QC Inspection | I76: 88 | J76: 11 | K76: 600 | L76: 6600 | M76: 26.98 | N76: 93.75 | O76: 2529.375 | P76: 30 | Q76: 7.5 | R76: 225 | S76: 10 | T76: 9.375 | U76: 93.75 | W76: 93.75 | X76: 0 | Z76: 97.5 | AA76: 0 | AC76: 126.75 | AD76: 0 | AF76: 9.75 | AG76: 0 | AI76: 12.6675 | AJ76: 0 | AL76: 97.5 | AM76: 0 | AO76: 126.75 | AP76: 0 | AR76: 9.75 | AS76: 0 | AU76: 12.675 | AV76: 0 | AW76: 8 | AX76: 600 | AY76: 600 | BA76: 613 | BB76: 0 | BF76: 0 | BG76: 0 | BH76: 0 | BI76: 600 | BJ76: 0 | BL76: 93.75 | BM76: 0 | BO76: 7.5 | BP76: 0 | BR76: 9.375 | BS76: 0 | BU76: 97.5 | BV76: 0 | BW76: 0 | BX76: 31 | BY76: 0 | BZ76: 0 | CA76: 0 | CB76: 67.5 | CC76: 0 | CD76: 0 | CE76: 0 | CF76: 93.75 | CG76: 0 | CI76: 9.375 | CJ76: 0 | CK76: 10048.125 | CM76: 2130 | CN76: 391.25 | CO76: 200 | CP76: 550 | CQ76: 13319.375 | CR76: 1331.9375 | CS76: 14651.312 | CT76: 0 | CU76: 341 | CV76: 14992.312
A77: 73 | B77: 32292 | C77: 46175 | D77: B59 | E77: Fajardo, Jonaglen Berwega | G77: Factory 2 | H77: Trainee | I77: 80 | J77: 10 | K77: 600 | L77: 6000 | M77: 0 | N77: 99.21875 | O77: 0 | P77: 20 | Q77: 7.5 | R77: 150 | S77: 0 | T77: 9.921875 | U77: 0 | W77: 99.21875 | X77: 0 | Z77: 103.1875 | AA77: 0 | AC77: 134.14375 | AD77: 0 | AF77: 10.31875 | AG77: 0 | AI77: 13.406438 | AJ77: 0 | AL77: 103.1875 | AM77: 0 | AO77: 134.14375 | AP77: 0 | AR77: 10.31875 | AS77: 0 | AU77: 13.414375 | AV77: 0 | AW77: 8 | AX77: 600 | AY77: 600 | BA77: 614 | BB77: 0 | BF77: 0 | BG77: 0 | BH77: 0 | BI77: 600 | BJ77: 0 | BL77: 93.75 | BM77: 0 | BO77: 7.5 | BP77: 0 | BR77: 9.375 | BS77: 0 | BU77: 103.1875 | BV77: 0 | BW77: 0 | BX77: 31 | BY77: 0 | BZ77: 0 | CA77: 0 | CB77: 67.5 | CC77: 0 | CD77: 0 | CE77: 0 | CF77: 99.21875 | CG77: 0 | CI77: 9.921875 | CJ77: 0 | CK77: 7100 | CM77: 710 | CN77: 391.25 | CO77: 200 | CP77: 500 | CQ77: 8551.25 | CR77: 855.125 | CS77: 9406.375 | CT77: 0 | CU77: 310 | CV77: 9716.375
A78: 74 | B78: 31137 | C78: 45951 | D78: B50 | E78: Fidelson, Maria Noralie N/A | G78: Factory 1 | H78: Subaru Engine | I78: 88 | J78: 11 | K78: 600 | L78: 6600 | M78: 21 | N78: 93.75 | O78: 1968.75 | P78: 25 | Q78: 7.5 | R78: 187.5 | S78: 10 | T78: 9.375 | U78: 93.75 | W78: 93.75 | X78: 0 | Z78: 97.5 | AA78: 0 | AC78: 126.75 | AD78: 0 | AF78: 9.75 | AG78: 0 | AI78: 12.6675 | AJ78: 0 | AL78: 97.5 | AM78: 0 | AO78: 126.75 | AP78: 0 | AR78: 9.75 | AS78: 0 | AU78: 12.675 | AV78: 0 | AW78: 8 | AX78: 600 | AY78: 600 | BA78: 615 | BB78: 0 | BF78: 0 | BG78: 0 | BH78: 0 | BI78: 600 | BJ78: 0 | BL78: 93.75 | BM78: 0 | BO78: 7.5 | BP78: 0 | BR78: 9.375 | BS78: 0 | BU78: 97.5 | BV78: 0 | BW78: 0 | BX78: 31 | BY78: 0 | BZ78: 0 | CA78: 0 | CB78: 67.5 | CC78: 0 | CD78: 0 | CE78: 0 | CF78: 93.75 | CG78: 0 | CI78: 9.375 | CJ78: 0 | CK78: 9450 | CM78: 1930 | CN78: 391.25 | CO78: 200 | CP78: 550 | CQ78: 12521.25 | CR78: 1252.125 | CS78: 13773.375 | CT78: 0 | CU78: 341 | CV78: 14114.375
... A123: 119 | B123: 31090 | C123: 45993 | D123: B53 | E123: Mesina, Jhon Patrick Villanueva | G123: Factory 1 | H123: Material Handler | I123: 16 | J123: 2 | K123: 600 | L123: 1200 | M123: 0 | N123: 93.75 | O123: 0 | P123: 10 | Q123: 7.5 | R123: 75 | S123: 0 | T123: 9.375 | U123: 0 | W123: 93.75 | X123: 0 | Z123: 97.5 | AA123: 0 | AC123: 126.75 | AD123: 0 | AF123: 9.75 | AG123: 0 | AI123: 12.6675 | AJ123: 0 | AL123: 97.5 | AM123: 0 | AO123: 126.75 | AP123: 0 | AR123: 9.75 | AS123: 0 | AU123: 12.675 | AV123: 0 | AW123: 0 | AX123: 600 | AY123: 0 | BA123: 660 | BB123: 0 | BF123: 0 | BG123: 0 | BH123: 0 | BI123: 600 | BJ123: 0 | BL123: 93.75 | BM123: 0 | BO123: 7.5 | BP123: 0 | BR123: 9.375 | BS123: 0 | BU123: 97.5 | BV123: 0 | BW123: 0 | BX123: 31 | BY123: 0 | BZ123: 0 | CA123: 0 | CB123: 67.5 | CC123: 0 | CD123: 0 | CE123: 0 | CF123: 93.75 | CG123: 0 | CI123: 9.375 | CJ123: 0 | CK123: 1275 | CM123: 0 | CN123: 0 | CO123: 0 | CP123: 100 | CQ123: 1375 | CR123: 137.5 | CS123: 1512.5 | CT123: 0 | CU123: 62 | CV123: 1574.5
A124: 120 | B124: 32295 | C124: 46175 | D124: B59 | E124: Miranda, Ruben Peregrino De Asis | G124: Factory 2 | H124: Trainee | I124: 80 | J124: 10 | K124: 600 | L124: 6000 | M124: 3 | N124: 93.75 | O124: 281.25 | P124: 20 | Q124: 7.5 | R124: 150 | S124: 2 | T124: 9.375 | U124: 18.75 | W124: 93.75 | X124: 0 | Z124: 97.5 | AA124: 0 | AC124: 126.75 | AD124: 0 | AF124: 9.75 | AG124: 0 | AI124: 12.6675 | AJ124: 0 | AL124: 97.5 | AM124: 0 | AO124: 126.75 | AP124: 0 | AR124: 9.75 | AS124: 0 | AU124: 12.675 | AV124: 0 | AW124: 8 | AX124: 600 | AY124: 600 | BA124: 661 | BB124: 0 | BF124: 0 | BG124: 0 | CK124: 7050 | CM124: 760 | CN124: 391.25 | CO124: 200 | CP124: 500 | CQ124: 8901.25 | CR124: 890.125 | CS124: 9791.375 | CT124: 0 | CU124: 310 | CV124: 10101.375
A125: 121 | B125: 12743 | C125: 45685 | D125: B33 | E125: Misula, Ruden Romualdo | G125: Factory 3 | H125: Transmission | I125: 88 | J125: 11 | K125: 600 | L125: 6600 | M125: 9 | N125: 93.75 | O125: 843.75 | P125: 25 | Q125: 7.5 | R125: 187.5 | S125: 6 | T125: 9.375 | U125: 56.25 | W125: 93.75 | X125: 0 | Z125: 97.5 | AA125: 0 | AC125: 126.75 | AD125: 0 | AF125: 9.75 | AG125: 0 | AI125: 12.6675 | AJ125: 0 | AL125: 97.5 | AM125: 0 | AO125: 126.75 | AP125: 0 | AR125: 9.75 | AS125: 0 | AU125: 12.675 | AV125: 0 | AW125: 8 | AX125: 600 | AY125: 600 | BA125: 662 | BB125: 0 | BF125: 0 | BG125: 0 | CK125: 8287.5 | CM125: 1880 | CN125: 391.25 | CO125: 200 | CP125: 550 | CQ125: 11308.75 | CR125: 1130.875 | CS125: 12439.625 | CT125: 0 | CU125: 341 | CV125: 12780.625
A126: 122 | B126: 32543 | C126: 46154 | D126: B57 | E126: Mojica, Raymart | G126: Factory 2 | H126: Molding | I126: 88 | J126: 11 | K126: 600 | L126: 6600 | M126: 24 | N126: 93.75 | O126: 2250 | P126: 25 | Q126: 7.5 | R126: 187.5 | S126: 10 | T126: 9.375 | U126: 93.75 | W126: 93.75 | X126: 0 | Z126: 97.5 | AA126: 0 | AC126: 126.75 | AD126: 0 | AF126: 9.75 | AG126: 0 | AI126: 12.6675 | AJ126: 0 | AL126: 97.5 | AM126: 0 | AO126: 126.75 | AP126: 0 | AR126: 9.75 | AS126: 0 | AU126: 12.675 | AV126: 0 | AW126: 8 | AX126: 600 | AY126: 600 | BA126: 663 | BB126: 0 | BF126: 0 | BG126: 0 | CK126: 9731.25 | CM126: 1980 | CN126: 391.25 | CO126: 200 | CP126: 550 | CQ126: 12852.5 | CR126: 1285.25 | CS126: 14137.75 | CT126: 0 | CU126: 341 | CV126: 14478.75
A127: 123 | B127: 13893 | C127: 45545 | D127: B26 | E127: Montejo, John Miguel Bitchayda | G127: Factory 1 | H127: Subaru Engine | I127: 88 | J127: 11 | K127: 600 | L127: 6600 | M127: 24 | N127: 93.75 | O127: 2250 | P127: 30 | Q127: 7.5 | R127: 225 | S127: 10 | T127: 9.375 | U127: 93.75 | W127: 93.75 | X127: 0 | Z127: 97.5 | AA127: 0 | AC127: 126.75 | AD127: 0 | AF127: 9.75 | AG127: 0 | AI127: 12.6675 | AJ127: 0 | AL127: 97.5 | AM127: 0 | AO127: 126.75 | AP127: 0 | AR127: 9.75 | AS127: 0 | AU127: 12.675 | AV127: 0 | AW127: 8 | AX127: 600 | AY127: 600 | BA127: 664 | BB127: 0 | BF127: 0 | BG127: 0 | CK127: 9768.75 | CM127: 2030 | CN127: 391.25 | CO127: 200 | CP127: 550 | CQ127: 12940 | CR127: 1294 | CS127: 14234 | CT127: 0 | CU127: 341 | CV127: 14575
A128: 124 | B128: 32819 | C128: 46084 | D128: B56 | E128: Mora, Stephany Jerrylle Robles | G128: Factory 1 | H128: QC Inspection | I128: 88 | J128: 11 | K128: 600 | L128: 6600 | M128: 30 | N128: 93.75 | O128: 2812.5 | P128: 30 | Q128: 7.5 | R128: 225 | S128: 10 | T128: 9.375 | U128: 93.75 | W128: 93.75 | X128: 0 | Z128: 97.5 | AA128: 0 | AC128: 126.75 | AD128: 0 | AF128: 9.75 | AG128: 0 | AI128: 12.6675 | AJ128: 0 | AL128: 97.5 | AM128: 0 | AO128: 126.75 | AP128: 0 | AR128: 9.75 | AS128: 0 | AU128: 12.675 | AV128: 0 | AW128: 8 | AX128: 600 | AY128: 600 | BA128: 665 | BB128: 0 | BF128: 0 | BG128: 0 | CK128: 10331.25 | CM128: 1930 | CN128: 391.25 | CO128: 200 | CP128: 550 | CQ128: 13402.5 | CR128: 1340.25 | CS128: 14742.75 | CT128: 0 | CU128: 341 | CV128: 15083.75
A129: 125 | B129: 32566 | C129: 46154 | D129: B57 | E129: Morales, Eden Motol | G129: Factory 2 | H129: Wire Preparation | I129: 32 | J129: 4 | K129: 600 | L129: 2400 | M129: 0 | N129: 93.75 | O129: 0 | P129: 0 | Q129: 7.5 | R129: 0 | S129: 0 | T129: 9.375 | U129: 0 | W129: 93.75 | X129: 0 | Z129: 97.5 | AA129: 0 | AC129: 126.75 | AD129: 0 | AF129: 9.75 | AG129: 0 | AI129: 12.6675 | AJ129: 0 | AL129: 97.5 | AM129: 0 | AO129: 126.75 | AP129: 0 | AR129: 9.75 | AS129: 0 | AU129: 12.675 | AV129: 0 | AW129: 0 | AX129: 600 | AY129: 0 | BA129: 666 | BB129: 0 | BF129: 0 | BG129: 0 | CK129: 2400 | CM129: 1060 | CN129: 391.25 | CO129: 200 | CP129: 200 | CQ129: 4251.25 | CR129: 425.125 | CS129: 4676.375 | CT129: 0 | CU129: 124 | CV129: 4800.375
A130: 126 | B130: 32282 | C130: 46175 | D130: B59 | E130: Morales, Lira Ann Sabanal | G130: Factory 2 | H130: Trainee | I130: 80 | J130: 10 | K130: 600 | L130: 6000 | M130: 0 | N130: 93.75 | O130: 0 | P130: 0 | Q130: 7.5 | R130: 0 | S130: 0 | T130: 9.375 | U130: 0 | W130: 93.75 | X130: 0 | Z130: 97.5 | AA130: 0 | AC130: 126.75 | AD130: 0 | AF130: 9.75 | AG130: 0 | AI130: 12.6675 | AJ130: 0 | AL130: 97.5 | AM130: 0 | AO130: 126.75 | AP130: 0 | AR130: 9.75 | AS130: 0 | AU130: 12.675 | AV130: 0 | AW130: 8 | AX130: 600 | AY130: 600 | BA130: 667 | BB130: 0 | BF130: 0 | BG130: 0 | CK130: 6600 | CM130: 710 | CN130: 391.25 | CO130: 200 | CP130: 500 | CQ130: 8401.25 | CR130: 840.125 | CS130: 9241.375 | CT130: 0 | CU130: 310 | CV130: 9551.375
A131: 127 | B131: 32562 | C131: 46154 | D131: B57 | E131: Morales, Marwin Rodriguez | G131: Factory 1 | H131: Wire Preparation | I131: 88 | J131: 11 | K131: 600 | L131: 6600 | M131: 21 | N131: 93.75 | O131: 1968.75 | P131: 25 | Q131: 7.5 | R131: 187.5 | S131: 6 | T131: 9.375 | U131: 56.25 | W131: 93.75 | X131: 0 | Z131: 97.5 | AA131: 0 | AC131: 126.75 | AD131: 0 | AF131: 9.75 | AG131: 0 | AI131: 12.6675 | AJ131: 0 | AL131: 97.5 | AM131: 0 | AO131: 126.75 | AP131: 0 | AR131: 9.75 | AS131: 0 | AU131: 12.675 | AV131: 0 | AW131: 8 | AX131: 600 | AY131: 600 | BA131: 668 | BB131: 0 | BF131: 0 | BG131: 0 | CK131: 9412.5 | CM131: 1880 | CN131: 391.25 | CO131: 200 | CP131: 550 | CQ131: 12433.75 | CR131: 1243.375 | CS131: 13677.125 | CT131: 0 | CU131: 341 | CV131: 14018.125
A132: 128 | B132: 13360 | C132: 45811 | D132: B47 | E132: Moratin, Ian Vincent Libet | G132: Factory 1 | H132: Wire Preparation | I132: 80 | J132: 10 | K132: 600 | L132: 6000 | M132: 21 | N132: 93.75 | O132: 1968.75 | P132: 30 | Q132: 7.5 | R132: 225 | S132: 8 | T132: 9.375 | U132: 75 | W132: 93.75 | X132: 0 | Z132: 97.5 | AA132: 0 | AC132: 126.75 | AD132: 0 | AF132: 9.75 | AG132: 0 | AI132: 12.6675 | AJ132: 0 | AL132: 97.5 | AM132: 0 | AO132: 126.75 | AP132: 0 | AR132: 9.75 | AS132: 0 | AU132: 12.675 | AV132: 0 | AW132: 8 | AX132: 600 | AY132: 600 | BA132: 669 | BB132: 0 | BF132: 0 | BG132: 0 | CK132: 8868.75 | CM132: 1880 | CN132: 391.25 | CO132: 200 | CP132: 500 | CQ132: 11840 | CR132: 1184 | CS132: 13024 | CT132: 0 | CU132: 310 | CV132: 13334
A133: 129 | B133: 13358 | C133: 45811 | D133: B47 | E133: Moster, Danilyn Padrique | G133: Factory 1 | H133: Transmission | I133: 16 | J133: 2 | K133: 600 | L133: 1200 | M133: 0 | N133: 93.75 | O133: 0 | P133: 10 | Q133: 7.5 | R133: 75 | S133: 0 | T133: 9.375 | U133: 0 | W133: 93.75 | X133: 0 | Z133: 97.5 | AA133: 0 | AC133: 126.75 | AD133: 0 | AF133: 9.75 | AG133: 0 | AI133: 12.6675 | AJ133: 0 | AL133: 97.5 | AM133: 0 | AO133: 126.75 | AP133: 0 | AR133: 9.75 | AS133: 0 | AU133: 12.675 | AV133: 0 | AW133: 0 | AX133: 600 | AY133: 0 | BA133: 670 | BB133: 0 | BF133: 0 | BG133: 0 | CK133: 1275 | CM133: 0 | CN133: 0 | CO133: 0 | CP133: 100 | CQ133: 1375 | CR133: 137.5 | CS133: 1512.5 | CT133: 0 | CU133: 62 | CV133: 1574.5
...

Sheet SSS_2025
A1: RANGE OF COMPENSATION | C1: MONTHLY SALARY CREDIT | F1: AMOUNT OF CONTRIBUTION
C2: REGULAR SSS | D2: WISP/MPF | E2: TOTAL | F2: EMPLOYER | K2: EMPLOYEE | N2: TOTAL CONTRIBUTION
F3: REGULAR SS | G3: WISP/MPF | H3: TOTAL 1 | I3: EC | J3: TOTAL 2 | K3: REGULAR SS | L3: WISP | M3: TOTAL
A4: 1 | B4: 2 | C4: 3 | D4: 4 | E4: 5 | F4: 6 | G4: 7 | H4: 8 | I4: 9 | J4: 10 | K4: 11 | L4: 12 | M4: 13 | N4: 14
A5: 0 | B5: 0 | C5: 0 | D5: 0 | E5: 0 | F5: 0 | G5: 0 | H5: 0 | I5: 0 | J5: 0 | K5: 0 | L5: 0 | M5: 0 | N5: 0
A6: 1 | B6: 5250 | C6: 5000 | D6: 0 | E6: 5000 | F6: 500 | G6: 0 | H6: =SUM(F6:G6) -> 500 | I6: 10 | J6: =SUM(H6:I6) -> 510 | K6: 250 | L6: 0 | M6: =SUM(K6:L6) -> 250 | N6: =J6+M6 -> 760
A7: 5250 | B7: 5749.99 | C7: 5500 | D7: 0 | E7: 5500 | F7: 550 | G7: 0 | H7: =SUM(F7:G7) -> 550 | I7: 10 | J7: =SUM(H7:I7) -> 560 | K7: 275 | L7: 0 | M7: =SUM(K7:L7) -> 275 | N7: =J7+M7 -> 835
A8: 5750 | B8: 6249.99 | C8: 6000 | D8: 0 | E8: 6000 | F8: 600 | G8: 0 | H8: =SUM(F8:G8) -> 600 | I8: 10 | J8: =SUM(H8:I8) -> 610 | K8: 300 | L8: 0 | M8: =SUM(K8:L8) -> 300 | N8: =J8+M8 -> 910
A9: 6250 | B9: 6749.99 | C9: 6500 | D9: 0 | E9: 6500 | F9: 650 | G9: 0 | H9: =SUM(F9:G9) -> 650 | I9: 10 | J9: =SUM(H9:I9) -> 660 | K9: 325 | L9: 0 | M9: =SUM(K9:L9) -> 325 | N9: =J9+M9 -> 985
A10: 6750 | B10: 7249.99 | C10: 7000 | D10: 0 | E10: 7000 | F10: 700 | G10: 0 | H10: =SUM(F10:G10) -> 700 | I10: 10 | J10: =SUM(H10:I10) -> 710 | K10: 350 | L10: 0 | M10: =SUM(K10:L10) -> 350 | N10: =J10+M10 -> 1060
A11: 7250 | B11: 7749.99 | C11: 7500 | D11: 0 | E11: 7500 | F11: 750 | G11: 0 | H11: =SUM(F11:G11) -> 750 | I11: 10 | J11: =SUM(H11:I11) -> 760 | K11: 375 | L11: 0 | M11: =SUM(K11:L11) -> 375 | N11: =J11+M11 -> 1135
A12: 7750 | B12: 8249.99 | C12: 8000 | D12: 0 | E12: 8000 | F12: 800 | G12: 0 | H12: =SUM(F12:G12) -> 800 | I12: 10 | J12: =SUM(H12:I12) -> 810 | K12: 400 | L12: 0 | M12: =SUM(K12:L12) -> 400 | N12: =J12+M12 -> 1210
A13: 8250 | B13: 8749.99 | C13: 8500 | D13: 0 | E13: 8500 | F13: 850 | G13: 0 | H13: =SUM(F13:G13) -> 850 | I13: 10 | J13: =SUM(H13:I13) -> 860 | K13: 425 | L13: 0 | M13: =SUM(K13:L13) -> 425 | N13: =J13+M13 -> 1285
A14: 8750 | B14: 9249.99 | C14: 9000 | D14: 0 | E14: 9000 | F14: 900 | G14: 0 | H14: =SUM(F14:G14) -> 900 | I14: 10 | J14: =SUM(H14:I14) -> 910 | K14: 450 | L14: 0 | M14: =SUM(K14:L14) -> 450 | N14: =J14+M14 -> 1360
A15: 9250 | B15: 9749.99 | C15: 9500 | D15: 0 | E15: 9500 | F15: 950 | G15: 0 | H15: =SUM(F15:G15) -> 950 | I15: 10 | J15: =SUM(H15:I15) -> 960 | K15: 475 | L15: 0 | M15: =SUM(K15:L15) -> 475 | N15: =J15+M15 -> 1435
A16: 9750 | B16: 10249.99 | C16: 10000 | D16: 0 | E16: 10000 | F16: 1000 | G16: 0 | H16: =SUM(F16:G16) -> 1000 | I16: 10 | J16: =SUM(H16:I16) -> 1010 | K16: 500 | L16: 0 | M16: =SUM(K16:L16) -> 500 | N16: =J16+M16 -> 1510
A17: 10250 | B17: 10749.99 | C17: 10500 | D17: 0 | E17: 10500 | F17: 1050 | G17: 0 | H17: =SUM(F17:G17) -> 1050 | I17: 10 | J17: =SUM(H17:I17) -> 1060 | K17: 525 | L17: 0 | M17: =SUM(K17:L17) -> 525 | N17: =J17+M17 -> 1585
... A65: 34250 | B65: 34749.99 | C65: 20000 | D65: 14500 | E65: 34500 | F65: 2000 | G65: 1450 | H65: =SUM(F65:G65) -> 3450 | I65: 30 | J65: =SUM(H65:I65) -> 3480 | K65: 1000 | L65: 725 | M65: =SUM(K65:L65) -> 1725 | N65: =J65+M65 -> 5205
A66: 34750 | C66: 20000 | D66: 15000 | E66: 35000 | F66: 2000 | G66: 1500 | H66: =SUM(F66:G66) -> 3500 | I66: 30 | J66: =SUM(H66:I66) -> 3530 | K66: 1000 | L66: 750 | M66: =SUM(K66:L66) -> 1750 | N66: =J66+M66 -> 5280

Sheet SUMMARY
A1: NO. | B1: DATE HIRED | C1: BATCH | D1: EMPLOYEE ID | E1: NAME | F1: LOCATION | G1: SCHEDULE | H1: SECTION | I1: DATE | J1: IN | K1: OUT | L1: REMARKS | M1: SHIFT | N1: REGULAR HOURS | O1: OT | P1: OTND | Q1: ND | R1: LATE | S1: UNDERTIME | T1: LATE/UT | U1: SAT WORK | V1: SAT WORK ND | W1: RD REG | X1: RD OT | Y1: RD NDOT | Z1: RD ND | AA1: UNWORKED LH | AB1: SH REG | AC1: SH OT | AD1: SH NDOT | AE1: SH ND
A2: 1 | B2: 45244 | C2: B3 | D2: 5683 | E2: Abcede, Jomar Pavino | F2: Factory 2 | G2: Shift 1 | H2: QC Inspection | I2: 46174 | J2: 0.25313657 | K2: 0.79354167 | M2: DS | N2: 8 | O2: 3 | T2: =SUM(R2:S2) -> 0
A3: 2 | B3: 45951 | C3: B50 | D3: 31024 | E3: Abrio, Althea Mae Divila | F3: Factory 1 | G3: Shift 2 | H3: Subaru Engine | I3: 46174 | J3: 0.75875 | K3: 0.29373843 | M3: NS | N3: 8 | O3: 3 | P3: 2 | Q3: 5 | T3: =SUM(R3:S3) -> 0
A4: 3 | B4: 45811 | C4: B47 | D4: 13373 | E4: Acasamoso, Jerico Ladia | F4: Factory 3 | G4: Shift 2 | H4: QC Inspection | I4: 46174 | J4: 0.7643287 | K4: 0.29236111 | L4: NO TIME OUT | M4: NS | N4: 8 | O4: 3 | P4: 2 | Q4: 5 | T4: =SUM(R4:S4) -> 0
A5: 4 | B5: 45524 | C5: B23 | D5: 7167 | E5: Aguirre, Christopher Isla | F5: Factory 1 | G5: Shift 2 | H5: Subaru Engine | I5: 46174 | J5: 0.7694213 | K5: 0.29445602 | M5: NS | N5: 8 | O5: 3 | P5: 2 | Q5: 5 | T5: =SUM(R5:S5) -> 0
A6: 5 | B6: 46161 | C6: B58 | D6: 32202 | E6: Alcantara, Felix Salvador Andoque | F6: Factory 2 | G6: ADS | H6: Trainee | I6: 46174 | J6: 0.26751157 | K6: 0.66711806 | M6: ADS | N6: 8 | T6: =SUM(R6:S6) -> 0
A7: 6 | B7: 45734 | C7: B38 | D7: 11936 | E7: Alongalay, Ruiz Trillanes | F7: Factory 1 | G7: Shift 1 | H7: Parts Preparation | I7: 46174 | J7: 0.24447917 | K7: 0.66824074 | M7: DS | N7: 8 | T7: =SUM(R7:S7) -> 0
A8: 7 | B8: 45944 | C8: B49 | D8: 31006 | E8: An, Rey Alcos | F8: Factory 1 | G8: Shift 2 | H8: Material Handler | I8: 46174 | J8: 0.77131944 | K8: 0.29315972 | M8: NS | N8: 8 | O8: 3 | P8: 2 | Q8: 5 | T8: =SUM(R8:S8) -> 0
A9: 8 | B9: 45531 | C9: B24 | D9: 7080 | E9: Antaran, Alrey jay Barber | F9: Factory 3 | G9: Shift 2 | H9: Warehouse | I9: 46174 | J9: 0.7690625 | K9: 0.29287037 | M9: NS | N9: 8 | O9: 3 | P9: 2 | Q9: 5 | T9: =SUM(R9:S9) -> 0
A10: 9 | B10: 45993 | C10: B53 | D10: 31088 | E10: Armada, Simon Estacio | F10: Factory 1 | G10: Shift 2 | H10: QC Inspection | I10: 46174 | J10: 0.75329861 | K10: 0.2987963 | M10: NS | N10: 8 | O10: 3 | P10: 2 | Q10: 5 | T10: =SUM(R10:S10) -> 0
A11: 10 | B11: 45755 | C11: B40 | D11: 11601 | E11: Asuncion, Rhenzo N/A | F11: Factory 2 | G11: ADS | H11: Warehouse | I11: 46174 | J11: 0.26724537 | K11: 0.66912037 | M11: ADS | N11: 8 | T11: =SUM(R11:S11) -> 0
A12: 11 | B12: 45531 | C12: B24 | D12: 7115 | E12: Aveñon, Reymart Magnaye | F12: Factory 1 | G12: Shift 2 | H12: Transmission | I12: 46174 | J12: 0.77155093 | K12: 0.96527778 | L12: UNDERTIME | M12: NS | N12: 8 | Q12: 0.42 | S12: 275 | T12: =SUM(R12:S12) -> 275
A13: 12 | B13: 46084 | C13: B56 | D13: 32818 | E13: Azarga, Glebel Nañola | F13: Factory 1 | G13: Shift 2 | H13: Wire Preparation | I13: 46174 | L13: ABSENT | M13: NS | T13: 0
A14: 13 | B14: 45734 | C14: B38 | D14: 11939 | E14: Baay, Edrian Samar | F14: Factory 1 | G14: Shift 1 | H14: QC Inspection | I14: 46174 | L14: ABSENT | M14: DS | T14: =SUM(R14:S14) -> 0
A15: 14 | B15: 45951 | C15: B50 | D15: 31047 | E15: Bacay, Princess Jane Garcia | F15: Factory 1 | G15: Shift 1 | H15: Subaru Insertion | I15: 46174 | J15: 0.26722222 | K15: 0.79333333 | M15: DS | N15: 8 | O15: 3 | T15: =SUM(R15:S15) -> 0
A16: 15 | B16: 46161 | C16: B58 | D16: 32205 | E16: Bada, Genm Bryant Carino | F16: Factory 2 | G16: Shift 2 | H16: Subaru Engine/TM | I16: 46174 | J16: 0.75599537 | K16: 0.17145833 | M16: NS | N16: 8 | Q16: 5 | T16: =SUM(R16:S16) -> 0
A17: 16 | B17: 46161 | C17: B58 | D17: 32203 | E17: Bagsic, Protacio Jr. Conception | F17: Factory 2 | G17: Shift 2 | H17: Trainee | I17: 46174 | J17: 0.75010417 | K17: 0.29375 | M17: NS | N17: 8 | O17: 3 | P17: 2 | Q17: 5 | T17: =SUM(R17:S17) -> 0
A18: 17 | B18: 45468 | C18: B15 | D18: 7738 | E18: Balmes, Sheila May Godoy | F18: Factory 1 | G18: Shift 2 | H18: Wire Preparation | I18: 46174 | J18: 0.76915509 | K18: 0.16975694 | M18: NS | N18: 8 | Q18: 5 | T18: =SUM(R18:S18) -> 0
A19: 18 | B19: 45629 | C19: B28 | D19: 10894 | E19: Balobaldo, Jhon Lister Ponpon | F19: Factory 1 | G19: Shift 1 | H19: Wire Preparation | I19: 46174 | J19: 0.2869213 | K19: 0.79435185 | M19: DS | N19: 8 | O19: 3 | T19: =SUM(R19:S19) -> 0
A20: 19 | B20: 45719 | C20: B36 | D20: 12092 | E20: Banaira, Jason Aldovino | F20: Factory 3 | G20: Shift 2 | H20: QA | I20: 46174 | J20: 0.76107639 | K20: 0.29248843 | M20: NS | N20: 8 | O20: 3 | P20: 2 | Q20: 5 | T20: =SUM(R20:S20) -> 0
A21: 20 | B21: 45468 | C21: B15 | D21: 7731 | E21: Baril, Edelyn Digo | F21: Factory 1 | G21: Shift 2 | H21: Wire Preparation | I21: 46174 | J21: 0.76605324 | K21: 0.29438657 | M21: NS | N21: 8 | O21: 3 | P21: 2 | Q21: 5 | T21: =SUM(R21:S21) -> 0
A22: 21 | B22: 45719 | C22: B36 | D22: 12019 | E22: Basila, Mayrelyn Flores | F22: Factory 3 | G22: ADS | H22: Yamaha | I22: 46174 | J22: 0.2624537 | K22: 0.79184028 | M22: ADS | N22: 8 | O22: 3 | T22: =SUM(R22:S22) -> 0
A23: 22 | B23: 46161 | C23: B58 | D23: 32223 | E23: Bathan, Gellie Biscocho | F23: Factory 2 | G23: ADS | H23: Trainee | I23: 46174 | J23: 0.25902778 | K23: 0.67127315 | M23: ADS | N23: 8 | T23: =SUM(R23:S23) -> 0
A24: 23 | B24: 45797 | C24: B45 | D24: 14750 | E24: Bea, Dominic Penano | F24: Factory 3 | G24: Shift 1 | H24: Wire Preparation - Yamaha | I24: 46174 | J24: 0.26570602 | K24: 0.79361111 | M24: DS | N24: 8 | O24: 3 | T24: =SUM(R24:S24) -> 0
A25: 24 | B25: 45622 | C25: B27 | D25: 10941 | E25: Begonia, Christopher Bolo | F25: Factory 3 | G25: Shift 2 | H25: Yamaha | I25: 46174 | J25: 0.7608912 | K25: 0.29315972 | M25: NS | N25: 8 | O25: 3 | P25: 2 | Q25: 5 | T25: =SUM(R25:S25) -> 0
A26: 25 | B26: 45993 | C26: B53 | D26: 31086 | E26: Belardo, Mariel Volante | F26: Factory 1 | G26: Shift 2 | H26: Wire Preparation | I26: 46174 | J26: 0.77030093 | K26: 0.16899306 | M26: NS | N26: 8 | Q26: 5 | T26: =SUM(R26:S26) -> 0
A27: 26 | B27: 46084 | C27: B56 | D27: 32817 | E27: Belir, Mark Shane N/A | F27: Factory 1 | G27: Shift 1 | H27: Subaru Engine | I27: 46174 | J27: 0.27199074 | K27: 0.67074074 | M27: DS | N27: 8 | T27: 0
A28: 27 | B28: 45818 | C28: B48 | D28: 14851 | E28: Beltrano, Celjay N/A | F28: Factory 3 | G28: Shift 2 | H28: Wire Preparation | I28: 46174 | L28: ABSENT | M28: NS | T28: =SUM(R28:S28) -> 0
A29: 28 | B29: 45670 | C29: B30 | D29: 12577 | E29: Bocado, Richard Cocayco | F29: Factory 2 | G29: Shift 1 | H29: Warehouse | I29: 46174 | J29: 0.25935185 | K29: 0.6684838 | M29: DS | N29: 8 | T29: =SUM(R29:S29) -> 0
A30: 29 | B30: 45811 | C30: B47 | D30: 13366 | E30: Bonaobra, Andro Pineda | F30: Factory 1 | G30: Shift 2 | H30: QA Packing | I30: 46174 | J30: 0.7722338 | K30: 0.29549769 | M30: NS | N30: 8 | O30: 3 | P30: 2 | Q30: 5 | T30: =SUM(R30:S30) -> 0
A31: 30 | B31: 45670 | C31: B31 | D31: 13678 | E31: Botin, Jhon Carlo Medallion | F31: Factory 1 | G31: Shift 1 | H31: Wire Preparation | I31: 46174 | J31: 0.26771991 | K31: 0.79451389 | M31: DS | N31: 8 | O31: 3 | T31: =SUM(R31:S31) -> 0
A32: 31 | B32: 45719 | C32: B36 | D32: 12083 | E32: Brozo, Jonel Bautista | F32: Factory 3 | G32: Shift 1 | H32: QA | I32: 46174 | L32: ABSENT | M32: DS | T32: =SUM(R32:S32) -> 0
A33: 32 | B33: 46154 | C33: B57 | D33: 32571 | E33: Brucelo Joshua Alano | F33: Factory 1 | G33: Shift 1 | H33: Material Handler | I33: 46174 | L33: ABSENT | M33: DS | T33: =SUM(R33:S33) -> 0
A34: 33 | B34: 45944 | C34: B49 | D34: 31010 | E34: Burac, Ma. Kaycha Antonio | F34: Factory 1 | G34: Shift 1 | H34: Transmission | I34: 46174 | J34: 0.25394676 | K34: 0.79690972 | M34: DS | N34: 8 | O34: 3 | T34: =SUM(R34:S34) -> 0
A35: 34 | B35: 45685 | C35: B33 | D35: 12634 | E35: Burgos, Yonathan Robles | F35: Factory 1 | G35: Shift 1 | H35: Wire Preparation-Yamaha | I35: 46174 | J35: 0.26125 | K35: 0.79619213 | M35: DS | N35: 8 | O35: 3 | T35: =SUM(R35:S35) -> 0
A36: 35 | B36: 45818 | C36: B48 | D36: 14841 | E36: Caburobias, Aerole John Asparin | F36: Factory 3 | G36: ADS | H36: Warehouse | I36: 46174 | J36: 0.25869213 | K36: 0.79269676 | M36: ADS | N36: 8 | O36: 3 | T36: =SUM(R36:S36) -> 0
A37: 36 | B37: 46084 | C37: B56 | D37: 32803 | E37: Calalo, Hyacinth Ruba | F37: Factory 1 | G37: Shift 1 | H37: QC Inspection | I37: 46174 | J37: 0.26111111 | K37: 0.79778935 | M37: DS | N37: 8 | O37: 3 | T37: 0
A38: 37 | B38: 46084 | C38: B56 | D38: 32822 | E38: Cañelas, Michelle Ann Ramos | F38: Factory 3 | G38: Shift 2 | H38: Wire Preparation - Yamaha | I38: 46174 | J38: 0.7581713 | K38: 0.29282407 | M38: NS | N38: 8 | O38: 3 | P38: 2 | Q38: 5 | T38: 0
A39: 38 | B39: 46084 | C39: B56 | D39: 32814 | E39: Canson, Gerald Corral | F39: Factory 1 | G39: Shift 1 | H39: Subaru Engine | I39: 46174 | J39: 0.26716435 | K39: 0.67048611 | M39: DS | N39: 8 | T39: 0
A40: 39 | B40: 45440 | C40: B11 | D40: 6362 | E40: Clores, Lea Amaro | F40: Factory 1 | G40: Shift 1 | H40: QA Inspection | I40: 46174 | L40: ABSENT | M40: DS | T40: =SUM(R40:S40) -> 0
...

Sheet PVT
B3: Row Labels | C3: Sum of REGULAR HOURS | D3: Sum of UNWORKED LH | E3: Sum of LATE/UT | F3: Sum of ND | G3: Sum of OTND | H3: Sum of OT | J3: REG HRS | K3: ULH | L3: UT/LATE | M3: ND | N3: OTND | O3: OT
A4: 5683 | B4: Abcede, Jomar Pavino | C4: 88 | D4: 8 | E4: 0 | F4: 30 | G4: 10 | H4: 27 | J4: =600/8*C:C -> 6600 | K4: =600/8*D:D -> 600 | L4: =600/8/60*E:E -> 0 | M4: =600/8*0.1*F:F -> 225 | N4: =600/8*0.1*1.25*G:G -> 93.75 | O4: =600/8*1.25*H:H -> 2531.25
A5: 31024 | B5: Abrio, Althea Mae Divila | C5: 80 | E5: 0 | F5: 25 | G5: 10 | H5: 27 | J5: =600/8*C:C -> 6000 | K5: =600/8*D:D -> 0 | L5: =600/8/60*E:E -> 0 | M5: =600/8*0.1*F:F -> 187.5 | N5: =600/8*0.1*1.25*G:G -> 93.75 | O5: =600/8*1.25*H:H -> 2531.25
A6: 13373 | B6: Acasamoso, Jerico Ladia | C6: 80 | D6: 8 | E6: 0 | F6: 20 | G6: 2 | H6: 19.67 | J6: =600/8*C:C -> 6000 | K6: =600/8*D:D -> 600 | L6: =600/8/60*E:E -> 0 | M6: =600/8*0.1*F:F -> 150 | N6: =600/8*0.1*1.25*G:G -> 18.75 | O6: =600/8*1.25*H:H -> 1844.0625
A7: 7167 | B7: Aguirre, Christopher Isla | C7: 56 | E7: 0 | F7: 20 | G7: 6 | H7: 15 | J7: =600/8*C:C -> 4200 | K7: =600/8*D:D -> 0 | L7: =600/8/60*E:E -> 0 | M7: =600/8*0.1*F:F -> 150 | N7: =600/8*0.1*1.25*G:G -> 56.25 | O7: =600/8*1.25*H:H -> 1406.25
A8: 32300 | B8: Albello, Joyce Anne Palma | C8: 80 | D8: 8 | E8: 0 | J8: =600/8*C:C -> 6000 | K8: =600/8*D:D -> 600 | L8: =600/8/60*E:E -> 0 | M8: =600/8*0.1*F:F -> 0 | N8: =600/8*0.1*1.25*G:G -> 0 | O8: =600/8*1.25*H:H -> 0
A9: 32202 | B9: Alcantara, Felix Salvador Andoque | C9: 80 | D9: 8 | E9: 0 | J9: =600/8*C:C -> 6000 | K9: =600/8*D:D -> 600 | L9: =600/8/60*E:E -> 0 | M9: =600/8*0.1*F:F -> 0 | N9: =600/8*0.1*1.25*G:G -> 0 | O9: =600/8*1.25*H:H -> 0
A10: 32255 | B10: Alikhan, Mohammad King Verona | C10: 80 | D10: 8 | E10: 0 | F10: 30 | G10: 4 | H10: 6 | J10: =600/8*C:C -> 6000 | K10: =600/8*D:D -> 600 | L10: =600/8/60*E:E -> 0 | M10: =600/8*0.1*F:F -> 225 | N10: =600/8*0.1*1.25*G:G -> 37.5 | O10: =600/8*1.25*H:H -> 562.5
A11: 11936 | B11: Alongalay, Ruiz Trillanes | C11: 88 | D11: 8 | E11: 0 | F11: 30 | G11: 2 | H11: 13.92 | J11: =600/8*C:C -> 6600 | K11: =600/8*D:D -> 600 | L11: =600/8/60*E:E -> 0 | M11: =600/8*0.1*F:F -> 225 | N11: =600/8*0.1*1.25*G:G -> 18.75 | O11: =600/8*1.25*H:H -> 1305
A12: 31006 | B12: An, Rey Alcos | C12: 88 | D12: 8 | E12: 0 | F12: 25 | G12: 10 | H12: 27 | J12: =600/8*C:C -> 6600 | K12: =600/8*D:D -> 600 | L12: =600/8/60*E:E -> 0 | M12: =600/8*0.1*F:F -> 187.5 | N12: =600/8*0.1*1.25*G:G -> 93.75 | O12: =600/8*1.25*H:H -> 2531.25
A13: 32281 | B13: Andal, Ana Mae De Jesus | C13: 80 | D13: 8 | E13: 0 | J13: =600/8*C:C -> 6000 | K13: =600/8*D:D -> 600 | L13: =600/8/60*E:E -> 0 | M13: =600/8*0.1*F:F -> 0 | N13: =600/8*0.1*1.25*G:G -> 0 | O13: =600/8*1.25*H:H -> 0
A14: 7080 | B14: Antaran, Alrey jay Barber | C14: 80 | D14: 8 | E14: 3 | F14: 24.96 | G14: 6 | H14: 12 | J14: =600/8*C:C -> 6000 | K14: =600/8*D:D -> 600 | L14: =600/8/60*E:E -> 3.75 | M14: =600/8*0.1*F:F -> 187.2 | N14: =600/8*0.1*1.25*G:G -> 56.25 | O14: =600/8*1.25*H:H -> 1125
A15: 31088 | B15: Armada, Simon Estacio | C15: 72 | D15: 8 | E15: 0 | F15: 25 | G15: 8 | H15: 18 | J15: =600/8*C:C -> 5400 | K15: =600/8*D:D -> 600 | L15: =600/8/60*E:E -> 0 | M15: =600/8*0.1*F:F -> 187.5 | N15: =600/8*0.1*1.25*G:G -> 75 | O15: =600/8*1.25*H:H -> 1687.5
A16: 11601 | B16: Asuncion, Rhenzo N/A | C16: 88 | D16: 8 | E16: 0 | H16: 18 | J16: =600/8*C:C -> 6600 | K16: =600/8*D:D -> 600 | L16: =600/8/60*E:E -> 0 | M16: =600/8*0.1*F:F -> 0 | N16: =600/8*0.1*1.25*G:G -> 0 | O16: =600/8*1.25*H:H -> 1687.5
A17: 7115 | B17: Aveñon, Reymart Magnaye | C17: 88 | D17: 8 | E17: 275 | F17: 20.42 | G17: 8 | H17: 30 | J17: =600/8*C:C -> 6600 | K17: =600/8*D:D -> 600 | L17: =600/8/60*E:E -> 343.75 | M17: =600/8*0.1*F:F -> 153.15 | N17: =600/8*0.1*1.25*G:G -> 75 | O17: =600/8*1.25*H:H -> 2812.5
A18: 32818 | B18: Azarga, Glebel Nañola | C18: 48 | D18: 8 | E18: 0 | H18: 6 | J18: =600/8*C:C -> 3600 | K18: =600/8*D:D -> 600 | L18: =600/8/60*E:E -> 0 | M18: =600/8*0.1*F:F -> 0 | N18: =600/8*0.1*1.25*G:G -> 0 | O18: =600/8*1.25*H:H -> 562.5
A19: 11939 | B19: Baay, Edrian Samar | C19: 56 | D19: 8 | E19: 0 | F19: 15 | G19: 2 | H19: 15 | J19: =600/8*C:C -> 4200 | K19: =600/8*D:D -> 600 | L19: =600/8/60*E:E -> 0 | M19: =600/8*0.1*F:F -> 112.5 | N19: =600/8*0.1*1.25*G:G -> 18.75 | O19: =600/8*1.25*H:H -> 1406.25
A20: 31047 | B20: Bacay, Princess Jane Garcia | C20: 88 | D20: 8 | E20: 0 | F20: 30 | G20: 8 | H20: 24 | J20: =600/8*C:C -> 6600 | K20: =600/8*D:D -> 600 | L20: =600/8/60*E:E -> 0 | M20: =600/8*0.1*F:F -> 225 | N20: =600/8*0.1*1.25*G:G -> 75 | O20: =600/8*1.25*H:H -> 2250
A21: 32205 | B21: Bada, Genm Bryant Carino | C21: 80 | D21: 8 | E21: 0 | F21: 25 | J21: =600/8*C:C -> 6000 | K21: =600/8*D:D -> 600 | L21: =600/8/60*E:E -> 0 | M21: =600/8*0.1*F:F -> 187.5 | N21: =600/8*0.1*1.25*G:G -> 0 | O21: =600/8*1.25*H:H -> 0
A22: 32203 | B22: Bagsic, Protacio Jr. Conception | C22: 88 | D22: 8 | E22: 0 | F22: 25 | G22: 6 | H22: 12 | J22: =600/8*C:C -> 6600 | K22: =600/8*D:D -> 600 | L22: =600/8/60*E:E -> 0 | M22: =600/8*0.1*F:F -> 187.5 | N22: =600/8*0.1*1.25*G:G -> 56.25 | O22: =600/8*1.25*H:H -> 1125
A23: 7738 | B23: Balmes, Sheila May Godoy | C23: 88 | D23: 8 | E23: 0 | F23: 25 | H23: 3 | J23: =600/8*C:C -> 6600 | K23: =600/8*D:D -> 600 | L23: =600/8/60*E:E -> 0 | M23: =600/8*0.1*F:F -> 187.5 | N23: =600/8*0.1*1.25*G:G -> 0 | O23: =600/8*1.25*H:H -> 281.25
A24: 10894 | B24: Balobaldo, Jhon Lister Ponpon | C24: 88 | D24: 8 | E24: 0 | F24: 30 | G24: 2 | H24: 18 | J24: =600/8*C:C -> 6600 | K24: =600/8*D:D -> 600 | L24: =600/8/60*E:E -> 0 | M24: =600/8*0.1*F:F -> 225 | N24: =600/8*0.1*1.25*G:G -> 18.75 | O24: =600/8*1.25*H:H -> 1687.5
A25: 12092 | B25: Banaira, Jason Aldovino | C25: 80 | D25: 8 | E25: 0 | F25: 25 | G25: 8 | H25: 24 | J25: =600/8*C:C -> 6000 | K25: =600/8*D:D -> 600 | L25: =600/8/60*E:E -> 0 | M25: =600/8*0.1*F:F -> 187.5 | N25: =600/8*0.1*1.25*G:G -> 75 | O25: =600/8*1.25*H:H -> 2250
A26: 7731 | B26: Baril, Edelyn Digo | C26: 88 | D26: 8 | E26: 7 | F26: 25 | G26: 6 | H26: 9 | J26: =600/8*C:C -> 6600 | K26: =600/8*D:D -> 600 | L26: =600/8/60*E:E -> 8.75 | M26: =600/8*0.1*F:F -> 187.5 | N26: =600/8*0.1*1.25*G:G -> 56.25 | O26: =600/8*1.25*H:H -> 843.75
A27: 12019 | B27: Basila, Mayrelyn Flores | C27: 88 | D27: 8 | E27: 0 | F27: 5 | G27: 2 | H27: 24 | J27: =600/8*C:C -> 6600 | K27: =600/8*D:D -> 600 | L27: =600/8/60*E:E -> 0 | M27: =600/8*0.1*F:F -> 37.5 | N27: =600/8*0.1*1.25*G:G -> 18.75 | O27: =600/8*1.25*H:H -> 2250
A28: 32223 | B28: Bathan, Gellie Biscocho | C28: 88 | D28: 8 | E28: 0 | F28: 5 | G28: 2 | H28: 3 | J28: =600/8*C:C -> 6600 | K28: =600/8*D:D -> 600 | L28: =600/8/60*E:E -> 0 | M28: =600/8*0.1*F:F -> 37.5 | N28: =600/8*0.1*1.25*G:G -> 18.75 | O28: =600/8*1.25*H:H -> 281.25
A29: 14750 | B29: Bea, Dominic Penano | C29: 80 | D29: 8 | E29: 0 | F29: 25 | H29: 9 | J29: =600/8*C:C -> 6000 | K29: =600/8*D:D -> 600 | L29: =600/8/60*E:E -> 0 | M29: =600/8*0.1*F:F -> 187.5 | N29: =600/8*0.1*1.25*G:G -> 0 | O29: =600/8*1.25*H:H -> 843.75
A30: 10941 | B30: Begonia, Christopher Bolo | C30: 88 | D30: 8 | E30: 0 | F30: 25 | G30: 8 | H30: 24 | J30: =600/8*C:C -> 6600 | K30: =600/8*D:D -> 600 | L30: =600/8/60*E:E -> 0 | M30: =600/8*0.1*F:F -> 187.5 | N30: =600/8*0.1*1.25*G:G -> 75 | O30: =600/8*1.25*H:H -> 2250
A31: 32279 | B31: Bejasa, Marielle Balasa | C31: 80 | D31: 8 | E31: 0 | J31: =600/8*C:C -> 6000 | K31: =600/8*D:D -> 600 | L31: =600/8/60*E:E -> 0 | M31: =600/8*0.1*F:F -> 0 | N31: =600/8*0.1*1.25*G:G -> 0 | O31: =600/8*1.25*H:H -> 0
A32: 31086 | B32: Belardo, Mariel Volante | C32: 80 | E32: 0 | F32: 25 | J32: =600/8*C:C -> 6000 | K32: =600/8*D:D -> 0 | L32: =600/8/60*E:E -> 0 | M32: =600/8*0.1*F:F -> 187.5 | N32: =600/8*0.1*1.25*G:G -> 0 | O32: =600/8*1.25*H:H -> 0
